<<< -- process set (n=8) with 6 CPU-bound processes
<<< -- seed=768; lambda=0.001000; bound=1024

CPU-bound process A0: arrival time 54ms; 29 CPU bursts:
==> CPU burst 3764ms ==> I/O burst 686ms
==> CPU burst 1732ms ==> I/O burst 212ms
==> CPU burst 844ms ==> I/O burst 493ms
==> CPU burst 168ms ==> I/O burst 372ms
==> CPU burst 736ms ==> I/O burst 141ms
==> CPU burst 1372ms ==> I/O burst 554ms
==> CPU burst 1808ms ==> I/O burst 149ms
==> CPU burst 1808ms ==> I/O burst 266ms
==> CPU burst 848ms ==> I/O burst 75ms
==> CPU burst 3384ms ==> I/O burst 17ms
==> CPU burst 104ms ==> I/O burst 428ms
==> CPU burst 3924ms ==> I/O burst 667ms
==> CPU burst 3388ms ==> I/O burst 94ms
==> CPU burst 100ms ==> I/O burst 487ms
==> CPU burst 3868ms ==> I/O burst 112ms
==> CPU burst 1516ms ==> I/O burst 311ms
==> CPU burst 1260ms ==> I/O burst 413ms
==> CPU burst 728ms ==> I/O burst 773ms
==> CPU burst 2568ms ==> I/O burst 348ms
==> CPU burst 1220ms ==> I/O burst 883ms
==> CPU burst 2296ms ==> I/O burst 664ms
==> CPU burst 3268ms ==> I/O burst 923ms
==> CPU burst 3468ms ==> I/O burst 288ms
==> CPU burst 2392ms ==> I/O burst 108ms
==> CPU burst 1976ms ==> I/O burst 564ms
==> CPU burst 312ms ==> I/O burst 545ms
==> CPU burst 1440ms ==> I/O burst 136ms
==> CPU burst 3052ms ==> I/O burst 558ms
==> CPU burst 2044ms

CPU-bound process A1: arrival time 56ms; 31 CPU bursts:
==> CPU burst 2828ms ==> I/O burst 322ms
==> CPU burst 1444ms ==> I/O burst 167ms
==> CPU burst 2476ms ==> I/O burst 417ms
==> CPU burst 2256ms ==> I/O burst 290ms
==> CPU burst 1188ms ==> I/O burst 777ms
==> CPU burst 2812ms ==> I/O burst 863ms
==> CPU burst 368ms ==> I/O burst 173ms
==> CPU burst 200ms ==> I/O burst 607ms
==> CPU burst 1044ms ==> I/O burst 592ms
==> CPU burst 940ms ==> I/O burst 445ms
==> CPU burst 660ms ==> I/O burst 28ms
==> CPU burst 2196ms ==> I/O burst 976ms
==> CPU burst 36ms ==> I/O burst 637ms
==> CPU burst 4060ms ==> I/O burst 90ms
==> CPU burst 3904ms ==> I/O burst 534ms
==> CPU burst 1488ms ==> I/O burst 404ms
==> CPU burst 1080ms ==> I/O burst 51ms
==> CPU burst 916ms ==> I/O burst 71ms
==> CPU burst 3724ms ==> I/O burst 111ms
==> CPU burst 1764ms ==> I/O burst 282ms
==> CPU burst 860ms ==> I/O burst 99ms
==> CPU burst 2700ms ==> I/O burst 767ms
==> CPU burst 100ms ==> I/O burst 586ms
==> CPU burst 420ms ==> I/O burst 709ms
==> CPU burst 3504ms ==> I/O burst 671ms
==> CPU burst 3504ms ==> I/O burst 334ms
==> CPU burst 2352ms ==> I/O burst 251ms
==> CPU burst 2652ms ==> I/O burst 768ms
==> CPU burst 3812ms ==> I/O burst 527ms
==> CPU burst 2288ms ==> I/O burst 166ms
==> CPU burst 388ms

CPU-bound process A2: arrival time 456ms; 9 CPU bursts:
==> CPU burst 1896ms ==> I/O burst 618ms
==> CPU burst 2940ms ==> I/O burst 439ms
==> CPU burst 248ms ==> I/O burst 464ms
==> CPU burst 952ms ==> I/O burst 774ms
==> CPU burst 1796ms ==> I/O burst 411ms
==> CPU burst 2200ms ==> I/O burst 15ms
==> CPU burst 1512ms ==> I/O burst 787ms
==> CPU burst 1764ms ==> I/O burst 84ms
==> CPU burst 1768ms

CPU-bound process A3: arrival time 758ms; 16 CPU bursts:
==> CPU burst 548ms ==> I/O burst 799ms
==> CPU burst 428ms ==> I/O burst 938ms
==> CPU burst 1432ms ==> I/O burst 317ms
==> CPU burst 3896ms ==> I/O burst 124ms
==> CPU burst 804ms ==> I/O burst 65ms
==> CPU burst 2564ms ==> I/O burst 380ms
==> CPU burst 3416ms ==> I/O burst 889ms
==> CPU burst 3756ms ==> I/O burst 651ms
==> CPU burst 3864ms ==> I/O burst 423ms
==> CPU burst 1144ms ==> I/O burst 150ms
==> CPU burst 492ms ==> I/O burst 368ms
==> CPU burst 2704ms ==> I/O burst 176ms
==> CPU burst 316ms ==> I/O burst 668ms
==> CPU burst 204ms ==> I/O burst 332ms
==> CPU burst 2328ms ==> I/O burst 896ms
==> CPU burst 2760ms

CPU-bound process A4: arrival time 346ms; 2 CPU bursts:
==> CPU burst 2428ms ==> I/O burst 509ms
==> CPU burst 2532ms

CPU-bound process A5: arrival time 115ms; 1 CPU burst:
==> CPU burst 564ms

I/O-bound process A6: arrival time 242ms; 27 CPU bursts:
==> CPU burst 761ms ==> I/O burst 2264ms
==> CPU burst 903ms ==> I/O burst 2048ms
==> CPU burst 303ms ==> I/O burst 7328ms
==> CPU burst 194ms ==> I/O burst 6896ms
==> CPU burst 203ms ==> I/O burst 2800ms
==> CPU burst 603ms ==> I/O burst 3064ms
==> CPU burst 95ms ==> I/O burst 1056ms
==> CPU burst 556ms ==> I/O burst 3376ms
==> CPU burst 599ms ==> I/O burst 560ms
==> CPU burst 58ms ==> I/O burst 2056ms
==> CPU burst 455ms ==> I/O burst 3112ms
==> CPU burst 826ms ==> I/O burst 2640ms
==> CPU burst 587ms ==> I/O burst 1920ms
==> CPU burst 292ms ==> I/O burst 4480ms
==> CPU burst 572ms ==> I/O burst 520ms
==> CPU burst 494ms ==> I/O burst 7088ms
==> CPU burst 19ms ==> I/O burst 4216ms
==> CPU burst 355ms ==> I/O burst 2968ms
==> CPU burst 81ms ==> I/O burst 7440ms
==> CPU burst 25ms ==> I/O burst 944ms
==> CPU burst 445ms ==> I/O burst 3208ms
==> CPU burst 35ms ==> I/O burst 3040ms
==> CPU burst 245ms ==> I/O burst 7240ms
==> CPU burst 732ms ==> I/O burst 2064ms
==> CPU burst 850ms ==> I/O burst 6800ms
==> CPU burst 667ms ==> I/O burst 248ms
==> CPU burst 370ms

I/O-bound process A7: arrival time 357ms; 21 CPU bursts:
==> CPU burst 297ms ==> I/O burst 7864ms
==> CPU burst 598ms ==> I/O burst 2456ms
==> CPU burst 721ms ==> I/O burst 2736ms
==> CPU burst 641ms ==> I/O burst 1944ms
==> CPU burst 128ms ==> I/O burst 6168ms
==> CPU burst 277ms ==> I/O burst 848ms
==> CPU burst 984ms ==> I/O burst 5208ms
==> CPU burst 961ms ==> I/O burst 3432ms
==> CPU burst 587ms ==> I/O burst 792ms
==> CPU burst 33ms ==> I/O burst 2584ms
==> CPU burst 875ms ==> I/O burst 2352ms
==> CPU burst 53ms ==> I/O burst 240ms
==> CPU burst 64ms ==> I/O burst 3496ms
==> CPU burst 264ms ==> I/O burst 1048ms
==> CPU burst 228ms ==> I/O burst 2264ms
==> CPU burst 37ms ==> I/O burst 5496ms
==> CPU burst 364ms ==> I/O burst 4312ms
==> CPU burst 278ms ==> I/O burst 2512ms
==> CPU burst 23ms ==> I/O burst 7880ms
==> CPU burst 188ms ==> I/O burst 3896ms
==> CPU burst 214ms

<<< PROJECT SIMULATIONS
<<< -- t_cs=6ms; alpha=<n/a>; t_slice=128ms; RR_ALT
time 0ms: Simulator started for FCFS [Q empty]
time 54ms: Process A0 arrived; added to ready queue [Q A0]
time 56ms: Process A1 arrived; added to ready queue [Q A1]
time 57ms: Process A0 started using the CPU for 3764ms burst [Q A1]
time 115ms: Process A5 arrived; added to ready queue [Q A1 A5]
time 242ms: Process A6 arrived; added to ready queue [Q A1 A5 A6]
time 346ms: Process A4 arrived; added to ready queue [Q A1 A5 A6 A4]
time 357ms: Process A7 arrived; added to ready queue [Q A1 A5 A6 A4 A7]
time 456ms: Process A2 arrived; added to ready queue [Q A1 A5 A6 A4 A7 A2]
time 758ms: Process A3 arrived; added to ready queue [Q A1 A5 A6 A4 A7 A2 A3]
time 3821ms: Process A0 completed a CPU burst; 28 bursts to go [Q A1 A5 A6 A4 A7 A2 A3]
time 3821ms: Process A0 switching out of CPU; blocking on I/O until time 4510ms [Q A1 A5 A6 A4 A7 A2 A3]
time 3827ms: Process A1 started using the CPU for 2828ms burst [Q A5 A6 A4 A7 A2 A3]
time 4510ms: Process A0 completed I/O; added to ready queue [Q A5 A6 A4 A7 A2 A3 A0]
time 6655ms: Process A1 completed a CPU burst; 30 bursts to go [Q A5 A6 A4 A7 A2 A3 A0]
time 6655ms: Process A1 switching out of CPU; blocking on I/O until time 6980ms [Q A5 A6 A4 A7 A2 A3 A0]
time 6661ms: Process A5 started using the CPU for 564ms burst [Q A6 A4 A7 A2 A3 A0]
time 6980ms: Process A1 completed I/O; added to ready queue [Q A6 A4 A7 A2 A3 A0 A1]
time 7225ms: Process A5 terminated [Q A6 A4 A7 A2 A3 A0 A1]
time 7231ms: Process A6 started using the CPU for 761ms burst [Q A4 A7 A2 A3 A0 A1]
time 7992ms: Process A6 completed a CPU burst; 26 bursts to go [Q A4 A7 A2 A3 A0 A1]
time 7992ms: Process A6 switching out of CPU; blocking on I/O until time 10259ms [Q A4 A7 A2 A3 A0 A1]
time 7998ms: Process A4 started using the CPU for 2428ms burst [Q A7 A2 A3 A0 A1]
time 19820ms: Process A4 terminated [Q A2 A3 A0 A1 A7 A6]
time 71120ms: Process A2 terminated [Q A6 A3 A7 A0 A1]
time 122158ms: Process A3 terminated [Q A7 A1 A6 A0]
time 174453ms: Process A0 terminated [Q A7 A1]
time 178763ms: Process A7 terminated [Q empty]
time 182131ms: Process A1 terminated [Q empty]
time 207272ms: Process A6 terminated [Q empty]
time 207275ms: Simulator ended for FCFS [Q empty]

time 0ms: Simulator started for SJF [Q empty]
time 54ms: Process A0 arrived; added to ready queue [Q A0]
time 56ms: Process A1 arrived; added to ready queue [Q A1]
time 57ms: Process A0 started using the CPU for 3764ms burst [Q A1]
time 115ms: Process A5 arrived; added to ready queue [Q A5 A1]
time 242ms: Process A6 arrived; added to ready queue [Q A5 A6 A1]
time 346ms: Process A4 arrived; added to ready queue [Q A5 A6 A4 A1]
time 357ms: Process A7 arrived; added to ready queue [Q A7 A5 A6 A4 A1]
time 456ms: Process A2 arrived; added to ready queue [Q A7 A5 A6 A2 A4 A1]
time 758ms: Process A3 arrived; added to ready queue [Q A7 A3 A5 A6 A2 A4 A1]
time 3821ms: Process A0 completed a CPU burst; 28 bursts to go [Q A7 A3 A5 A6 A2 A4 A1]
time 3821ms: Process A0 switching out of CPU; blocking on I/O until time 4510ms [Q A7 A3 A5 A6 A2 A4 A1]
time 3827ms: Process A7 started using the CPU for 297ms burst [Q A3 A5 A6 A2 A4 A1]
time 4124ms: Process A7 completed a CPU burst; 20 bursts to go [Q A3 A5 A6 A2 A4 A1]
time 4124ms: Process A7 switching out of CPU; blocking on I/O until time 11991ms [Q A3 A5 A6 A2 A4 A1]
time 4130ms: Process A3 started using the CPU for 548ms burst [Q A5 A6 A2 A4 A1]
time 4510ms: Process A0 completed I/O; added to ready queue [Q A5 A6 A0 A2 A4 A1]
time 4678ms: Process A3 completed a CPU burst; 15 bursts to go [Q A5 A6 A0 A2 A4 A1]
time 4678ms: Process A3 switching out of CPU; blocking on I/O until time 5480ms [Q A5 A6 A0 A2 A4 A1]
time 4684ms: Process A5 started using the CPU for 564ms burst [Q A6 A0 A2 A4 A1]
time 5248ms: Process A5 terminated [Q A6 A0 A2 A4 A1]
time 5254ms: Process A6 started using the CPU for 761ms burst [Q A0 A2 A4 A1]
time 5480ms: Process A3 completed I/O; added to ready queue [Q A3 A0 A2 A4 A1]
time 6015ms: Process A6 completed a CPU burst; 26 bursts to go [Q A3 A0 A2 A4 A1]
time 6015ms: Process A6 switching out of CPU; blocking on I/O until time 8282ms [Q A3 A0 A2 A4 A1]
time 6021ms: Process A3 started using the CPU for 428ms burst [Q A0 A2 A4 A1]
time 6449ms: Process A3 completed a CPU burst; 14 bursts to go [Q A0 A2 A4 A1]
time 6449ms: Process A3 switching out of CPU; blocking on I/O until time 7390ms [Q A0 A2 A4 A1]
time 6455ms: Process A0 started using the CPU for 1732ms burst [Q A2 A4 A1]
time 7390ms: Process A3 completed I/O; added to ready queue [Q A3 A2 A4 A1]
time 8187ms: Process A0 completed a CPU burst; 27 bursts to go [Q A3 A2 A4 A1]
time 8187ms: Process A0 switching out of CPU; blocking on I/O until time 8402ms [Q A3 A2 A4 A1]
time 8193ms: Process A3 started using the CPU for 1432ms burst [Q A2 A4 A1]
time 8282ms: Process A6 completed I/O; added to ready queue [Q A6 A2 A4 A1]
time 8402ms: Process A0 completed I/O; added to ready queue [Q A0 A6 A2 A4 A1]
time 9625ms: Process A3 completed a CPU burst; 13 bursts to go [Q A0 A6 A2 A4 A1]
time 9625ms: Process A3 switching out of CPU; blocking on I/O until time 9945ms [Q A0 A6 A2 A4 A1]
time 9631ms: Process A0 started using the CPU for 844ms burst [Q A6 A2 A4 A1]
time 9945ms: Process A3 completed I/O; added to ready queue [Q A6 A2 A4 A1 A3]
time 22192ms: Process A4 terminated [Q A6 A7 A0 A1 A2 A3]
time 71395ms: Process A2 terminated [Q A7 A3 A0 A1]
time 107929ms: Process A7 terminated [Q A3 A1]
time 132426ms: Process A3 terminated [Q A6 A0 A1]
time 143209ms: Process A6 terminated [Q A0]
time 162835ms: Process A0 terminated [Q A1]
time 189394ms: Process A1 terminated [Q empty]
time 189397ms: Simulator ended for SJF [Q empty]

time 0ms: Simulator started for SRT [Q empty]
time 54ms: Process A0 arrived; added to ready queue [Q A0]
time 56ms: Process A1 arrived; added to ready queue [Q A1]
time 57ms: Process A0 started using the CPU for 3764ms burst [Q A1]
time 57ms: Process A1 will preempt A0 [Q A1]
time 63ms: Process A1 started using the CPU for 2828ms burst [Q A0]
time 115ms: Process A5 arrived; preempting A1 [Q A5 A0]
time 121ms: Process A5 started using the CPU for 564ms burst [Q A1 A0]
time 242ms: Process A6 arrived; added to ready queue [Q A6 A1 A0]
time 346ms: Process A4 arrived; added to ready queue [Q A6 A4 A1 A0]
time 357ms: Process A7 arrived; preempting A5 [Q A7 A6 A4 A1 A0]
time 363ms: Process A7 started using the CPU for 297ms burst [Q A5 A6 A4 A1 A0]
time 456ms: Process A2 arrived; added to ready queue [Q A5 A6 A2 A4 A1 A0]
time 660ms: Process A7 completed a CPU burst; 20 bursts to go [Q A5 A6 A2 A4 A1 A0]
time 660ms: Process A7 switching out of CPU; blocking on I/O until time 8527ms [Q A5 A6 A2 A4 A1 A0]
time 666ms: Process A5 started using the CPU for remaining 328ms of 564ms burst [Q A6 A2 A4 A1 A0]
time 758ms: Process A3 arrived; added to ready queue [Q A3 A6 A2 A4 A1 A0]
time 994ms: Process A5 terminated [Q A3 A6 A2 A4 A1 A0]
time 1000ms: Process A3 started using the CPU for 548ms burst [Q A6 A2 A4 A1 A0]
time 1548ms: Process A3 completed a CPU burst; 15 bursts to go [Q A6 A2 A4 A1 A0]
time 1548ms: Process A3 switching out of CPU; blocking on I/O until time 2350ms [Q A6 A2 A4 A1 A0]
time 1554ms: Process A6 started using the CPU for 761ms burst [Q A2 A4 A1 A0]
time 2315ms: Process A6 completed a CPU burst; 26 bursts to go [Q A2 A4 A1 A0]
time 2315ms: Process A6 switching out of CPU; blocking on I/O until time 4582ms [Q A2 A4 A1 A0]
time 2321ms: Process A2 started using the CPU for 1896ms burst [Q A4 A1 A0]
time 2350ms: Process A3 completed I/O; preempting A2 [Q A3 A4 A1 A0]
time 2356ms: Process A3 started using the CPU for 428ms burst [Q A2 A4 A1 A0]
time 2784ms: Process A3 completed a CPU burst; 14 bursts to go [Q A2 A4 A1 A0]
time 2784ms: Process A3 switching out of CPU; blocking on I/O until time 3725ms [Q A2 A4 A1 A0]
time 2790ms: Process A2 started using the CPU for remaining 1867ms of 1896ms burst [Q A4 A1 A0]
time 3725ms: Process A3 completed I/O; added to ready queue [Q A3 A4 A1 A0]
time 4582ms: Process A6 completed I/O; added to ready queue [Q A6 A3 A4 A1 A0]
time 4657ms: Process A2 completed a CPU burst; 8 bursts to go [Q A6 A3 A4 A1 A0]
time 4657ms: Process A2 switching out of CPU; blocking on I/O until time 5278ms [Q A6 A3 A4 A1 A0]
time 4663ms: Process A6 started using the CPU for 903ms burst [Q A3 A4 A1 A0]
time 5278ms: Process A2 completed I/O; added to ready queue [Q A3 A4 A1 A2 A0]
time 5566ms: Process A6 completed a CPU burst; 25 bursts to go [Q A3 A4 A1 A2 A0]
time 5566ms: Process A6 switching out of CPU; blocking on I/O until time 7617ms [Q A3 A4 A1 A2 A0]
time 5572ms: Process A3 started using the CPU for 1432ms burst [Q A4 A1 A2 A0]
time 7004ms: Process A3 completed a CPU burst; 13 bursts to go [Q A4 A1 A2 A0]
time 7004ms: Process A3 switching out of CPU; blocking on I/O until time 7324ms [Q A4 A1 A2 A0]
time 7010ms: Process A4 started using the CPU for 2428ms burst [Q A1 A2 A0]
time 7324ms: Process A3 completed I/O; added to ready queue [Q A1 A2 A0 A3]
time 7617ms: Process A6 completed I/O; preempting A4 [Q A6 A1 A2 A0 A3]
time 7623ms: Process A6 started using the CPU for 303ms burst [Q A4 A1 A2 A0 A3]
time 7926ms: Process A6 completed a CPU burst; 24 bursts to go [Q A4 A1 A2 A0 A3]
time 7926ms: Process A6 switching out of CPU; blocking on I/O until time 15257ms [Q A4 A1 A2 A0 A3]
time 7932ms: Process A4 started using the CPU for remaining 1821ms of 2428ms burst [Q A1 A2 A0 A3]
time 8527ms: Process A7 completed I/O; preempting A4 [Q A7 A1 A2 A0 A3]
time 8533ms: Process A7 started using the CPU for 598ms burst [Q A4 A1 A2 A0 A3]
time 9131ms: Process A7 completed a CPU burst; 19 bursts to go [Q A4 A1 A2 A0 A3]
time 9131ms: Process A7 switching out of CPU; blocking on I/O until time 11590ms [Q A4 A1 A2 A0 A3]
time 9137ms: Process A4 started using the CPU for remaining 1226ms of 2428ms burst [Q A1 A2 A0 A3]
time 18865ms: Process A4 terminated [Q A1 A2 A0 A3]
time 56407ms: Process A2 terminated [Q A0 A3 A1]
time 80152ms: Process A7 terminated [Q A0 A3 A1]
time 104496ms: Process A6 terminated [Q A3 A0 A1]
time 125091ms: Process A3 terminated [Q A0 A1]
time 157480ms: Process A0 terminated [Q A1]
time 190342ms: Process A1 terminated [Q empty]
time 190345ms: Simulator ended for SRT [Q empty]

time 0ms: Simulator started for RR [Q empty]
time 54ms: Process A0 arrived; added to ready queue [Q A0]
time 56ms: Process A1 arrived; added to ready queue [Q A1]
time 57ms: Process A0 started using the CPU for 3764ms burst [Q A1]
time 115ms: Process A5 arrived; added to ready queue [Q A1 A5]
time 185ms: Time slice expired; preempting process A0 with 3636ms remaining [Q A1 A5]
time 191ms: Process A1 started using the CPU for 2828ms burst [Q A0 A5]
time 242ms: Process A6 arrived; added to ready queue [Q A0 A5 A6]
time 319ms: Time slice expired; preempting process A1 with 2700ms remaining [Q A0 A5 A6]
time 325ms: Process A0 started using the CPU for remaining 3636ms of 3764ms burst [Q A1 A5 A6]
time 346ms: Process A4 arrived; added to ready queue [Q A1 A5 A6 A4]
time 357ms: Process A7 arrived; added to ready queue [Q A1 A5 A6 A4 A7]
time 453ms: Time slice expired; preempting process A0 with 3508ms remaining [Q A1 A5 A6 A4 A7]
time 456ms: Process A2 arrived; added to ready queue [Q A1 A0 A5 A6 A4 A7 A2]
time 459ms: Process A1 started using the CPU for remaining 2700ms of 2828ms burst [Q A0 A5 A6 A4 A7 A2]
time 587ms: Time slice expired; preempting process A1 with 2572ms remaining [Q A0 A5 A6 A4 A7 A2]
time 593ms: Process A0 started using the CPU for remaining 3508ms of 3764ms burst [Q A1 A5 A6 A4 A7 A2]
time 721ms: Time slice expired; preempting process A0 with 3380ms remaining [Q A1 A5 A6 A4 A7 A2]
time 727ms: Process A1 started using the CPU for remaining 2572ms of 2828ms burst [Q A0 A5 A6 A4 A7 A2]
time 758ms: Process A3 arrived; added to ready queue [Q A0 A5 A6 A4 A7 A2 A3]
time 855ms: Time slice expired; preempting process A1 with 2444ms remaining [Q A0 A5 A6 A4 A7 A2 A3]
time 861ms: Process A0 started using the CPU for remaining 3380ms of 3764ms burst [Q A1 A5 A6 A4 A7 A2 A3]
time 989ms: Time slice expired; preempting process A0 with 3252ms remaining [Q A1 A5 A6 A4 A7 A2 A3]
time 995ms: Process A1 started using the CPU for remaining 2444ms of 2828ms burst [Q A0 A5 A6 A4 A7 A2 A3]
time 1123ms: Time slice expired; preempting process A1 with 2316ms remaining [Q A0 A5 A6 A4 A7 A2 A3]
time 1129ms: Process A0 started using the CPU for remaining 3252ms of 3764ms burst [Q A1 A5 A6 A4 A7 A2 A3]
time 1257ms: Time slice expired; preempting process A0 with 3124ms remaining [Q A1 A5 A6 A4 A7 A2 A3]
time 1263ms: Process A1 started using the CPU for remaining 2316ms of 2828ms burst [Q A0 A5 A6 A4 A7 A2 A3]
time 1391ms: Time slice expired; preempting process A1 with 2188ms remaining [Q A0 A5 A6 A4 A7 A2 A3]
time 1397ms: Process A0 started using the CPU for remaining 3124ms of 3764ms burst [Q A1 A5 A6 A4 A7 A2 A3]
time 1525ms: Time slice expired; preempting process A0 with 2996ms remaining [Q A1 A5 A6 A4 A7 A2 A3]
time 1531ms: Process A1 started using the CPU for remaining 2188ms of 2828ms burst [Q A0 A5 A6 A4 A7 A2 A3]
time 1659ms: Time slice expired; preempting process A1 with 2060ms remaining [Q A0 A5 A6 A4 A7 A2 A3]
time 1665ms: Process A0 started using the CPU for remaining 2996ms of 3764ms burst [Q A1 A5 A6 A4 A7 A2 A3]
time 1793ms: Time slice expired; preempting process A0 with 2868ms remaining [Q A1 A5 A6 A4 A7 A2 A3]
time 1799ms: Process A1 started using the CPU for remaining 2060ms of 2828ms burst [Q A0 A5 A6 A4 A7 A2 A3]
time 1927ms: Time slice expired; preempting process A1 with 1932ms remaining [Q A0 A5 A6 A4 A7 A2 A3]
time 1933ms: Process A0 started using the CPU for remaining 2868ms of 3764ms burst [Q A1 A5 A6 A4 A7 A2 A3]
time 2061ms: Time slice expired; preempting process A0 with 2740ms remaining [Q A1 A5 A6 A4 A7 A2 A3]
time 2067ms: Process A1 started using the CPU for remaining 1932ms of 2828ms burst [Q A0 A5 A6 A4 A7 A2 A3]
time 2195ms: Time slice expired; preempting process A1 with 1804ms remaining [Q A0 A5 A6 A4 A7 A2 A3]
time 2201ms: Process A0 started using the CPU for remaining 2740ms of 3764ms burst [Q A1 A5 A6 A4 A7 A2 A3]
time 2329ms: Time slice expired; preempting process A0 with 2612ms remaining [Q A1 A5 A6 A4 A7 A2 A3]
time 2335ms: Process A1 started using the CPU for remaining 1804ms of 2828ms burst [Q A0 A5 A6 A4 A7 A2 A3]
time 2463ms: Time slice expired; preempting process A1 with 1676ms remaining [Q A0 A5 A6 A4 A7 A2 A3]
time 2469ms: Process A0 started using the CPU for remaining 2612ms of 3764ms burst [Q A1 A5 A6 A4 A7 A2 A3]
time 2597ms: Time slice expired; preempting process A0 with 2484ms remaining [Q A1 A5 A6 A4 A7 A2 A3]
time 2603ms: Process A1 started using the CPU for remaining 1676ms of 2828ms burst [Q A0 A5 A6 A4 A7 A2 A3]
time 2731ms: Time slice expired; preempting process A1 with 1548ms remaining [Q A0 A5 A6 A4 A7 A2 A3]
time 2737ms: Process A0 started using the CPU for remaining 2484ms of 3764ms burst [Q A1 A5 A6 A4 A7 A2 A3]
time 2865ms: Time slice expired; preempting process A0 with 2356ms remaining [Q A1 A5 A6 A4 A7 A2 A3]
time 2871ms: Process A1 started using the CPU for remaining 1548ms of 2828ms burst [Q A0 A5 A6 A4 A7 A2 A3]
time 2999ms: Time slice expired; preempting process A1 with 1420ms remaining [Q A0 A5 A6 A4 A7 A2 A3]
time 3005ms: Process A0 started using the CPU for remaining 2356ms of 3764ms burst [Q A1 A5 A6 A4 A7 A2 A3]
time 3133ms: Time slice expired; preempting process A0 with 2228ms remaining [Q A1 A5 A6 A4 A7 A2 A3]
time 3139ms: Process A1 started using the CPU for remaining 1420ms of 2828ms burst [Q A0 A5 A6 A4 A7 A2 A3]
time 3267ms: Time slice expired; preempting process A1 with 1292ms remaining [Q A0 A5 A6 A4 A7 A2 A3]
time 3273ms: Process A0 started using the CPU for remaining 2228ms of 3764ms burst [Q A1 A5 A6 A4 A7 A2 A3]
time 3401ms: Time slice expired; preempting process A0 with 2100ms remaining [Q A1 A5 A6 A4 A7 A2 A3]
time 3407ms: Process A1 started using the CPU for remaining 1292ms of 2828ms burst [Q A0 A5 A6 A4 A7 A2 A3]
time 3535ms: Time slice expired; preempting process A1 with 1164ms remaining [Q A0 A5 A6 A4 A7 A2 A3]
time 3541ms: Process A0 started using the CPU for remaining 2100ms of 3764ms burst [Q A1 A5 A6 A4 A7 A2 A3]
time 3669ms: Time slice expired; preempting process A0 with 1972ms remaining [Q A1 A5 A6 A4 A7 A2 A3]
time 3675ms: Process A1 started using the CPU for remaining 1164ms of 2828ms burst [Q A0 A5 A6 A4 A7 A2 A3]
time 3803ms: Time slice expired; preempting process A1 with 1036ms remaining [Q A0 A5 A6 A4 A7 A2 A3]
time 3809ms: Process A0 started using the CPU for remaining 1972ms of 3764ms burst [Q A1 A5 A6 A4 A7 A2 A3]
time 3937ms: Time slice expired; preempting process A0 with 1844ms remaining [Q A1 A5 A6 A4 A7 A2 A3]
time 3943ms: Process A1 started using the CPU for remaining 1036ms of 2828ms burst [Q A0 A5 A6 A4 A7 A2 A3]
time 4071ms: Time slice expired; preempting process A1 with 908ms remaining [Q A0 A5 A6 A4 A7 A2 A3]
time 4077ms: Process A0 started using the CPU for remaining 1844ms of 3764ms burst [Q A1 A5 A6 A4 A7 A2 A3]
time 4205ms: Time slice expired; preempting process A0 with 1716ms remaining [Q A1 A5 A6 A4 A7 A2 A3]
time 4211ms: Process A1 started using the CPU for remaining 908ms of 2828ms burst [Q A0 A5 A6 A4 A7 A2 A3]
time 4339ms: Time slice expired; preempting process A1 with 780ms remaining [Q A0 A5 A6 A4 A7 A2 A3]
time 4345ms: Process A0 started using the CPU for remaining 1716ms of 3764ms burst [Q A1 A5 A6 A4 A7 A2 A3]
time 4473ms: Time slice expired; preempting process A0 with 1588ms remaining [Q A1 A5 A6 A4 A7 A2 A3]
time 4479ms: Process A1 started using the CPU for remaining 780ms of 2828ms burst [Q A0 A5 A6 A4 A7 A2 A3]
time 4607ms: Time slice expired; preempting process A1 with 652ms remaining [Q A0 A5 A6 A4 A7 A2 A3]
time 4613ms: Process A0 started using the CPU for remaining 1588ms of 3764ms burst [Q A1 A5 A6 A4 A7 A2 A3]
time 4741ms: Time slice expired; preempting process A0 with 1460ms remaining [Q A1 A5 A6 A4 A7 A2 A3]
time 4747ms: Process A1 started using the CPU for remaining 652ms of 2828ms burst [Q A0 A5 A6 A4 A7 A2 A3]
time 4875ms: Time slice expired; preempting process A1 with 524ms remaining [Q A0 A5 A6 A4 A7 A2 A3]
time 4881ms: Process A0 started using the CPU for remaining 1460ms of 3764ms burst [Q A1 A5 A6 A4 A7 A2 A3]
time 5009ms: Time slice expired; preempting process A0 with 1332ms remaining [Q A1 A5 A6 A4 A7 A2 A3]
time 5015ms: Process A1 started using the CPU for remaining 524ms of 2828ms burst [Q A0 A5 A6 A4 A7 A2 A3]
time 5143ms: Time slice expired; preempting process A1 with 396ms remaining [Q A0 A5 A6 A4 A7 A2 A3]
time 5149ms: Process A0 started using the CPU for remaining 1332ms of 3764ms burst [Q A1 A5 A6 A4 A7 A2 A3]
time 5277ms: Time slice expired; preempting process A0 with 1204ms remaining [Q A1 A5 A6 A4 A7 A2 A3]
time 5283ms: Process A1 started using the CPU for remaining 396ms of 2828ms burst [Q A0 A5 A6 A4 A7 A2 A3]
time 5411ms: Time slice expired; preempting process A1 with 268ms remaining [Q A0 A5 A6 A4 A7 A2 A3]
time 5417ms: Process A0 started using the CPU for remaining 1204ms of 3764ms burst [Q A1 A5 A6 A4 A7 A2 A3]
time 5545ms: Time slice expired; preempting process A0 with 1076ms remaining [Q A1 A5 A6 A4 A7 A2 A3]
time 5551ms: Process A1 started using the CPU for remaining 268ms of 2828ms burst [Q A0 A5 A6 A4 A7 A2 A3]
time 5679ms: Time slice expired; preempting process A1 with 140ms remaining [Q A0 A5 A6 A4 A7 A2 A3]
time 5685ms: Process A0 started using the CPU for remaining 1076ms of 3764ms burst [Q A1 A5 A6 A4 A7 A2 A3]
time 5813ms: Time slice expired; preempting process A0 with 948ms remaining [Q A1 A5 A6 A4 A7 A2 A3]
time 5819ms: Process A1 started using the CPU for remaining 140ms of 2828ms burst [Q A0 A5 A6 A4 A7 A2 A3]
time 5947ms: Time slice expired; preempting process A1 with 12ms remaining [Q A0 A5 A6 A4 A7 A2 A3]
time 5953ms: Process A0 started using the CPU for remaining 948ms of 3764ms burst [Q A1 A5 A6 A4 A7 A2 A3]
time 6081ms: Time slice expired; preempting process A0 with 820ms remaining [Q A1 A5 A6 A4 A7 A2 A3]
time 6087ms: Process A1 started using the CPU for remaining 12ms of 2828ms burst [Q A0 A5 A6 A4 A7 A2 A3]
time 6099ms: Process A1 completed a CPU burst; 30 bursts to go [Q A0 A5 A6 A4 A7 A2 A3]
time 6099ms: Process A1 switching out of CPU; blocking on I/O until time 6424ms [Q A0 A5 A6 A4 A7 A2 A3]
time 6105ms: Process A0 started using the CPU for remaining 820ms of 3764ms burst [Q A5 A6 A4 A7 A2 A3]
time 6233ms: Time slice expired; preempting process A0 with 692ms remaining [Q A5 A6 A4 A7 A2 A3]
time 6239ms: Process A5 started using the CPU for 564ms burst [Q A0 A6 A4 A7 A2 A3]
time 6367ms: Time slice expired; preempting process A5 with 436ms remaining [Q A0 A6 A4 A7 A2 A3]
time 6373ms: Process A0 started using the CPU for remaining 692ms of 3764ms burst [Q A5 A6 A4 A7 A2 A3]
time 6424ms: Process A1 completed I/O; added to ready queue [Q A5 A6 A4 A7 A2 A3 A1]
time 6501ms: Time slice expired; preempting process A0 with 564ms remaining [Q A5 A6 A4 A7 A2 A3 A1]
time 6507ms: Process A5 started using the CPU for remaining 436ms of 564ms burst [Q A0 A6 A4 A7 A2 A3 A1]
time 6635ms: Time slice expired; preempting process A5 with 308ms remaining [Q A0 A6 A4 A7 A2 A3 A1]
time 6641ms: Process A0 started using the CPU for remaining 564ms of 3764ms burst [Q A5 A6 A4 A7 A2 A3 A1]
time 6769ms: Time slice expired; preempting process A0 with 436ms remaining [Q A5 A6 A4 A7 A2 A3 A1]
time 6775ms: Process A5 started using the CPU for remaining 308ms of 564ms burst [Q A0 A6 A4 A7 A2 A3 A1]
time 6903ms: Time slice expired; preempting process A5 with 180ms remaining [Q A0 A6 A4 A7 A2 A3 A1]
time 6909ms: Process A0 started using the CPU for remaining 436ms of 3764ms burst [Q A5 A6 A4 A7 A2 A3 A1]
time 7037ms: Time slice expired; preempting process A0 with 308ms remaining [Q A5 A6 A4 A7 A2 A3 A1]
time 7043ms: Process A5 started using the CPU for remaining 180ms of 564ms burst [Q A0 A6 A4 A7 A2 A3 A1]
time 7171ms: Time slice expired; preempting process A5 with 52ms remaining [Q A0 A6 A4 A7 A2 A3 A1]
time 7177ms: Process A0 started using the CPU for remaining 308ms of 3764ms burst [Q A5 A6 A4 A7 A2 A3 A1]
time 7305ms: Time slice expired; preempting process A0 with 180ms remaining [Q A5 A6 A4 A7 A2 A3 A1]
time 7311ms: Process A5 started using the CPU for remaining 52ms of 564ms burst [Q A0 A6 A4 A7 A2 A3 A1]
time 7363ms: Process A5 terminated [Q A0 A6 A4 A7 A2 A3 A1]
time 7369ms: Process A0 started using the CPU for remaining 180ms of 3764ms burst [Q A6 A4 A7 A2 A3 A1]
time 7497ms: Time slice expired; preempting process A0 with 52ms remaining [Q A6 A4 A7 A2 A3 A1]
time 7503ms: Process A6 started using the CPU for 761ms burst [Q A0 A4 A7 A2 A3 A1]
time 7631ms: Time slice expired; preempting process A6 with 633ms remaining [Q A0 A4 A7 A2 A3 A1]
time 7637ms: Process A0 started using the CPU for remaining 52ms of 3764ms burst [Q A6 A4 A7 A2 A3 A1]
time 7689ms: Process A0 completed a CPU burst; 28 bursts to go [Q A6 A4 A7 A2 A3 A1]
time 7689ms: Process A0 switching out of CPU; blocking on I/O until time 8378ms [Q A6 A4 A7 A2 A3 A1]
time 7695ms: Process A6 started using the CPU for remaining 633ms of 761ms burst [Q A4 A7 A2 A3 A1]
time 7823ms: Time slice expired; preempting process A6 with 505ms remaining [Q A4 A7 A2 A3 A1]
time 7829ms: Process A4 started using the CPU for 2428ms burst [Q A6 A7 A2 A3 A1]
time 7957ms: Time slice expired; preempting process A4 with 2300ms remaining [Q A6 A7 A2 A3 A1]
time 7963ms: Process A6 started using the CPU for remaining 505ms of 761ms burst [Q A4 A7 A2 A3 A1]
time 8091ms: Time slice expired; preempting process A6 with 377ms remaining [Q A4 A7 A2 A3 A1]
time 8097ms: Process A4 started using the CPU for remaining 2300ms of 2428ms burst [Q A6 A7 A2 A3 A1]
time 8225ms: Time slice expired; preempting process A4 with 2172ms remaining [Q A6 A7 A2 A3 A1]
time 8231ms: Process A6 started using the CPU for remaining 377ms of 761ms burst [Q A4 A7 A2 A3 A1]
time 8359ms: Time slice expired; preempting process A6 with 249ms remaining [Q A4 A7 A2 A3 A1]
time 8365ms: Process A4 started using the CPU for remaining 2172ms of 2428ms burst [Q A6 A7 A2 A3 A1]
time 8378ms: Process A0 completed I/O; added to ready queue [Q A6 A7 A2 A3 A1 A0]
time 8493ms: Time slice expired; preempting process A4 with 2044ms remaining [Q A6 A7 A2 A3 A1 A0]
time 8499ms: Process A6 started using the CPU for remaining 249ms of 761ms burst [Q A4 A7 A2 A3 A1 A0]
time 8627ms: Time slice expired; preempting process A6 with 121ms remaining [Q A4 A7 A2 A3 A1 A0]
time 8633ms: Process A4 started using the CPU for remaining 2044ms of 2428ms burst [Q A6 A7 A2 A3 A1 A0]
time 8761ms: Time slice expired; preempting process A4 with 1916ms remaining [Q A6 A7 A2 A3 A1 A0]
time 8767ms: Process A6 started using the CPU for remaining 121ms of 761ms burst [Q A4 A7 A2 A3 A1 A0]
time 8888ms: Process A6 completed a CPU burst; 26 bursts to go [Q A4 A7 A2 A3 A1 A0]
time 8888ms: Process A6 switching out of CPU; blocking on I/O until time 11155ms [Q A4 A7 A2 A3 A1 A0]
time 8894ms: Process A4 started using the CPU for remaining 1916ms of 2428ms burst [Q A7 A2 A3 A1 A0]
time 9022ms: Time slice expired; preempting process A4 with 1788ms remaining [Q A7 A2 A3 A1 A0]
time 9028ms: Process A7 started using the CPU for 297ms burst [Q A4 A2 A3 A1 A0]
time 9156ms: Time slice expired; preempting process A7 with 169ms remaining [Q A4 A2 A3 A1 A0]
time 9162ms: Process A4 started using the CPU for remaining 1788ms of 2428ms burst [Q A7 A2 A3 A1 A0]
time 9290ms: Time slice expired; preempting process A4 with 1660ms remaining [Q A7 A2 A3 A1 A0]
time 9296ms: Process A7 started using the CPU for remaining 169ms of 297ms burst [Q A4 A2 A3 A1 A0]
time 9424ms: Time slice expired; preempting process A7 with 41ms remaining [Q A4 A2 A3 A1 A0]
time 9430ms: Process A4 started using the CPU for remaining 1660ms of 2428ms burst [Q A7 A2 A3 A1 A0]
time 9558ms: Time slice expired; preempting process A4 with 1532ms remaining [Q A7 A2 A3 A1 A0]
time 9564ms: Process A7 started using the CPU for remaining 41ms of 297ms burst [Q A4 A2 A3 A1 A0]
time 9605ms: Process A7 completed a CPU burst; 20 bursts to go [Q A4 A2 A3 A1 A0]
time 9605ms: Process A7 switching out of CPU; blocking on I/O until time 17472ms [Q A4 A2 A3 A1 A0]
time 9611ms: Process A4 started using the CPU for remaining 1532ms of 2428ms burst [Q A2 A3 A1 A0]
time 9739ms: Time slice expired; preempting process A4 with 1404ms remaining [Q A2 A3 A1 A0]
time 9745ms: Process A2 started using the CPU for 1896ms burst [Q A4 A3 A1 A0]
time 9873ms: Time slice expired; preempting process A2 with 1768ms remaining [Q A4 A3 A1 A0]
time 9879ms: Process A4 started using the CPU for remaining 1404ms of 2428ms burst [Q A2 A3 A1 A0]
time 22718ms: Process A4 terminated [Q A2 A3 A1 A7 A0 A6]
time 71492ms: Process A2 terminated [Q A3 A1 A0 A6]
time 130678ms: Process A3 terminated [Q A1 A6 A0]
time 167794ms: Process A7 terminated [Q A1 A6]
time 186994ms: Process A0 terminated [Q A1]
time 189848ms: Process A1 terminated [Q empty]
time 202293ms: Process A6 terminated [Q empty]
time 202296ms: Simulator ended for RR [Q empty]
