<<< -- process set (n=8) with 6 CPU-bound processes
<<< -- seed=768; lambda=0.001000; bound=1024

CPU-bound process A0: arrival time 54ms; 29 CPU bursts:
==> CPU burst 3764ms ==> I/O burst 686ms
==> CPU burst 1732ms ==> I/O burst 212ms
==> CPU burst 844ms ==> I/O burst 493ms
==> CPU burst 168ms ==> I/O burst 372ms
==> CPU burst 736ms ==> I/O burst 141ms
==> CPU burst 1372ms ==> I/O burst 554ms
==> CPU burst 1808ms ==> I/O burst 149ms
==> CPU burst 1808ms ==> I/O burst 266ms
==> CPU burst 848ms ==> I/O burst 75ms
==> CPU burst 3384ms ==> I/O burst 17ms
==> CPU burst 104ms ==> I/O burst 428ms
==> CPU burst 3924ms ==> I/O burst 667ms
==> CPU burst 3388ms ==> I/O burst 94ms
==> CPU burst 100ms ==> I/O burst 487ms
==> CPU burst 3868ms ==> I/O burst 112ms
==> CPU burst 1516ms ==> I/O burst 311ms
==> CPU burst 1260ms ==> I/O burst 413ms
==> CPU burst 728ms ==> I/O burst 773ms
==> CPU burst 2568ms ==> I/O burst 348ms
==> CPU burst 1220ms ==> I/O burst 883ms
==> CPU burst 2296ms ==> I/O burst 664ms
==> CPU burst 3268ms ==> I/O burst 923ms
==> CPU burst 3468ms ==> I/O burst 288ms
==> CPU burst 2392ms ==> I/O burst 108ms
==> CPU burst 1976ms ==> I/O burst 564ms
==> CPU burst 312ms ==> I/O burst 545ms
==> CPU burst 1440ms ==> I/O burst 136ms
==> CPU burst 3052ms ==> I/O burst 558ms
==> CPU burst 2044ms

CPU-bound process A1: arrival time 56ms; 31 CPU bursts:
==> CPU burst 2828ms ==> I/O burst 322ms
==> CPU burst 1444ms ==> I/O burst 167ms
==> CPU burst 2476ms ==> I/O burst 417ms
==> CPU burst 2256ms ==> I/O burst 290ms
==> CPU burst 1188ms ==> I/O burst 777ms
==> CPU burst 2812ms ==> I/O burst 863ms
==> CPU burst 368ms ==> I/O burst 173ms
==> CPU burst 200ms ==> I/O burst 607ms
==> CPU burst 1044ms ==> I/O burst 592ms
==> CPU burst 940ms ==> I/O burst 445ms
==> CPU burst 660ms ==> I/O burst 28ms
==> CPU burst 2196ms ==> I/O burst 976ms
==> CPU burst 36ms ==> I/O burst 637ms
==> CPU burst 4060ms ==> I/O burst 90ms
==> CPU burst 3904ms ==> I/O burst 534ms
==> CPU burst 1488ms ==> I/O burst 404ms
==> CPU burst 1080ms ==> I/O burst 51ms
==> CPU burst 916ms ==> I/O burst 71ms
==> CPU burst 3724ms ==> I/O burst 111ms
==> CPU burst 1764ms ==> I/O burst 282ms
==> CPU burst 860ms ==> I/O burst 99ms
==> CPU burst 2700ms ==> I/O burst 767ms
==> CPU burst 100ms ==> I/O burst 586ms
==> CPU burst 420ms ==> I/O burst 709ms
==> CPU burst 3504ms ==> I/O burst 671ms
==> CPU burst 3504ms ==> I/O burst 334ms
==> CPU burst 2352ms ==> I/O burst 251ms
==> CPU burst 2652ms ==> I/O burst 768ms
==> CPU burst 3812ms ==> I/O burst 527ms
==> CPU burst 2288ms ==> I/O burst 166ms
==> CPU burst 388ms

CPU-bound process A2: arrival time 456ms; 9 CPU bursts:
==> CPU burst 1896ms ==> I/O burst 618ms
==> CPU burst 2940ms ==> I/O burst 439ms
==> CPU burst 248ms ==> I/O burst 464ms
==> CPU burst 952ms ==> I/O burst 774ms
==> CPU burst 1796ms ==> I/O burst 411ms
==> CPU burst 2200ms ==> I/O burst 15ms
==> CPU burst 1512ms ==> I/O burst 787ms
==> CPU burst 1764ms ==> I/O burst 84ms
==> CPU burst 1768ms

CPU-bound process A3: arrival time 758ms; 16 CPU bursts:
==> CPU burst 548ms ==> I/O burst 799ms
==> CPU burst 428ms ==> I/O burst 938ms
==> CPU burst 1432ms ==> I/O burst 317ms
==> CPU burst 3896ms ==> I/O burst 124ms
==> CPU burst 804ms ==> I/O burst 65ms
==> CPU burst 2564ms ==> I/O burst 380ms
==> CPU burst 3416ms ==> I/O burst 889ms
==> CPU burst 3756ms ==> I/O burst 651ms
==> CPU burst 3864ms ==> I/O burst 423ms
==> CPU burst 1144ms ==> I/O burst 150ms
==> CPU burst 492ms ==> I/O burst 368ms
==> CPU burst 2704ms ==> I/O burst 176ms
==> CPU burst 316ms ==> I/O burst 668ms
==> CPU burst 204ms ==> I/O burst 332ms
==> CPU burst 2328ms ==> I/O burst 896ms
==> CPU burst 2760ms

CPU-bound process A4: arrival time 346ms; 2 CPU bursts:
==> CPU burst 2428ms ==> I/O burst 509ms
==> CPU burst 2532ms

CPU-bound process A5: arrival time 115ms; 1 CPU burst:
==> CPU burst 564ms

I/O-bound process A6: arrival time 242ms; 27 CPU bursts:
==> CPU burst 761ms ==> I/O burst 2264ms
==> CPU burst 903ms ==> I/O burst 2048ms
==> CPU burst 303ms ==> I/O burst 7328ms
==> CPU burst 194ms ==> I/O burst 6896ms
==> CPU burst 203ms ==> I/O burst 2800ms
==> CPU burst 603ms ==> I/O burst 3064ms
==> CPU burst 95ms ==> I/O burst 1056ms
==> CPU burst 556ms ==> I/O burst 3376ms
==> CPU burst 599ms ==> I/O burst 560ms
==> CPU burst 58ms ==> I/O burst 2056ms
==> CPU burst 455ms ==> I/O burst 3112ms
==> CPU burst 826ms ==> I/O burst 2640ms
==> CPU burst 587ms ==> I/O burst 1920ms
==> CPU burst 292ms ==> I/O burst 4480ms
==> CPU burst 572ms ==> I/O burst 520ms
==> CPU burst 494ms ==> I/O burst 7088ms
==> CPU burst 19ms ==> I/O burst 4216ms
==> CPU burst 355ms ==> I/O burst 2968ms
==> CPU burst 81ms ==> I/O burst 7440ms
==> CPU burst 25ms ==> I/O burst 944ms
==> CPU burst 445ms ==> I/O burst 3208ms
==> CPU burst 35ms ==> I/O burst 3040ms
==> CPU burst 245ms ==> I/O burst 7240ms
==> CPU burst 732ms ==> I/O burst 2064ms
==> CPU burst 850ms ==> I/O burst 6800ms
==> CPU burst 667ms ==> I/O burst 248ms
==> CPU burst 370ms

I/O-bound process A7: arrival time 357ms; 21 CPU bursts:
==> CPU burst 297ms ==> I/O burst 7864ms
==> CPU burst 598ms ==> I/O burst 2456ms
==> CPU burst 721ms ==> I/O burst 2736ms
==> CPU burst 641ms ==> I/O burst 1944ms
==> CPU burst 128ms ==> I/O burst 6168ms
==> CPU burst 277ms ==> I/O burst 848ms
==> CPU burst 984ms ==> I/O burst 5208ms
==> CPU burst 961ms ==> I/O burst 3432ms
==> CPU burst 587ms ==> I/O burst 792ms
==> CPU burst 33ms ==> I/O burst 2584ms
==> CPU burst 875ms ==> I/O burst 2352ms
==> CPU burst 53ms ==> I/O burst 240ms
==> CPU burst 64ms ==> I/O burst 3496ms
==> CPU burst 264ms ==> I/O burst 1048ms
==> CPU burst 228ms ==> I/O burst 2264ms
==> CPU burst 37ms ==> I/O burst 5496ms
==> CPU burst 364ms ==> I/O burst 4312ms
==> CPU burst 278ms ==> I/O burst 2512ms
==> CPU burst 23ms ==> I/O burst 7880ms
==> CPU burst 188ms ==> I/O burst 3896ms
==> CPU burst 214ms

<<< PROJECT SIMULATIONS
<<< -- t_cs=6ms; alpha=<n/a>; t_slice=128ms; RR_ALT
time 0ms: Simulator started for FCFS [Q empty]
time 54ms: Process A0 arrived; added to ready queue [Q A0]
time 56ms: Process A1 arrived; added to ready queue [Q A1]
time 57ms: Process A0 started using the CPU for 3764ms burst [Q A1]
time 115ms: Process A5 arrived; added to ready queue [Q A1 A5]
time 242ms: Process A6 arrived; added to ready queue [Q A1 A5 A6]
time 346ms: Process A4 arrived; added to ready queue [Q A1 A5 A6 A4]
time 357ms: Process A7 arrived; added to ready queue [Q A1 A5 A6 A4 A7]
time 456ms: Process A2 arrived; added to ready queue [Q A1 A5 A6 A4 A7 A2]
time 758ms: Process A3 arrived; added to ready queue [Q A1 A5 A6 A4 A7 A2 A3]
time 3821ms: Process A0 completed a CPU burst; 28 bursts to go [Q A1 A5 A6 A4 A7 A2 A3]
time 3821ms: Process A0 switching out of CPU; blocking on I/O until time 4510ms [Q A1 A5 A6 A4 A7 A2 A3]
time 3827ms: Process A1 started using the CPU for 2828ms burst [Q A5 A6 A4 A7 A2 A3]
time 4510ms: Process A0 completed I/O; added to ready queue [Q A5 A6 A4 A7 A2 A3 A0]
time 6655ms: Process A1 completed a CPU burst; 30 bursts to go [Q A5 A6 A4 A7 A2 A3 A0]
time 6655ms: Process A1 switching out of CPU; blocking on I/O until time 6980ms [Q A5 A6 A4 A7 A2 A3 A0]
time 6661ms: Process A5 started using the CPU for 564ms burst [Q A6 A4 A7 A2 A3 A0]
time 6980ms: Process A1 completed I/O; added to ready queue [Q A6 A4 A7 A2 A3 A0 A1]
time 7225ms: Process A5 terminated [Q A6 A4 A7 A2 A3 A0 A1]
time 7231ms: Process A6 started using the CPU for 761ms burst [Q A4 A7 A2 A3 A0 A1]
time 7992ms: Process A6 completed a CPU burst; 26 bursts to go [Q A4 A7 A2 A3 A0 A1]
time 7992ms: Process A6 switching out of CPU; blocking on I/O until time 10259ms [Q A4 A7 A2 A3 A0 A1]
time 7998ms: Process A4 started using the CPU for 2428ms burst [Q A7 A2 A3 A0 A1]
time 10259ms: Process A6 completed I/O; added to ready queue [Q A7 A2 A3 A0 A1 A6]
time 10426ms: Process A4 completed a CPU burst; 1 burst to go [Q A7 A2 A3 A0 A1 A6]
time 10426ms: Process A4 switching out of CPU; blocking on I/O until time 10938ms [Q A7 A2 A3 A0 A1 A6]
time 10432ms: Process A7 started using the CPU for 297ms burst [Q A2 A3 A0 A1 A6]
time 10729ms: Process A7 completed a CPU burst; 20 bursts to go [Q A2 A3 A0 A1 A6]
time 10729ms: Process A7 switching out of CPU; blocking on I/O until time 18596ms [Q A2 A3 A0 A1 A6]
time 10735ms: Process A2 started using the CPU for 1896ms burst [Q A3 A0 A1 A6]
time 10938ms: Process A4 completed I/O; added to ready queue [Q A3 A0 A1 A6 A4]
time 12631ms: Process A2 completed a CPU burst; 8 bursts to go [Q A3 A0 A1 A6 A4]
time 12631ms: Process A2 switching out of CPU; blocking on I/O until time 13252ms [Q A3 A0 A1 A6 A4]
time 12637ms: Process A3 started using the CPU for 548ms burst [Q A0 A1 A6 A4]
time 13185ms: Process A3 completed a CPU burst; 15 bursts to go [Q A0 A1 A6 A4]
time 13185ms: Process A3 switching out of CPU; blocking on I/O until time 13987ms [Q A0 A1 A6 A4]
time 13191ms: Process A0 started using the CPU for 1732ms burst [Q A1 A6 A4]
time 13252ms: Process A2 completed I/O; added to ready queue [Q A1 A6 A4 A2]
time 13987ms: Process A3 completed I/O; added to ready queue [Q A1 A6 A4 A2 A3]
time 14923ms: Process A0 completed a CPU burst; 27 bursts to go [Q A1 A6 A4 A2 A3]
time 14923ms: Process A0 switching out of CPU; blocking on I/O until time 15138ms [Q A1 A6 A4 A2 A3]
time 14929ms: Process A1 started using the CPU for 1444ms burst [Q A6 A4 A2 A3]
time 15138ms: Process A0 completed I/O; added to ready queue [Q A6 A4 A2 A3 A0]
time 16373ms: Process A1 completed a CPU burst; 29 bursts to go [Q A6 A4 A2 A3 A0]
time 16373ms: Process A1 switching out of CPU; blocking on I/O until time 16543ms [Q A6 A4 A2 A3 A0]
time 16379ms: Process A6 started using the CPU for 903ms burst [Q A4 A2 A3 A0]
time 16543ms: Process A1 completed I/O; added to ready queue [Q A4 A2 A3 A0 A1]
time 17282ms: Process A6 completed a CPU burst; 25 bursts to go [Q A4 A2 A3 A0 A1]
time 17282ms: Process A6 switching out of CPU; blocking on I/O until time 19333ms [Q A4 A2 A3 A0 A1]
time 17288ms: Process A4 started using the CPU for 2532ms burst [Q A2 A3 A0 A1]
time 18596ms: Process A7 completed I/O; added to ready queue [Q A2 A3 A0 A1 A7]
time 19333ms: Process A6 completed I/O; added to ready queue [Q A2 A3 A0 A1 A7 A6]
time 19820ms: Process A4 terminated [Q A2 A3 A0 A1 A7 A6]
time 19826ms: Process A2 started using the CPU for 2940ms burst [Q A3 A0 A1 A7 A6]
time 22766ms: Process A2 completed a CPU burst; 7 bursts to go [Q A3 A0 A1 A7 A6]
time 22766ms: Process A2 switching out of CPU; blocking on I/O until time 23208ms [Q A3 A0 A1 A7 A6]
time 22772ms: Process A3 started using the CPU for 428ms burst [Q A0 A1 A7 A6]
time 23200ms: Process A3 completed a CPU burst; 14 bursts to go [Q A0 A1 A7 A6]
time 23200ms: Process A3 switching out of CPU; blocking on I/O until time 24141ms [Q A0 A1 A7 A6]
time 23206ms: Process A0 started using the CPU for 844ms burst [Q A1 A7 A6]
time 23208ms: Process A2 completed I/O; added to ready queue [Q A1 A7 A6 A2]
time 24050ms: Process A0 completed a CPU burst; 26 bursts to go [Q A1 A7 A6 A2]
time 24050ms: Process A0 switching out of CPU; blocking on I/O until time 24546ms [Q A1 A7 A6 A2]
time 24056ms: Process A1 started using the CPU for 2476ms burst [Q A7 A6 A2]
time 24141ms: Process A3 completed I/O; added to ready queue [Q A7 A6 A2 A3]
time 24546ms: Process A0 completed I/O; added to ready queue [Q A7 A6 A2 A3 A0]
time 26532ms: Process A1 completed a CPU burst; 28 bursts to go [Q A7 A6 A2 A3 A0]
time 26532ms: Process A1 switching out of CPU; blocking on I/O until time 26952ms [Q A7 A6 A2 A3 A0]
time 26538ms: Process A7 started using the CPU for 598ms burst [Q A6 A2 A3 A0]
time 26952ms: Process A1 completed I/O; added to ready queue [Q A6 A2 A3 A0 A1]
time 27136ms: Process A7 completed a CPU burst; 19 bursts to go [Q A6 A2 A3 A0 A1]
time 27136ms: Process A7 switching out of CPU; blocking on I/O until time 29595ms [Q A6 A2 A3 A0 A1]
time 27142ms: Process A6 started using the CPU for 303ms burst [Q A2 A3 A0 A1]
time 27445ms: Process A6 completed a CPU burst; 24 bursts to go [Q A2 A3 A0 A1]
time 27445ms: Process A6 switching out of CPU; blocking on I/O until time 34776ms [Q A2 A3 A0 A1]
time 27451ms: Process A2 started using the CPU for 248ms burst [Q A3 A0 A1]
time 27699ms: Process A2 completed a CPU burst; 6 bursts to go [Q A3 A0 A1]
time 27699ms: Process A2 switching out of CPU; blocking on I/O until time 28166ms [Q A3 A0 A1]
time 27705ms: Process A3 started using the CPU for 1432ms burst [Q A0 A1]
time 28166ms: Process A2 completed I/O; added to ready queue [Q A0 A1 A2]
time 29137ms: Process A3 completed a CPU burst; 13 bursts to go [Q A0 A1 A2]
time 29137ms: Process A3 switching out of CPU; blocking on I/O until time 29457ms [Q A0 A1 A2]
time 29143ms: Process A0 started using the CPU for 168ms burst [Q A1 A2]
time 29311ms: Process A0 completed a CPU burst; 25 bursts to go [Q A1 A2]
time 29311ms: Process A0 switching out of CPU; blocking on I/O until time 29686ms [Q A1 A2]
time 29317ms: Process A1 started using the CPU for 2256ms burst [Q A2]
time 29457ms: Process A3 completed I/O; added to ready queue [Q A2 A3]
time 29595ms: Process A7 completed I/O; added to ready queue [Q A2 A3 A7]
time 29686ms: Process A0 completed I/O; added to ready queue [Q A2 A3 A7 A0]
time 31573ms: Process A1 completed a CPU burst; 27 bursts to go [Q A2 A3 A7 A0]
time 31573ms: Process A1 switching out of CPU; blocking on I/O until time 31866ms [Q A2 A3 A7 A0]
time 31579ms: Process A2 started using the CPU for 952ms burst [Q A3 A7 A0]
time 31866ms: Process A1 completed I/O; added to ready queue [Q A3 A7 A0 A1]
time 32531ms: Process A2 completed a CPU burst; 5 bursts to go [Q A3 A7 A0 A1]
time 32531ms: Process A2 switching out of CPU; blocking on I/O until time 33308ms [Q A3 A7 A0 A1]
time 32537ms: Process A3 started using the CPU for 3896ms burst [Q A7 A0 A1]
time 33308ms: Process A2 completed I/O; added to ready queue [Q A7 A0 A1 A2]
time 34776ms: Process A6 completed I/O; added to ready queue [Q A7 A0 A1 A2 A6]
time 36433ms: Process A3 completed a CPU burst; 12 bursts to go [Q A7 A0 A1 A2 A6]
time 36433ms: Process A3 switching out of CPU; blocking on I/O until time 36560ms [Q A7 A0 A1 A2 A6]
time 36439ms: Process A7 started using the CPU for 721ms burst [Q A0 A1 A2 A6]
time 36560ms: Process A3 completed I/O; added to ready queue [Q A0 A1 A2 A6 A3]
time 37160ms: Process A7 completed a CPU burst; 18 bursts to go [Q A0 A1 A2 A6 A3]
time 37160ms: Process A7 switching out of CPU; blocking on I/O until time 39899ms [Q A0 A1 A2 A6 A3]
time 37166ms: Process A0 started using the CPU for 736ms burst [Q A1 A2 A6 A3]
time 37902ms: Process A0 completed a CPU burst; 24 bursts to go [Q A1 A2 A6 A3]
time 37902ms: Process A0 switching out of CPU; blocking on I/O until time 38046ms [Q A1 A2 A6 A3]
time 37908ms: Process A1 started using the CPU for 1188ms burst [Q A2 A6 A3]
time 38046ms: Process A0 completed I/O; added to ready queue [Q A2 A6 A3 A0]
time 39096ms: Process A1 completed a CPU burst; 26 bursts to go [Q A2 A6 A3 A0]
time 39096ms: Process A1 switching out of CPU; blocking on I/O until time 39876ms [Q A2 A6 A3 A0]
time 39102ms: Process A2 started using the CPU for 1796ms burst [Q A6 A3 A0]
time 39876ms: Process A1 completed I/O; added to ready queue [Q A6 A3 A0 A1]
time 39899ms: Process A7 completed I/O; added to ready queue [Q A6 A3 A0 A1 A7]
time 40898ms: Process A2 completed a CPU burst; 4 bursts to go [Q A6 A3 A0 A1 A7]
time 40898ms: Process A2 switching out of CPU; blocking on I/O until time 41312ms [Q A6 A3 A0 A1 A7]
time 40904ms: Process A6 started using the CPU for 194ms burst [Q A3 A0 A1 A7]
time 41098ms: Process A6 completed a CPU burst; 23 bursts to go [Q A3 A0 A1 A7]
time 41098ms: Process A6 switching out of CPU; blocking on I/O until time 47997ms [Q A3 A0 A1 A7]
time 41104ms: Process A3 started using the CPU for 804ms burst [Q A0 A1 A7]
time 41312ms: Process A2 completed I/O; added to ready queue [Q A0 A1 A7 A2]
time 41908ms: Process A3 completed a CPU burst; 11 bursts to go [Q A0 A1 A7 A2]
time 41908ms: Process A3 switching out of CPU; blocking on I/O until time 41976ms [Q A0 A1 A7 A2]
time 41914ms: Process A0 started using the CPU for 1372ms burst [Q A1 A7 A2]
time 41976ms: Process A3 completed I/O; added to ready queue [Q A1 A7 A2 A3]
time 43286ms: Process A0 completed a CPU burst; 23 bursts to go [Q A1 A7 A2 A3]
time 43286ms: Process A0 switching out of CPU; blocking on I/O until time 43843ms [Q A1 A7 A2 A3]
time 43292ms: Process A1 started using the CPU for 2812ms burst [Q A7 A2 A3]
time 43843ms: Process A0 completed I/O; added to ready queue [Q A7 A2 A3 A0]
time 46104ms: Process A1 completed a CPU burst; 25 bursts to go [Q A7 A2 A3 A0]
time 46104ms: Process A1 switching out of CPU; blocking on I/O until time 46970ms [Q A7 A2 A3 A0]
time 46110ms: Process A7 started using the CPU for 641ms burst [Q A2 A3 A0]
time 46751ms: Process A7 completed a CPU burst; 17 bursts to go [Q A2 A3 A0]
time 46751ms: Process A7 switching out of CPU; blocking on I/O until time 48698ms [Q A2 A3 A0]
time 46757ms: Process A2 started using the CPU for 2200ms burst [Q A3 A0]
time 46970ms: Process A1 completed I/O; added to ready queue [Q A3 A0 A1]
time 47997ms: Process A6 completed I/O; added to ready queue [Q A3 A0 A1 A6]
time 48698ms: Process A7 completed I/O; added to ready queue [Q A3 A0 A1 A6 A7]
time 48957ms: Process A2 completed a CPU burst; 3 bursts to go [Q A3 A0 A1 A6 A7]
time 48957ms: Process A2 switching out of CPU; blocking on I/O until time 48975ms [Q A3 A0 A1 A6 A7]
time 48963ms: Process A3 started using the CPU for 2564ms burst [Q A0 A1 A6 A7]
time 48975ms: Process A2 completed I/O; added to ready queue [Q A0 A1 A6 A7 A2]
time 51527ms: Process A3 completed a CPU burst; 10 bursts to go [Q A0 A1 A6 A7 A2]
time 51527ms: Process A3 switching out of CPU; blocking on I/O until time 51910ms [Q A0 A1 A6 A7 A2]
time 51533ms: Process A0 started using the CPU for 1808ms burst [Q A1 A6 A7 A2]
time 51910ms: Process A3 completed I/O; added to ready queue [Q A1 A6 A7 A2 A3]
time 53341ms: Process A0 completed a CPU burst; 22 bursts to go [Q A1 A6 A7 A2 A3]
time 53341ms: Process A0 switching out of CPU; blocking on I/O until time 53493ms [Q A1 A6 A7 A2 A3]
time 53347ms: Process A1 started using the CPU for 368ms burst [Q A6 A7 A2 A3]
time 53493ms: Process A0 completed I/O; added to ready queue [Q A6 A7 A2 A3 A0]
time 53715ms: Process A1 completed a CPU burst; 24 bursts to go [Q A6 A7 A2 A3 A0]
time 53715ms: Process A1 switching out of CPU; blocking on I/O until time 53891ms [Q A6 A7 A2 A3 A0]
time 53721ms: Process A6 started using the CPU for 203ms burst [Q A7 A2 A3 A0]
time 53891ms: Process A1 completed I/O; added to ready queue [Q A7 A2 A3 A0 A1]
time 53924ms: Process A6 completed a CPU burst; 22 bursts to go [Q A7 A2 A3 A0 A1]
time 53924ms: Process A6 switching out of CPU; blocking on I/O until time 56727ms [Q A7 A2 A3 A0 A1]
time 53930ms: Process A7 started using the CPU for 128ms burst [Q A2 A3 A0 A1]
time 54058ms: Process A7 completed a CPU burst; 16 bursts to go [Q A2 A3 A0 A1]
time 54058ms: Process A7 switching out of CPU; blocking on I/O until time 60229ms [Q A2 A3 A0 A1]
time 54064ms: Process A2 started using the CPU for 1512ms burst [Q A3 A0 A1]
time 55576ms: Process A2 completed a CPU burst; 2 bursts to go [Q A3 A0 A1]
time 55576ms: Process A2 switching out of CPU; blocking on I/O until time 56366ms [Q A3 A0 A1]
time 55582ms: Process A3 started using the CPU for 3416ms burst [Q A0 A1]
time 56366ms: Process A2 completed I/O; added to ready queue [Q A0 A1 A2]
time 56727ms: Process A6 completed I/O; added to ready queue [Q A0 A1 A2 A6]
time 58998ms: Process A3 completed a CPU burst; 9 bursts to go [Q A0 A1 A2 A6]
time 58998ms: Process A3 switching out of CPU; blocking on I/O until time 59890ms [Q A0 A1 A2 A6]
time 59004ms: Process A0 started using the CPU for 1808ms burst [Q A1 A2 A6]
time 59890ms: Process A3 completed I/O; added to ready queue [Q A1 A2 A6 A3]
time 60229ms: Process A7 completed I/O; added to ready queue [Q A1 A2 A6 A3 A7]
time 60812ms: Process A0 completed a CPU burst; 21 bursts to go [Q A1 A2 A6 A3 A7]
time 60812ms: Process A0 switching out of CPU; blocking on I/O until time 61081ms [Q A1 A2 A6 A3 A7]
time 60818ms: Process A1 started using the CPU for 200ms burst [Q A2 A6 A3 A7]
time 61018ms: Process A1 completed a CPU burst; 23 bursts to go [Q A2 A6 A3 A7]
time 61018ms: Process A1 switching out of CPU; blocking on I/O until time 61628ms [Q A2 A6 A3 A7]
time 61024ms: Process A2 started using the CPU for 1764ms burst [Q A6 A3 A7]
time 61081ms: Process A0 completed I/O; added to ready queue [Q A6 A3 A7 A0]
time 61628ms: Process A1 completed I/O; added to ready queue [Q A6 A3 A7 A0 A1]
time 62788ms: Process A2 completed a CPU burst; 1 burst to go [Q A6 A3 A7 A0 A1]
time 62788ms: Process A2 switching out of CPU; blocking on I/O until time 62875ms [Q A6 A3 A7 A0 A1]
time 62794ms: Process A6 started using the CPU for 603ms burst [Q A3 A7 A0 A1]
time 62875ms: Process A2 completed I/O; added to ready queue [Q A3 A7 A0 A1 A2]
time 63397ms: Process A6 completed a CPU burst; 21 bursts to go [Q A3 A7 A0 A1 A2]
time 63397ms: Process A6 switching out of CPU; blocking on I/O until time 66464ms [Q A3 A7 A0 A1 A2]
time 63403ms: Process A3 started using the CPU for 3756ms burst [Q A7 A0 A1 A2]
time 66464ms: Process A6 completed I/O; added to ready queue [Q A7 A0 A1 A2 A6]
time 67159ms: Process A3 completed a CPU burst; 8 bursts to go [Q A7 A0 A1 A2 A6]
time 67159ms: Process A3 switching out of CPU; blocking on I/O until time 67813ms [Q A7 A0 A1 A2 A6]
time 67165ms: Process A7 started using the CPU for 277ms burst [Q A0 A1 A2 A6]
time 67442ms: Process A7 completed a CPU burst; 15 bursts to go [Q A0 A1 A2 A6]
time 67442ms: Process A7 switching out of CPU; blocking on I/O until time 68293ms [Q A0 A1 A2 A6]
time 67448ms: Process A0 started using the CPU for 848ms burst [Q A1 A2 A6]
time 67813ms: Process A3 completed I/O; added to ready queue [Q A1 A2 A6 A3]
time 68293ms: Process A7 completed I/O; added to ready queue [Q A1 A2 A6 A3 A7]
time 68296ms: Process A0 completed a CPU burst; 20 bursts to go [Q A1 A2 A6 A3 A7]
time 68296ms: Process A0 switching out of CPU; blocking on I/O until time 68374ms [Q A1 A2 A6 A3 A7]
time 68302ms: Process A1 started using the CPU for 1044ms burst [Q A2 A6 A3 A7]
time 68374ms: Process A0 completed I/O; added to ready queue [Q A2 A6 A3 A7 A0]
time 69346ms: Process A1 completed a CPU burst; 22 bursts to go [Q A2 A6 A3 A7 A0]
time 69346ms: Process A1 switching out of CPU; blocking on I/O until time 69941ms [Q A2 A6 A3 A7 A0]
time 69352ms: Process A2 started using the CPU for 1768ms burst [Q A6 A3 A7 A0]
time 69941ms: Process A1 completed I/O; added to ready queue [Q A6 A3 A7 A0 A1]
time 71120ms: Process A2 terminated [Q A6 A3 A7 A0 A1]
time 71126ms: Process A6 started using the CPU for 95ms burst [Q A3 A7 A0 A1]
time 71221ms: Process A6 completed a CPU burst; 20 bursts to go [Q A3 A7 A0 A1]
time 71221ms: Process A6 switching out of CPU; blocking on I/O until time 72280ms [Q A3 A7 A0 A1]
time 71227ms: Process A3 started using the CPU for 3864ms burst [Q A7 A0 A1]
time 72280ms: Process A6 completed I/O; added to ready queue [Q A7 A0 A1 A6]
time 75091ms: Process A3 completed a CPU burst; 7 bursts to go [Q A7 A0 A1 A6]
time 75091ms: Process A3 switching out of CPU; blocking on I/O until time 75517ms [Q A7 A0 A1 A6]
time 75097ms: Process A7 started using the CPU for 984ms burst [Q A0 A1 A6]
time 75517ms: Process A3 completed I/O; added to ready queue [Q A0 A1 A6 A3]
time 76081ms: Process A7 completed a CPU burst; 14 bursts to go [Q A0 A1 A6 A3]
time 76081ms: Process A7 switching out of CPU; blocking on I/O until time 81292ms [Q A0 A1 A6 A3]
time 76087ms: Process A0 started using the CPU for 3384ms burst [Q A1 A6 A3]
time 79471ms: Process A0 completed a CPU burst; 19 bursts to go [Q A1 A6 A3]
time 79471ms: Process A0 switching out of CPU; blocking on I/O until time 79491ms [Q A1 A6 A3]
time 79477ms: Process A1 started using the CPU for 940ms burst [Q A6 A3]
time 79491ms: Process A0 completed I/O; added to ready queue [Q A6 A3 A0]
time 80417ms: Process A1 completed a CPU burst; 21 bursts to go [Q A6 A3 A0]
time 80417ms: Process A1 switching out of CPU; blocking on I/O until time 80865ms [Q A6 A3 A0]
time 80423ms: Process A6 started using the CPU for 556ms burst [Q A3 A0]
time 80865ms: Process A1 completed I/O; added to ready queue [Q A3 A0 A1]
time 80979ms: Process A6 completed a CPU burst; 19 bursts to go [Q A3 A0 A1]
time 80979ms: Process A6 switching out of CPU; blocking on I/O until time 84358ms [Q A3 A0 A1]
time 80985ms: Process A3 started using the CPU for 1144ms burst [Q A0 A1]
time 81292ms: Process A7 completed I/O; added to ready queue [Q A0 A1 A7]
time 82129ms: Process A3 completed a CPU burst; 6 bursts to go [Q A0 A1 A7]
time 82129ms: Process A3 switching out of CPU; blocking on I/O until time 82282ms [Q A0 A1 A7]
time 82135ms: Process A0 started using the CPU for 104ms burst [Q A1 A7]
time 82239ms: Process A0 completed a CPU burst; 18 bursts to go [Q A1 A7]
time 82239ms: Process A0 switching out of CPU; blocking on I/O until time 82670ms [Q A1 A7]
time 82245ms: Process A1 started using the CPU for 660ms burst [Q A7]
time 82282ms: Process A3 completed I/O; added to ready queue [Q A7 A3]
time 82670ms: Process A0 completed I/O; added to ready queue [Q A7 A3 A0]
time 82905ms: Process A1 completed a CPU burst; 20 bursts to go [Q A7 A3 A0]
time 82905ms: Process A1 switching out of CPU; blocking on I/O until time 82936ms [Q A7 A3 A0]
time 82911ms: Process A7 started using the CPU for 961ms burst [Q A3 A0]
time 82936ms: Process A1 completed I/O; added to ready queue [Q A3 A0 A1]
time 83872ms: Process A7 completed a CPU burst; 13 bursts to go [Q A3 A0 A1]
time 83872ms: Process A7 switching out of CPU; blocking on I/O until time 87307ms [Q A3 A0 A1]
time 83878ms: Process A3 started using the CPU for 492ms burst [Q A0 A1]
time 84358ms: Process A6 completed I/O; added to ready queue [Q A0 A1 A6]
time 84370ms: Process A3 completed a CPU burst; 5 bursts to go [Q A0 A1 A6]
time 84370ms: Process A3 switching out of CPU; blocking on I/O until time 84741ms [Q A0 A1 A6]
time 84376ms: Process A0 started using the CPU for 3924ms burst [Q A1 A6]
time 84741ms: Process A3 completed I/O; added to ready queue [Q A1 A6 A3]
time 87307ms: Process A7 completed I/O; added to ready queue [Q A1 A6 A3 A7]
time 88300ms: Process A0 completed a CPU burst; 17 bursts to go [Q A1 A6 A3 A7]
time 88300ms: Process A0 switching out of CPU; blocking on I/O until time 88970ms [Q A1 A6 A3 A7]
time 88306ms: Process A1 started using the CPU for 2196ms burst [Q A6 A3 A7]
time 88970ms: Process A0 completed I/O; added to ready queue [Q A6 A3 A7 A0]
time 90502ms: Process A1 completed a CPU burst; 19 bursts to go [Q A6 A3 A7 A0]
time 90502ms: Process A1 switching out of CPU; blocking on I/O until time 91481ms [Q A6 A3 A7 A0]
time 90508ms: Process A6 started using the CPU for 599ms burst [Q A3 A7 A0]
time 91107ms: Process A6 completed a CPU burst; 18 bursts to go [Q A3 A7 A0]
time 91107ms: Process A6 switching out of CPU; blocking on I/O until time 91670ms [Q A3 A7 A0]
time 91113ms: Process A3 started using the CPU for 2704ms burst [Q A7 A0]
time 91481ms: Process A1 completed I/O; added to ready queue [Q A7 A0 A1]
time 91670ms: Process A6 completed I/O; added to ready queue [Q A7 A0 A1 A6]
time 93817ms: Process A3 completed a CPU burst; 4 bursts to go [Q A7 A0 A1 A6]
time 93817ms: Process A3 switching out of CPU; blocking on I/O until time 93996ms [Q A7 A0 A1 A6]
time 93823ms: Process A7 started using the CPU for 587ms burst [Q A0 A1 A6]
time 93996ms: Process A3 completed I/O; added to ready queue [Q A0 A1 A6 A3]
time 94410ms: Process A7 completed a CPU burst; 12 bursts to go [Q A0 A1 A6 A3]
time 94410ms: Process A7 switching out of CPU; blocking on I/O until time 95205ms [Q A0 A1 A6 A3]
time 94416ms: Process A0 started using the CPU for 3388ms burst [Q A1 A6 A3]
time 95205ms: Process A7 completed I/O; added to ready queue [Q A1 A6 A3 A7]
time 97804ms: Process A0 completed a CPU burst; 16 bursts to go [Q A1 A6 A3 A7]
time 97804ms: Process A0 switching out of CPU; blocking on I/O until time 97901ms [Q A1 A6 A3 A7]
time 97810ms: Process A1 started using the CPU for 36ms burst [Q A6 A3 A7]
time 97846ms: Process A1 completed a CPU burst; 18 bursts to go [Q A6 A3 A7]
time 97846ms: Process A1 switching out of CPU; blocking on I/O until time 98486ms [Q A6 A3 A7]
time 97852ms: Process A6 started using the CPU for 58ms burst [Q A3 A7]
time 97901ms: Process A0 completed I/O; added to ready queue [Q A3 A7 A0]
time 97910ms: Process A6 completed a CPU burst; 17 bursts to go [Q A3 A7 A0]
time 97910ms: Process A6 switching out of CPU; blocking on I/O until time 99969ms [Q A3 A7 A0]
time 97916ms: Process A3 started using the CPU for 316ms burst [Q A7 A0]
time 98232ms: Process A3 completed a CPU burst; 3 bursts to go [Q A7 A0]
time 98232ms: Process A3 switching out of CPU; blocking on I/O until time 98903ms [Q A7 A0]
time 98238ms: Process A7 started using the CPU for 33ms burst [Q A0]
time 98271ms: Process A7 completed a CPU burst; 11 bursts to go [Q A0]
time 98271ms: Process A7 switching out of CPU; blocking on I/O until time 100858ms [Q A0]
time 98277ms: Process A0 started using the CPU for 100ms burst [Q empty]
time 98377ms: Process A0 completed a CPU burst; 15 bursts to go [Q empty]
time 98377ms: Process A0 switching out of CPU; blocking on I/O until time 98867ms [Q empty]
time 98486ms: Process A1 completed I/O; added to ready queue [Q A1]
time 98489ms: Process A1 started using the CPU for 4060ms burst [Q empty]
time 98867ms: Process A0 completed I/O; added to ready queue [Q A0]
time 98903ms: Process A3 completed I/O; added to ready queue [Q A0 A3]
time 99969ms: Process A6 completed I/O; added to ready queue [Q A0 A3 A6]
time 100858ms: Process A7 completed I/O; added to ready queue [Q A0 A3 A6 A7]
time 102549ms: Process A1 completed a CPU burst; 17 bursts to go [Q A0 A3 A6 A7]
time 102549ms: Process A1 switching out of CPU; blocking on I/O until time 102642ms [Q A0 A3 A6 A7]
time 102555ms: Process A0 started using the CPU for 3868ms burst [Q A3 A6 A7]
time 102642ms: Process A1 completed I/O; added to ready queue [Q A3 A6 A7 A1]
time 106423ms: Process A0 completed a CPU burst; 14 bursts to go [Q A3 A6 A7 A1]
time 106423ms: Process A0 switching out of CPU; blocking on I/O until time 106538ms [Q A3 A6 A7 A1]
time 106429ms: Process A3 started using the CPU for 204ms burst [Q A6 A7 A1]
time 106538ms: Process A0 completed I/O; added to ready queue [Q A6 A7 A1 A0]
time 106633ms: Process A3 completed a CPU burst; 2 bursts to go [Q A6 A7 A1 A0]
time 106633ms: Process A3 switching out of CPU; blocking on I/O until time 106968ms [Q A6 A7 A1 A0]
time 106639ms: Process A6 started using the CPU for 455ms burst [Q A7 A1 A0]
time 106968ms: Process A3 completed I/O; added to ready queue [Q A7 A1 A0 A3]
time 107094ms: Process A6 completed a CPU burst; 16 bursts to go [Q A7 A1 A0 A3]
time 107094ms: Process A6 switching out of CPU; blocking on I/O until time 110209ms [Q A7 A1 A0 A3]
time 107100ms: Process A7 started using the CPU for 875ms burst [Q A1 A0 A3]
time 107975ms: Process A7 completed a CPU burst; 10 bursts to go [Q A1 A0 A3]
time 107975ms: Process A7 switching out of CPU; blocking on I/O until time 110330ms [Q A1 A0 A3]
time 107981ms: Process A1 started using the CPU for 3904ms burst [Q A0 A3]
time 110209ms: Process A6 completed I/O; added to ready queue [Q A0 A3 A6]
time 110330ms: Process A7 completed I/O; added to ready queue [Q A0 A3 A6 A7]
time 111885ms: Process A1 completed a CPU burst; 16 bursts to go [Q A0 A3 A6 A7]
time 111885ms: Process A1 switching out of CPU; blocking on I/O until time 112422ms [Q A0 A3 A6 A7]
time 111891ms: Process A0 started using the CPU for 1516ms burst [Q A3 A6 A7]
time 112422ms: Process A1 completed I/O; added to ready queue [Q A3 A6 A7 A1]
time 113407ms: Process A0 completed a CPU burst; 13 bursts to go [Q A3 A6 A7 A1]
time 113407ms: Process A0 switching out of CPU; blocking on I/O until time 113721ms [Q A3 A6 A7 A1]
time 113413ms: Process A3 started using the CPU for 2328ms burst [Q A6 A7 A1]
time 113721ms: Process A0 completed I/O; added to ready queue [Q A6 A7 A1 A0]
time 115741ms: Process A3 completed a CPU burst; 1 burst to go [Q A6 A7 A1 A0]
time 115741ms: Process A3 switching out of CPU; blocking on I/O until time 116640ms [Q A6 A7 A1 A0]
time 115747ms: Process A6 started using the CPU for 826ms burst [Q A7 A1 A0]
time 116573ms: Process A6 completed a CPU burst; 15 bursts to go [Q A7 A1 A0]
time 116573ms: Process A6 switching out of CPU; blocking on I/O until time 119216ms [Q A7 A1 A0]
time 116579ms: Process A7 started using the CPU for 53ms burst [Q A1 A0]
time 116632ms: Process A7 completed a CPU burst; 9 bursts to go [Q A1 A0]
time 116632ms: Process A7 switching out of CPU; blocking on I/O until time 116875ms [Q A1 A0]
time 116638ms: Process A1 started using the CPU for 1488ms burst [Q A0]
time 116640ms: Process A3 completed I/O; added to ready queue [Q A0 A3]
time 116875ms: Process A7 completed I/O; added to ready queue [Q A0 A3 A7]
time 118126ms: Process A1 completed a CPU burst; 15 bursts to go [Q A0 A3 A7]
time 118126ms: Process A1 switching out of CPU; blocking on I/O until time 118533ms [Q A0 A3 A7]
time 118132ms: Process A0 started using the CPU for 1260ms burst [Q A3 A7]
time 118533ms: Process A1 completed I/O; added to ready queue [Q A3 A7 A1]
time 119216ms: Process A6 completed I/O; added to ready queue [Q A3 A7 A1 A6]
time 119392ms: Process A0 completed a CPU burst; 12 bursts to go [Q A3 A7 A1 A6]
time 119392ms: Process A0 switching out of CPU; blocking on I/O until time 119808ms [Q A3 A7 A1 A6]
time 119398ms: Process A3 started using the CPU for 2760ms burst [Q A7 A1 A6]
time 119808ms: Process A0 completed I/O; added to ready queue [Q A7 A1 A6 A0]
time 122158ms: Process A3 terminated [Q A7 A1 A6 A0]
time 122164ms: Process A7 started using the CPU for 64ms burst [Q A1 A6 A0]
time 122228ms: Process A7 completed a CPU burst; 8 bursts to go [Q A1 A6 A0]
time 122228ms: Process A7 switching out of CPU; blocking on I/O until time 125727ms [Q A1 A6 A0]
time 122234ms: Process A1 started using the CPU for 1080ms burst [Q A6 A0]
time 123314ms: Process A1 completed a CPU burst; 14 bursts to go [Q A6 A0]
time 123314ms: Process A1 switching out of CPU; blocking on I/O until time 123368ms [Q A6 A0]
time 123320ms: Process A6 started using the CPU for 587ms burst [Q A0]
time 123368ms: Process A1 completed I/O; added to ready queue [Q A0 A1]
time 123907ms: Process A6 completed a CPU burst; 14 bursts to go [Q A0 A1]
time 123907ms: Process A6 switching out of CPU; blocking on I/O until time 125830ms [Q A0 A1]
time 123913ms: Process A0 started using the CPU for 728ms burst [Q A1]
time 124641ms: Process A0 completed a CPU burst; 11 bursts to go [Q A1]
time 124641ms: Process A0 switching out of CPU; blocking on I/O until time 125417ms [Q A1]
time 124647ms: Process A1 started using the CPU for 916ms burst [Q empty]
time 125417ms: Process A0 completed I/O; added to ready queue [Q A0]
time 125563ms: Process A1 completed a CPU burst; 13 bursts to go [Q A0]
time 125563ms: Process A1 switching out of CPU; blocking on I/O until time 125637ms [Q A0]
time 125569ms: Process A0 started using the CPU for 2568ms burst [Q empty]
time 125637ms: Process A1 completed I/O; added to ready queue [Q A1]
time 125727ms: Process A7 completed I/O; added to ready queue [Q A1 A7]
time 125830ms: Process A6 completed I/O; added to ready queue [Q A1 A7 A6]
time 128137ms: Process A0 completed a CPU burst; 10 bursts to go [Q A1 A7 A6]
time 128137ms: Process A0 switching out of CPU; blocking on I/O until time 128488ms [Q A1 A7 A6]
time 128143ms: Process A1 started using the CPU for 3724ms burst [Q A7 A6]
time 128488ms: Process A0 completed I/O; added to ready queue [Q A7 A6 A0]
time 131867ms: Process A1 completed a CPU burst; 12 bursts to go [Q A7 A6 A0]
time 131867ms: Process A1 switching out of CPU; blocking on I/O until time 131981ms [Q A7 A6 A0]
time 131873ms: Process A7 started using the CPU for 264ms burst [Q A6 A0]
time 131981ms: Process A1 completed I/O; added to ready queue [Q A6 A0 A1]
time 132137ms: Process A7 completed a CPU burst; 7 bursts to go [Q A6 A0 A1]
time 132137ms: Process A7 switching out of CPU; blocking on I/O until time 133188ms [Q A6 A0 A1]
time 132143ms: Process A6 started using the CPU for 292ms burst [Q A0 A1]
time 132435ms: Process A6 completed a CPU burst; 13 bursts to go [Q A0 A1]
time 132435ms: Process A6 switching out of CPU; blocking on I/O until time 136918ms [Q A0 A1]
time 132441ms: Process A0 started using the CPU for 1220ms burst [Q A1]
time 133188ms: Process A7 completed I/O; added to ready queue [Q A1 A7]
time 133661ms: Process A0 completed a CPU burst; 9 bursts to go [Q A1 A7]
time 133661ms: Process A0 switching out of CPU; blocking on I/O until time 134547ms [Q A1 A7]
time 133667ms: Process A1 started using the CPU for 1764ms burst [Q A7]
time 134547ms: Process A0 completed I/O; added to ready queue [Q A7 A0]
time 135431ms: Process A1 completed a CPU burst; 11 bursts to go [Q A7 A0]
time 135431ms: Process A1 switching out of CPU; blocking on I/O until time 135716ms [Q A7 A0]
time 135437ms: Process A7 started using the CPU for 228ms burst [Q A0]
time 135665ms: Process A7 completed a CPU burst; 6 bursts to go [Q A0]
time 135665ms: Process A7 switching out of CPU; blocking on I/O until time 137932ms [Q A0]
time 135671ms: Process A0 started using the CPU for 2296ms burst [Q empty]
time 135716ms: Process A1 completed I/O; added to ready queue [Q A1]
time 136918ms: Process A6 completed I/O; added to ready queue [Q A1 A6]
time 137932ms: Process A7 completed I/O; added to ready queue [Q A1 A6 A7]
time 137967ms: Process A0 completed a CPU burst; 8 bursts to go [Q A1 A6 A7]
time 137967ms: Process A0 switching out of CPU; blocking on I/O until time 138634ms [Q A1 A6 A7]
time 137973ms: Process A1 started using the CPU for 860ms burst [Q A6 A7]
time 138634ms: Process A0 completed I/O; added to ready queue [Q A6 A7 A0]
time 138833ms: Process A1 completed a CPU burst; 10 bursts to go [Q A6 A7 A0]
time 138833ms: Process A1 switching out of CPU; blocking on I/O until time 138935ms [Q A6 A7 A0]
time 138839ms: Process A6 started using the CPU for 572ms burst [Q A7 A0]
time 138935ms: Process A1 completed I/O; added to ready queue [Q A7 A0 A1]
time 139411ms: Process A6 completed a CPU burst; 12 bursts to go [Q A7 A0 A1]
time 139411ms: Process A6 switching out of CPU; blocking on I/O until time 139934ms [Q A7 A0 A1]
time 139417ms: Process A7 started using the CPU for 37ms burst [Q A0 A1]
time 139454ms: Process A7 completed a CPU burst; 5 bursts to go [Q A0 A1]
time 139454ms: Process A7 switching out of CPU; blocking on I/O until time 144953ms [Q A0 A1]
time 139460ms: Process A0 started using the CPU for 3268ms burst [Q A1]
time 139934ms: Process A6 completed I/O; added to ready queue [Q A1 A6]
time 142728ms: Process A0 completed a CPU burst; 7 bursts to go [Q A1 A6]
time 142728ms: Process A0 switching out of CPU; blocking on I/O until time 143654ms [Q A1 A6]
time 142734ms: Process A1 started using the CPU for 2700ms burst [Q A6]
time 143654ms: Process A0 completed I/O; added to ready queue [Q A6 A0]
time 144953ms: Process A7 completed I/O; added to ready queue [Q A6 A0 A7]
time 145434ms: Process A1 completed a CPU burst; 9 bursts to go [Q A6 A0 A7]
time 145434ms: Process A1 switching out of CPU; blocking on I/O until time 146204ms [Q A6 A0 A7]
time 145440ms: Process A6 started using the CPU for 494ms burst [Q A0 A7]
time 145934ms: Process A6 completed a CPU burst; 11 bursts to go [Q A0 A7]
time 145934ms: Process A6 switching out of CPU; blocking on I/O until time 153025ms [Q A0 A7]
time 145940ms: Process A0 started using the CPU for 3468ms burst [Q A7]
time 146204ms: Process A1 completed I/O; added to ready queue [Q A7 A1]
time 149408ms: Process A0 completed a CPU burst; 6 bursts to go [Q A7 A1]
time 149408ms: Process A0 switching out of CPU; blocking on I/O until time 149699ms [Q A7 A1]
time 149414ms: Process A7 started using the CPU for 364ms burst [Q A1]
time 149699ms: Process A0 completed I/O; added to ready queue [Q A1 A0]
time 149778ms: Process A7 completed a CPU burst; 4 bursts to go [Q A1 A0]
time 149778ms: Process A7 switching out of CPU; blocking on I/O until time 154093ms [Q A1 A0]
time 149784ms: Process A1 started using the CPU for 100ms burst [Q A0]
time 149884ms: Process A1 completed a CPU burst; 8 bursts to go [Q A0]
time 149884ms: Process A1 switching out of CPU; blocking on I/O until time 150473ms [Q A0]
time 149890ms: Process A0 started using the CPU for 2392ms burst [Q empty]
time 150473ms: Process A1 completed I/O; added to ready queue [Q A1]
time 152282ms: Process A0 completed a CPU burst; 5 bursts to go [Q A1]
time 152282ms: Process A0 switching out of CPU; blocking on I/O until time 152393ms [Q A1]
time 152288ms: Process A1 started using the CPU for 420ms burst [Q empty]
time 152393ms: Process A0 completed I/O; added to ready queue [Q A0]
time 152708ms: Process A1 completed a CPU burst; 7 bursts to go [Q A0]
time 152708ms: Process A1 switching out of CPU; blocking on I/O until time 153420ms [Q A0]
time 152714ms: Process A0 started using the CPU for 1976ms burst [Q empty]
time 153025ms: Process A6 completed I/O; added to ready queue [Q A6]
time 153420ms: Process A1 completed I/O; added to ready queue [Q A6 A1]
time 154093ms: Process A7 completed I/O; added to ready queue [Q A6 A1 A7]
time 154690ms: Process A0 completed a CPU burst; 4 bursts to go [Q A6 A1 A7]
time 154690ms: Process A0 switching out of CPU; blocking on I/O until time 155257ms [Q A6 A1 A7]
time 154696ms: Process A6 started using the CPU for 19ms burst [Q A1 A7]
time 154715ms: Process A6 completed a CPU burst; 10 bursts to go [Q A1 A7]
time 154715ms: Process A6 switching out of CPU; blocking on I/O until time 158934ms [Q A1 A7]
time 154721ms: Process A1 started using the CPU for 3504ms burst [Q A7]
time 155257ms: Process A0 completed I/O; added to ready queue [Q A7 A0]
time 158225ms: Process A1 completed a CPU burst; 6 bursts to go [Q A7 A0]
time 158225ms: Process A1 switching out of CPU; blocking on I/O until time 158899ms [Q A7 A0]
time 158231ms: Process A7 started using the CPU for 278ms burst [Q A0]
time 158509ms: Process A7 completed a CPU burst; 3 bursts to go [Q A0]
time 158509ms: Process A7 switching out of CPU; blocking on I/O until time 161024ms [Q A0]
time 158515ms: Process A0 started using the CPU for 312ms burst [Q empty]
time 158827ms: Process A0 completed a CPU burst; 3 bursts to go [Q empty]
time 158827ms: Process A0 switching out of CPU; blocking on I/O until time 159375ms [Q empty]
time 158899ms: Process A1 completed I/O; added to ready queue [Q A1]
time 158902ms: Process A1 started using the CPU for 3504ms burst [Q empty]
time 158934ms: Process A6 completed I/O; added to ready queue [Q A6]
time 159375ms: Process A0 completed I/O; added to ready queue [Q A6 A0]
time 161024ms: Process A7 completed I/O; added to ready queue [Q A6 A0 A7]
time 162406ms: Process A1 completed a CPU burst; 5 bursts to go [Q A6 A0 A7]
time 162406ms: Process A1 switching out of CPU; blocking on I/O until time 162743ms [Q A6 A0 A7]
time 162412ms: Process A6 started using the CPU for 355ms burst [Q A0 A7]
time 162743ms: Process A1 completed I/O; added to ready queue [Q A0 A7 A1]
time 162767ms: Process A6 completed a CPU burst; 9 bursts to go [Q A0 A7 A1]
time 162767ms: Process A6 switching out of CPU; blocking on I/O until time 165738ms [Q A0 A7 A1]
time 162773ms: Process A0 started using the CPU for 1440ms burst [Q A7 A1]
time 164213ms: Process A0 completed a CPU burst; 2 bursts to go [Q A7 A1]
time 164213ms: Process A0 switching out of CPU; blocking on I/O until time 164352ms [Q A7 A1]
time 164219ms: Process A7 started using the CPU for 23ms burst [Q A1]
time 164242ms: Process A7 completed a CPU burst; 2 bursts to go [Q A1]
time 164242ms: Process A7 switching out of CPU; blocking on I/O until time 172125ms [Q A1]
time 164248ms: Process A1 started using the CPU for 2352ms burst [Q empty]
time 164352ms: Process A0 completed I/O; added to ready queue [Q A0]
time 165738ms: Process A6 completed I/O; added to ready queue [Q A0 A6]
time 166600ms: Process A1 completed a CPU burst; 4 bursts to go [Q A0 A6]
time 166600ms: Process A1 switching out of CPU; blocking on I/O until time 166854ms [Q A0 A6]
time 166606ms: Process A0 started using the CPU for 3052ms burst [Q A6]
time 166854ms: Process A1 completed I/O; added to ready queue [Q A6 A1]
time 169658ms: Process A0 completed a CPU burst; 1 burst to go [Q A6 A1]
time 169658ms: Process A0 switching out of CPU; blocking on I/O until time 170219ms [Q A6 A1]
time 169664ms: Process A6 started using the CPU for 81ms burst [Q A1]
time 169745ms: Process A6 completed a CPU burst; 8 bursts to go [Q A1]
time 169745ms: Process A6 switching out of CPU; blocking on I/O until time 177188ms [Q A1]
time 169751ms: Process A1 started using the CPU for 2652ms burst [Q empty]
time 170219ms: Process A0 completed I/O; added to ready queue [Q A0]
time 172125ms: Process A7 completed I/O; added to ready queue [Q A0 A7]
time 172403ms: Process A1 completed a CPU burst; 3 bursts to go [Q A0 A7]
time 172403ms: Process A1 switching out of CPU; blocking on I/O until time 173174ms [Q A0 A7]
time 172409ms: Process A0 started using the CPU for 2044ms burst [Q A7]
time 173174ms: Process A1 completed I/O; added to ready queue [Q A7 A1]
time 174453ms: Process A0 terminated [Q A7 A1]
time 174459ms: Process A7 started using the CPU for 188ms burst [Q A1]
time 174647ms: Process A7 completed a CPU burst; 1 burst to go [Q A1]
time 174647ms: Process A7 switching out of CPU; blocking on I/O until time 178546ms [Q A1]
time 174653ms: Process A1 started using the CPU for 3812ms burst [Q empty]
time 177188ms: Process A6 completed I/O; added to ready queue [Q A6]
time 178465ms: Process A1 completed a CPU burst; 2 bursts to go [Q A6]
time 178465ms: Process A1 switching out of CPU; blocking on I/O until time 178995ms [Q A6]
time 178471ms: Process A6 started using the CPU for 25ms burst [Q empty]
time 178496ms: Process A6 completed a CPU burst; 7 bursts to go [Q empty]
time 178496ms: Process A6 switching out of CPU; blocking on I/O until time 179443ms [Q empty]
time 178546ms: Process A7 completed I/O; added to ready queue [Q A7]
time 178549ms: Process A7 started using the CPU for 214ms burst [Q empty]
time 178763ms: Process A7 terminated [Q empty]
time 178995ms: Process A1 completed I/O; added to ready queue [Q A1]
time 178998ms: Process A1 started using the CPU for 2288ms burst [Q empty]
time 179443ms: Process A6 completed I/O; added to ready queue [Q A6]
time 181286ms: Process A1 completed a CPU burst; 1 burst to go [Q A6]
time 181286ms: Process A1 switching out of CPU; blocking on I/O until time 181455ms [Q A6]
time 181292ms: Process A6 started using the CPU for 445ms burst [Q empty]
time 181455ms: Process A1 completed I/O; added to ready queue [Q A1]
time 181737ms: Process A6 completed a CPU burst; 6 bursts to go [Q A1]
time 181737ms: Process A6 switching out of CPU; blocking on I/O until time 184948ms [Q A1]
time 181743ms: Process A1 started using the CPU for 388ms burst [Q empty]
time 182131ms: Process A1 terminated [Q empty]
time 184948ms: Process A6 completed I/O; added to ready queue [Q A6]
time 184951ms: Process A6 started using the CPU for 35ms burst [Q empty]
time 184986ms: Process A6 completed a CPU burst; 5 bursts to go [Q empty]
time 184986ms: Process A6 switching out of CPU; blocking on I/O until time 188029ms [Q empty]
time 188029ms: Process A6 completed I/O; added to ready queue [Q A6]
time 188032ms: Process A6 started using the CPU for 245ms burst [Q empty]
time 188277ms: Process A6 completed a CPU burst; 4 bursts to go [Q empty]
time 188277ms: Process A6 switching out of CPU; blocking on I/O until time 195520ms [Q empty]
time 195520ms: Process A6 completed I/O; added to ready queue [Q A6]
time 195523ms: Process A6 started using the CPU for 732ms burst [Q empty]
time 196255ms: Process A6 completed a CPU burst; 3 bursts to go [Q empty]
time 196255ms: Process A6 switching out of CPU; blocking on I/O until time 198322ms [Q empty]
time 198322ms: Process A6 completed I/O; added to ready queue [Q A6]
time 198325ms: Process A6 started using the CPU for 850ms burst [Q empty]
time 199175ms: Process A6 completed a CPU burst; 2 bursts to go [Q empty]
time 199175ms: Process A6 switching out of CPU; blocking on I/O until time 205978ms [Q empty]
time 205978ms: Process A6 completed I/O; added to ready queue [Q A6]
time 205981ms: Process A6 started using the CPU for 667ms burst [Q empty]
time 206648ms: Process A6 completed a CPU burst; 1 burst to go [Q empty]
time 206648ms: Process A6 switching out of CPU; blocking on I/O until time 206899ms [Q empty]
time 206899ms: Process A6 completed I/O; added to ready queue [Q A6]
time 206902ms: Process A6 started using the CPU for 370ms burst [Q empty]
time 207272ms: Process A6 terminated [Q empty]
time 207275ms: Simulator ended for FCFS [Q empty]

time 0ms: Simulator started for SJF [Q empty]
time 54ms: Process A0 arrived; added to ready queue [Q A0]
time 56ms: Process A1 arrived; added to ready queue [Q A1]
time 57ms: Process A0 started using the CPU for 3764ms burst [Q A1]
time 115ms: Process A5 arrived; added to ready queue [Q A5 A1]
time 242ms: Process A6 arrived; added to ready queue [Q A5 A6 A1]
time 346ms: Process A4 arrived; added to ready queue [Q A5 A6 A4 A1]
time 357ms: Process A7 arrived; added to ready queue [Q A7 A5 A6 A4 A1]
time 456ms: Process A2 arrived; added to ready queue [Q A7 A5 A6 A2 A4 A1]
time 758ms: Process A3 arrived; added to ready queue [Q A7 A3 A5 A6 A2 A4 A1]
time 3821ms: Process A0 completed a CPU burst; 28 bursts to go [Q A7 A3 A5 A6 A2 A4 A1]
time 3821ms: Process A0 switching out of CPU; blocking on I/O until time 4510ms [Q A7 A3 A5 A6 A2 A4 A1]
time 3827ms: Process A7 started using the CPU for 297ms burst [Q A3 A5 A6 A2 A4 A1]
time 4124ms: Process A7 completed a CPU burst; 20 bursts to go [Q A3 A5 A6 A2 A4 A1]
time 4124ms: Process A7 switching out of CPU; blocking on I/O until time 11991ms [Q A3 A5 A6 A2 A4 A1]
time 4130ms: Process A3 started using the CPU for 548ms burst [Q A5 A6 A2 A4 A1]
time 4510ms: Process A0 completed I/O; added to ready queue [Q A5 A6 A0 A2 A4 A1]
time 4678ms: Process A3 completed a CPU burst; 15 bursts to go [Q A5 A6 A0 A2 A4 A1]
time 4678ms: Process A3 switching out of CPU; blocking on I/O until time 5480ms [Q A5 A6 A0 A2 A4 A1]
time 4684ms: Process A5 started using the CPU for 564ms burst [Q A6 A0 A2 A4 A1]
time 5248ms: Process A5 terminated [Q A6 A0 A2 A4 A1]
time 5254ms: Process A6 started using the CPU for 761ms burst [Q A0 A2 A4 A1]
time 5480ms: Process A3 completed I/O; added to ready queue [Q A3 A0 A2 A4 A1]
time 6015ms: Process A6 completed a CPU burst; 26 bursts to go [Q A3 A0 A2 A4 A1]
time 6015ms: Process A6 switching out of CPU; blocking on I/O until time 8282ms [Q A3 A0 A2 A4 A1]
time 6021ms: Process A3 started using the CPU for 428ms burst [Q A0 A2 A4 A1]
time 6449ms: Process A3 completed a CPU burst; 14 bursts to go [Q A0 A2 A4 A1]
time 6449ms: Process A3 switching out of CPU; blocking on I/O until time 7390ms [Q A0 A2 A4 A1]
time 6455ms: Process A0 started using the CPU for 1732ms burst [Q A2 A4 A1]
time 7390ms: Process A3 completed I/O; added to ready queue [Q A3 A2 A4 A1]
time 8187ms: Process A0 completed a CPU burst; 27 bursts to go [Q A3 A2 A4 A1]
time 8187ms: Process A0 switching out of CPU; blocking on I/O until time 8402ms [Q A3 A2 A4 A1]
time 8193ms: Process A3 started using the CPU for 1432ms burst [Q A2 A4 A1]
time 8282ms: Process A6 completed I/O; added to ready queue [Q A6 A2 A4 A1]
time 8402ms: Process A0 completed I/O; added to ready queue [Q A0 A6 A2 A4 A1]
time 9625ms: Process A3 completed a CPU burst; 13 bursts to go [Q A0 A6 A2 A4 A1]
time 9625ms: Process A3 switching out of CPU; blocking on I/O until time 9945ms [Q A0 A6 A2 A4 A1]
time 9631ms: Process A0 started using the CPU for 844ms burst [Q A6 A2 A4 A1]
time 9945ms: Process A3 completed I/O; added to ready queue [Q A6 A2 A4 A1 A3]
time 10475ms: Process A0 completed a CPU burst; 26 bursts to go [Q A6 A2 A4 A1 A3]
time 10475ms: Process A0 switching out of CPU; blocking on I/O until time 10971ms [Q A6 A2 A4 A1 A3]
time 10481ms: Process A6 started using the CPU for 903ms burst [Q A2 A4 A1 A3]
time 10971ms: Process A0 completed I/O; added to ready queue [Q A0 A2 A4 A1 A3]
time 11384ms: Process A6 completed a CPU burst; 25 bursts to go [Q A0 A2 A4 A1 A3]
time 11384ms: Process A6 switching out of CPU; blocking on I/O until time 13435ms [Q A0 A2 A4 A1 A3]
time 11390ms: Process A0 started using the CPU for 168ms burst [Q A2 A4 A1 A3]
time 11558ms: Process A0 completed a CPU burst; 25 bursts to go [Q A2 A4 A1 A3]
time 11558ms: Process A0 switching out of CPU; blocking on I/O until time 11933ms [Q A2 A4 A1 A3]
time 11564ms: Process A2 started using the CPU for 1896ms burst [Q A4 A1 A3]
time 11933ms: Process A0 completed I/O; added to ready queue [Q A0 A4 A1 A3]
time 11991ms: Process A7 completed I/O; added to ready queue [Q A7 A0 A4 A1 A3]
time 13435ms: Process A6 completed I/O; added to ready queue [Q A6 A7 A0 A4 A1 A3]
time 13460ms: Process A2 completed a CPU burst; 8 bursts to go [Q A6 A7 A0 A4 A1 A3]
time 13460ms: Process A2 switching out of CPU; blocking on I/O until time 14081ms [Q A6 A7 A0 A4 A1 A3]
time 13466ms: Process A6 started using the CPU for 303ms burst [Q A7 A0 A4 A1 A3]
time 13769ms: Process A6 completed a CPU burst; 24 bursts to go [Q A7 A0 A4 A1 A3]
time 13769ms: Process A6 switching out of CPU; blocking on I/O until time 21100ms [Q A7 A0 A4 A1 A3]
time 13775ms: Process A7 started using the CPU for 598ms burst [Q A0 A4 A1 A3]
time 14081ms: Process A2 completed I/O; added to ready queue [Q A0 A4 A1 A2 A3]
time 14373ms: Process A7 completed a CPU burst; 19 bursts to go [Q A0 A4 A1 A2 A3]
time 14373ms: Process A7 switching out of CPU; blocking on I/O until time 16832ms [Q A0 A4 A1 A2 A3]
time 14379ms: Process A0 started using the CPU for 736ms burst [Q A4 A1 A2 A3]
time 15115ms: Process A0 completed a CPU burst; 24 bursts to go [Q A4 A1 A2 A3]
time 15115ms: Process A0 switching out of CPU; blocking on I/O until time 15259ms [Q A4 A1 A2 A3]
time 15121ms: Process A4 started using the CPU for 2428ms burst [Q A1 A2 A3]
time 15259ms: Process A0 completed I/O; added to ready queue [Q A0 A1 A2 A3]
time 16832ms: Process A7 completed I/O; added to ready queue [Q A7 A0 A1 A2 A3]
time 17549ms: Process A4 completed a CPU burst; 1 burst to go [Q A7 A0 A1 A2 A3]
time 17549ms: Process A4 switching out of CPU; blocking on I/O until time 18061ms [Q A7 A0 A1 A2 A3]
time 17555ms: Process A7 started using the CPU for 721ms burst [Q A0 A1 A2 A3]
time 18061ms: Process A4 completed I/O; added to ready queue [Q A0 A4 A1 A2 A3]
time 18276ms: Process A7 completed a CPU burst; 18 bursts to go [Q A0 A4 A1 A2 A3]
time 18276ms: Process A7 switching out of CPU; blocking on I/O until time 21015ms [Q A0 A4 A1 A2 A3]
time 18282ms: Process A0 started using the CPU for 1372ms burst [Q A4 A1 A2 A3]
time 19654ms: Process A0 completed a CPU burst; 23 bursts to go [Q A4 A1 A2 A3]
time 19654ms: Process A0 switching out of CPU; blocking on I/O until time 20211ms [Q A4 A1 A2 A3]
time 19660ms: Process A4 started using the CPU for 2532ms burst [Q A1 A2 A3]
time 20211ms: Process A0 completed I/O; added to ready queue [Q A0 A1 A2 A3]
time 21015ms: Process A7 completed I/O; added to ready queue [Q A7 A0 A1 A2 A3]
time 21100ms: Process A6 completed I/O; added to ready queue [Q A6 A7 A0 A1 A2 A3]
time 22192ms: Process A4 terminated [Q A6 A7 A0 A1 A2 A3]
time 22198ms: Process A6 started using the CPU for 194ms burst [Q A7 A0 A1 A2 A3]
time 22392ms: Process A6 completed a CPU burst; 23 bursts to go [Q A7 A0 A1 A2 A3]
time 22392ms: Process A6 switching out of CPU; blocking on I/O until time 29291ms [Q A7 A0 A1 A2 A3]
time 22398ms: Process A7 started using the CPU for 641ms burst [Q A0 A1 A2 A3]
time 23039ms: Process A7 completed a CPU burst; 17 bursts to go [Q A0 A1 A2 A3]
time 23039ms: Process A7 switching out of CPU; blocking on I/O until time 24986ms [Q A0 A1 A2 A3]
time 23045ms: Process A0 started using the CPU for 1808ms burst [Q A1 A2 A3]
time 24853ms: Process A0 completed a CPU burst; 22 bursts to go [Q A1 A2 A3]
time 24853ms: Process A0 switching out of CPU; blocking on I/O until time 25005ms [Q A1 A2 A3]
time 24859ms: Process A1 started using the CPU for 2828ms burst [Q A2 A3]
time 24986ms: Process A7 completed I/O; added to ready queue [Q A7 A2 A3]
time 25005ms: Process A0 completed I/O; added to ready queue [Q A7 A0 A2 A3]
time 27687ms: Process A1 completed a CPU burst; 30 bursts to go [Q A7 A0 A2 A3]
time 27687ms: Process A1 switching out of CPU; blocking on I/O until time 28012ms [Q A7 A0 A2 A3]
time 27693ms: Process A7 started using the CPU for 128ms burst [Q A0 A2 A3]
time 27821ms: Process A7 completed a CPU burst; 16 bursts to go [Q A0 A2 A3]
time 27821ms: Process A7 switching out of CPU; blocking on I/O until time 33992ms [Q A0 A2 A3]
time 27827ms: Process A0 started using the CPU for 1808ms burst [Q A2 A3]
time 28012ms: Process A1 completed I/O; added to ready queue [Q A1 A2 A3]
time 29291ms: Process A6 completed I/O; added to ready queue [Q A6 A1 A2 A3]
time 29635ms: Process A0 completed a CPU burst; 21 bursts to go [Q A6 A1 A2 A3]
time 29635ms: Process A0 switching out of CPU; blocking on I/O until time 29904ms [Q A6 A1 A2 A3]
time 29641ms: Process A6 started using the CPU for 203ms burst [Q A1 A2 A3]
time 29844ms: Process A6 completed a CPU burst; 22 bursts to go [Q A1 A2 A3]
time 29844ms: Process A6 switching out of CPU; blocking on I/O until time 32647ms [Q A1 A2 A3]
time 29850ms: Process A1 started using the CPU for 1444ms burst [Q A2 A3]
time 29904ms: Process A0 completed I/O; added to ready queue [Q A0 A2 A3]
time 31294ms: Process A1 completed a CPU burst; 29 bursts to go [Q A0 A2 A3]
time 31294ms: Process A1 switching out of CPU; blocking on I/O until time 31464ms [Q A0 A2 A3]
time 31300ms: Process A0 started using the CPU for 848ms burst [Q A2 A3]
time 31464ms: Process A1 completed I/O; added to ready queue [Q A1 A2 A3]
time 32148ms: Process A0 completed a CPU burst; 20 bursts to go [Q A1 A2 A3]
time 32148ms: Process A0 switching out of CPU; blocking on I/O until time 32226ms [Q A1 A2 A3]
time 32154ms: Process A1 started using the CPU for 2476ms burst [Q A2 A3]
time 32226ms: Process A0 completed I/O; added to ready queue [Q A2 A0 A3]
time 32647ms: Process A6 completed I/O; added to ready queue [Q A6 A2 A0 A3]
time 33992ms: Process A7 completed I/O; added to ready queue [Q A7 A6 A2 A0 A3]
time 34630ms: Process A1 completed a CPU burst; 28 bursts to go [Q A7 A6 A2 A0 A3]
time 34630ms: Process A1 switching out of CPU; blocking on I/O until time 35050ms [Q A7 A6 A2 A0 A3]
time 34636ms: Process A7 started using the CPU for 277ms burst [Q A6 A2 A0 A3]
time 34913ms: Process A7 completed a CPU burst; 15 bursts to go [Q A6 A2 A0 A3]
time 34913ms: Process A7 switching out of CPU; blocking on I/O until time 35764ms [Q A6 A2 A0 A3]
time 34919ms: Process A6 started using the CPU for 603ms burst [Q A2 A0 A3]
time 35050ms: Process A1 completed I/O; added to ready queue [Q A1 A2 A0 A3]
time 35522ms: Process A6 completed a CPU burst; 21 bursts to go [Q A1 A2 A0 A3]
time 35522ms: Process A6 switching out of CPU; blocking on I/O until time 38589ms [Q A1 A2 A0 A3]
time 35528ms: Process A1 started using the CPU for 2256ms burst [Q A2 A0 A3]
time 35764ms: Process A7 completed I/O; added to ready queue [Q A7 A2 A0 A3]
time 37784ms: Process A1 completed a CPU burst; 27 bursts to go [Q A7 A2 A0 A3]
time 37784ms: Process A1 switching out of CPU; blocking on I/O until time 38077ms [Q A7 A2 A0 A3]
time 37790ms: Process A7 started using the CPU for 984ms burst [Q A2 A0 A3]
time 38077ms: Process A1 completed I/O; added to ready queue [Q A1 A2 A0 A3]
time 38589ms: Process A6 completed I/O; added to ready queue [Q A6 A1 A2 A0 A3]
time 38774ms: Process A7 completed a CPU burst; 14 bursts to go [Q A6 A1 A2 A0 A3]
time 38774ms: Process A7 switching out of CPU; blocking on I/O until time 43985ms [Q A6 A1 A2 A0 A3]
time 38780ms: Process A6 started using the CPU for 95ms burst [Q A1 A2 A0 A3]
time 38875ms: Process A6 completed a CPU burst; 20 bursts to go [Q A1 A2 A0 A3]
time 38875ms: Process A6 switching out of CPU; blocking on I/O until time 39934ms [Q A1 A2 A0 A3]
time 38881ms: Process A1 started using the CPU for 1188ms burst [Q A2 A0 A3]
time 39934ms: Process A6 completed I/O; added to ready queue [Q A6 A2 A0 A3]
time 40069ms: Process A1 completed a CPU burst; 26 bursts to go [Q A6 A2 A0 A3]
time 40069ms: Process A1 switching out of CPU; blocking on I/O until time 40849ms [Q A6 A2 A0 A3]
time 40075ms: Process A6 started using the CPU for 556ms burst [Q A2 A0 A3]
time 40631ms: Process A6 completed a CPU burst; 19 bursts to go [Q A2 A0 A3]
time 40631ms: Process A6 switching out of CPU; blocking on I/O until time 44010ms [Q A2 A0 A3]
time 40637ms: Process A2 started using the CPU for 2940ms burst [Q A0 A3]
time 40849ms: Process A1 completed I/O; added to ready queue [Q A1 A0 A3]
time 43577ms: Process A2 completed a CPU burst; 7 bursts to go [Q A1 A0 A3]
time 43577ms: Process A2 switching out of CPU; blocking on I/O until time 44019ms [Q A1 A0 A3]
time 43583ms: Process A1 started using the CPU for 2812ms burst [Q A0 A3]
time 43985ms: Process A7 completed I/O; added to ready queue [Q A7 A0 A3]
time 44010ms: Process A6 completed I/O; added to ready queue [Q A6 A7 A0 A3]
time 44019ms: Process A2 completed I/O; added to ready queue [Q A2 A6 A7 A0 A3]
time 46395ms: Process A1 completed a CPU burst; 25 bursts to go [Q A2 A6 A7 A0 A3]
time 46395ms: Process A1 switching out of CPU; blocking on I/O until time 47261ms [Q A2 A6 A7 A0 A3]
time 46401ms: Process A2 started using the CPU for 248ms burst [Q A6 A7 A0 A3]
time 46649ms: Process A2 completed a CPU burst; 6 bursts to go [Q A6 A7 A0 A3]
time 46649ms: Process A2 switching out of CPU; blocking on I/O until time 47116ms [Q A6 A7 A0 A3]
time 46655ms: Process A6 started using the CPU for 599ms burst [Q A7 A0 A3]
time 47116ms: Process A2 completed I/O; added to ready queue [Q A2 A7 A0 A3]
time 47254ms: Process A6 completed a CPU burst; 18 bursts to go [Q A2 A7 A0 A3]
time 47254ms: Process A6 switching out of CPU; blocking on I/O until time 47817ms [Q A2 A7 A0 A3]
time 47260ms: Process A2 started using the CPU for 952ms burst [Q A7 A0 A3]
time 47261ms: Process A1 completed I/O; added to ready queue [Q A1 A7 A0 A3]
time 47817ms: Process A6 completed I/O; added to ready queue [Q A6 A1 A7 A0 A3]
time 48212ms: Process A2 completed a CPU burst; 5 bursts to go [Q A6 A1 A7 A0 A3]
time 48212ms: Process A2 switching out of CPU; blocking on I/O until time 48989ms [Q A6 A1 A7 A0 A3]
time 48218ms: Process A6 started using the CPU for 58ms burst [Q A1 A7 A0 A3]
time 48276ms: Process A6 completed a CPU burst; 17 bursts to go [Q A1 A7 A0 A3]
time 48276ms: Process A6 switching out of CPU; blocking on I/O until time 50335ms [Q A1 A7 A0 A3]
time 48282ms: Process A1 started using the CPU for 368ms burst [Q A7 A0 A3]
time 48650ms: Process A1 completed a CPU burst; 24 bursts to go [Q A7 A0 A3]
time 48650ms: Process A1 switching out of CPU; blocking on I/O until time 48826ms [Q A7 A0 A3]
time 48656ms: Process A7 started using the CPU for 961ms burst [Q A0 A3]
time 48826ms: Process A1 completed I/O; added to ready queue [Q A1 A0 A3]
time 48989ms: Process A2 completed I/O; added to ready queue [Q A1 A2 A0 A3]
time 49617ms: Process A7 completed a CPU burst; 13 bursts to go [Q A1 A2 A0 A3]
time 49617ms: Process A7 switching out of CPU; blocking on I/O until time 53052ms [Q A1 A2 A0 A3]
time 49623ms: Process A1 started using the CPU for 200ms burst [Q A2 A0 A3]
time 49823ms: Process A1 completed a CPU burst; 23 bursts to go [Q A2 A0 A3]
time 49823ms: Process A1 switching out of CPU; blocking on I/O until time 50433ms [Q A2 A0 A3]
time 49829ms: Process A2 started using the CPU for 1796ms burst [Q A0 A3]
time 50335ms: Process A6 completed I/O; added to ready queue [Q A6 A0 A3]
time 50433ms: Process A1 completed I/O; added to ready queue [Q A6 A1 A0 A3]
time 51625ms: Process A2 completed a CPU burst; 4 bursts to go [Q A6 A1 A0 A3]
time 51625ms: Process A2 switching out of CPU; blocking on I/O until time 52039ms [Q A6 A1 A0 A3]
time 51631ms: Process A6 started using the CPU for 455ms burst [Q A1 A0 A3]
time 52039ms: Process A2 completed I/O; added to ready queue [Q A1 A2 A0 A3]
time 52086ms: Process A6 completed a CPU burst; 16 bursts to go [Q A1 A2 A0 A3]
time 52086ms: Process A6 switching out of CPU; blocking on I/O until time 55201ms [Q A1 A2 A0 A3]
time 52092ms: Process A1 started using the CPU for 1044ms burst [Q A2 A0 A3]
time 53052ms: Process A7 completed I/O; added to ready queue [Q A7 A2 A0 A3]
time 53136ms: Process A1 completed a CPU burst; 22 bursts to go [Q A7 A2 A0 A3]
time 53136ms: Process A1 switching out of CPU; blocking on I/O until time 53731ms [Q A7 A2 A0 A3]
time 53142ms: Process A7 started using the CPU for 587ms burst [Q A2 A0 A3]
time 53729ms: Process A7 completed a CPU burst; 12 bursts to go [Q A2 A0 A3]
time 53729ms: Process A7 switching out of CPU; blocking on I/O until time 54524ms [Q A2 A0 A3]
time 53731ms: Process A1 completed I/O; added to ready queue [Q A1 A2 A0 A3]
time 53735ms: Process A1 started using the CPU for 940ms burst [Q A2 A0 A3]
time 54524ms: Process A7 completed I/O; added to ready queue [Q A7 A2 A0 A3]
time 54675ms: Process A1 completed a CPU burst; 21 bursts to go [Q A7 A2 A0 A3]
time 54675ms: Process A1 switching out of CPU; blocking on I/O until time 55123ms [Q A7 A2 A0 A3]
time 54681ms: Process A7 started using the CPU for 33ms burst [Q A2 A0 A3]
time 54714ms: Process A7 completed a CPU burst; 11 bursts to go [Q A2 A0 A3]
time 54714ms: Process A7 switching out of CPU; blocking on I/O until time 57301ms [Q A2 A0 A3]
time 54720ms: Process A2 started using the CPU for 2200ms burst [Q A0 A3]
time 55123ms: Process A1 completed I/O; added to ready queue [Q A1 A0 A3]
time 55201ms: Process A6 completed I/O; added to ready queue [Q A1 A6 A0 A3]
time 56920ms: Process A2 completed a CPU burst; 3 bursts to go [Q A1 A6 A0 A3]
time 56920ms: Process A2 switching out of CPU; blocking on I/O until time 56938ms [Q A1 A6 A0 A3]
time 56926ms: Process A1 started using the CPU for 660ms burst [Q A6 A0 A3]
time 56938ms: Process A2 completed I/O; added to ready queue [Q A6 A2 A0 A3]
time 57301ms: Process A7 completed I/O; added to ready queue [Q A6 A7 A2 A0 A3]
time 57586ms: Process A1 completed a CPU burst; 20 bursts to go [Q A6 A7 A2 A0 A3]
time 57586ms: Process A1 switching out of CPU; blocking on I/O until time 57617ms [Q A6 A7 A2 A0 A3]
time 57592ms: Process A6 started using the CPU for 826ms burst [Q A7 A2 A0 A3]
time 57617ms: Process A1 completed I/O; added to ready queue [Q A7 A2 A1 A0 A3]
time 58418ms: Process A6 completed a CPU burst; 15 bursts to go [Q A7 A2 A1 A0 A3]
time 58418ms: Process A6 switching out of CPU; blocking on I/O until time 61061ms [Q A7 A2 A1 A0 A3]
time 58424ms: Process A7 started using the CPU for 875ms burst [Q A2 A1 A0 A3]
time 59299ms: Process A7 completed a CPU burst; 10 bursts to go [Q A2 A1 A0 A3]
time 59299ms: Process A7 switching out of CPU; blocking on I/O until time 61654ms [Q A2 A1 A0 A3]
time 59305ms: Process A2 started using the CPU for 1512ms burst [Q A1 A0 A3]
time 60817ms: Process A2 completed a CPU burst; 2 bursts to go [Q A1 A0 A3]
time 60817ms: Process A2 switching out of CPU; blocking on I/O until time 61607ms [Q A1 A0 A3]
time 60823ms: Process A1 started using the CPU for 2196ms burst [Q A0 A3]
time 61061ms: Process A6 completed I/O; added to ready queue [Q A6 A0 A3]
time 61607ms: Process A2 completed I/O; added to ready queue [Q A6 A2 A0 A3]
time 61654ms: Process A7 completed I/O; added to ready queue [Q A7 A6 A2 A0 A3]
time 63019ms: Process A1 completed a CPU burst; 19 bursts to go [Q A7 A6 A2 A0 A3]
time 63019ms: Process A1 switching out of CPU; blocking on I/O until time 63998ms [Q A7 A6 A2 A0 A3]
time 63025ms: Process A7 started using the CPU for 53ms burst [Q A6 A2 A0 A3]
time 63078ms: Process A7 completed a CPU burst; 9 bursts to go [Q A6 A2 A0 A3]
time 63078ms: Process A7 switching out of CPU; blocking on I/O until time 63321ms [Q A6 A2 A0 A3]
time 63084ms: Process A6 started using the CPU for 587ms burst [Q A2 A0 A3]
time 63321ms: Process A7 completed I/O; added to ready queue [Q A7 A2 A0 A3]
time 63671ms: Process A6 completed a CPU burst; 14 bursts to go [Q A7 A2 A0 A3]
time 63671ms: Process A6 switching out of CPU; blocking on I/O until time 65594ms [Q A7 A2 A0 A3]
time 63677ms: Process A7 started using the CPU for 64ms burst [Q A2 A0 A3]
time 63741ms: Process A7 completed a CPU burst; 8 bursts to go [Q A2 A0 A3]
time 63741ms: Process A7 switching out of CPU; blocking on I/O until time 67240ms [Q A2 A0 A3]
time 63747ms: Process A2 started using the CPU for 1764ms burst [Q A0 A3]
time 63998ms: Process A1 completed I/O; added to ready queue [Q A1 A0 A3]
time 65511ms: Process A2 completed a CPU burst; 1 burst to go [Q A1 A0 A3]
time 65511ms: Process A2 switching out of CPU; blocking on I/O until time 65598ms [Q A1 A0 A3]
time 65517ms: Process A1 started using the CPU for 36ms burst [Q A0 A3]
time 65553ms: Process A1 completed a CPU burst; 18 bursts to go [Q A0 A3]
time 65553ms: Process A1 switching out of CPU; blocking on I/O until time 66193ms [Q A0 A3]
time 65559ms: Process A0 started using the CPU for 3384ms burst [Q A3]
time 65594ms: Process A6 completed I/O; added to ready queue [Q A6 A3]
time 65598ms: Process A2 completed I/O; added to ready queue [Q A6 A2 A3]
time 66193ms: Process A1 completed I/O; added to ready queue [Q A6 A2 A3 A1]
time 67240ms: Process A7 completed I/O; added to ready queue [Q A7 A6 A2 A3 A1]
time 68943ms: Process A0 completed a CPU burst; 19 bursts to go [Q A7 A6 A2 A3 A1]
time 68943ms: Process A0 switching out of CPU; blocking on I/O until time 68963ms [Q A7 A6 A2 A3 A1]
time 68949ms: Process A7 started using the CPU for 264ms burst [Q A6 A2 A3 A1]
time 68963ms: Process A0 completed I/O; added to ready queue [Q A0 A6 A2 A3 A1]
time 69213ms: Process A7 completed a CPU burst; 7 bursts to go [Q A0 A6 A2 A3 A1]
time 69213ms: Process A7 switching out of CPU; blocking on I/O until time 70264ms [Q A0 A6 A2 A3 A1]
time 69219ms: Process A0 started using the CPU for 104ms burst [Q A6 A2 A3 A1]
time 69323ms: Process A0 completed a CPU burst; 18 bursts to go [Q A6 A2 A3 A1]
time 69323ms: Process A0 switching out of CPU; blocking on I/O until time 69754ms [Q A6 A2 A3 A1]
time 69329ms: Process A6 started using the CPU for 292ms burst [Q A2 A3 A1]
time 69621ms: Process A6 completed a CPU burst; 13 bursts to go [Q A2 A3 A1]
time 69621ms: Process A6 switching out of CPU; blocking on I/O until time 74104ms [Q A2 A3 A1]
time 69627ms: Process A2 started using the CPU for 1768ms burst [Q A3 A1]
time 69754ms: Process A0 completed I/O; added to ready queue [Q A3 A0 A1]
time 70264ms: Process A7 completed I/O; added to ready queue [Q A7 A3 A0 A1]
time 71395ms: Process A2 terminated [Q A7 A3 A0 A1]
time 71401ms: Process A7 started using the CPU for 228ms burst [Q A3 A0 A1]
time 71629ms: Process A7 completed a CPU burst; 6 bursts to go [Q A3 A0 A1]
time 71629ms: Process A7 switching out of CPU; blocking on I/O until time 73896ms [Q A3 A0 A1]
time 71635ms: Process A3 started using the CPU for 3896ms burst [Q A0 A1]
time 73896ms: Process A7 completed I/O; added to ready queue [Q A7 A0 A1]
time 74104ms: Process A6 completed I/O; added to ready queue [Q A7 A6 A0 A1]
time 75531ms: Process A3 completed a CPU burst; 12 bursts to go [Q A7 A6 A0 A1]
time 75531ms: Process A3 switching out of CPU; blocking on I/O until time 75658ms [Q A7 A6 A0 A1]
time 75537ms: Process A7 started using the CPU for 37ms burst [Q A6 A0 A1]
time 75574ms: Process A7 completed a CPU burst; 5 bursts to go [Q A6 A0 A1]
time 75574ms: Process A7 switching out of CPU; blocking on I/O until time 81073ms [Q A6 A0 A1]
time 75580ms: Process A6 started using the CPU for 572ms burst [Q A0 A1]
time 75658ms: Process A3 completed I/O; added to ready queue [Q A3 A0 A1]
time 76152ms: Process A6 completed a CPU burst; 12 bursts to go [Q A3 A0 A1]
time 76152ms: Process A6 switching out of CPU; blocking on I/O until time 76675ms [Q A3 A0 A1]
time 76158ms: Process A3 started using the CPU for 804ms burst [Q A0 A1]
time 76675ms: Process A6 completed I/O; added to ready queue [Q A6 A0 A1]
time 76962ms: Process A3 completed a CPU burst; 11 bursts to go [Q A6 A0 A1]
time 76962ms: Process A3 switching out of CPU; blocking on I/O until time 77030ms [Q A6 A0 A1]
time 76968ms: Process A6 started using the CPU for 494ms burst [Q A0 A1]
time 77030ms: Process A3 completed I/O; added to ready queue [Q A3 A0 A1]
time 77462ms: Process A6 completed a CPU burst; 11 bursts to go [Q A3 A0 A1]
time 77462ms: Process A6 switching out of CPU; blocking on I/O until time 84553ms [Q A3 A0 A1]
time 77468ms: Process A3 started using the CPU for 2564ms burst [Q A0 A1]
time 80032ms: Process A3 completed a CPU burst; 10 bursts to go [Q A0 A1]
time 80032ms: Process A3 switching out of CPU; blocking on I/O until time 80415ms [Q A0 A1]
time 80038ms: Process A0 started using the CPU for 3924ms burst [Q A1]
time 80415ms: Process A3 completed I/O; added to ready queue [Q A3 A1]
time 81073ms: Process A7 completed I/O; added to ready queue [Q A7 A3 A1]
time 83962ms: Process A0 completed a CPU burst; 17 bursts to go [Q A7 A3 A1]
time 83962ms: Process A0 switching out of CPU; blocking on I/O until time 84632ms [Q A7 A3 A1]
time 83968ms: Process A7 started using the CPU for 364ms burst [Q A3 A1]
time 84332ms: Process A7 completed a CPU burst; 4 bursts to go [Q A3 A1]
time 84332ms: Process A7 switching out of CPU; blocking on I/O until time 88647ms [Q A3 A1]
time 84338ms: Process A3 started using the CPU for 3416ms burst [Q A1]
time 84553ms: Process A6 completed I/O; added to ready queue [Q A6 A1]
time 84632ms: Process A0 completed I/O; added to ready queue [Q A6 A0 A1]
time 87754ms: Process A3 completed a CPU burst; 9 bursts to go [Q A6 A0 A1]
time 87754ms: Process A3 switching out of CPU; blocking on I/O until time 88646ms [Q A6 A0 A1]
time 87760ms: Process A6 started using the CPU for 19ms burst [Q A0 A1]
time 87779ms: Process A6 completed a CPU burst; 10 bursts to go [Q A0 A1]
time 87779ms: Process A6 switching out of CPU; blocking on I/O until time 91998ms [Q A0 A1]
time 87785ms: Process A0 started using the CPU for 3388ms burst [Q A1]
time 88646ms: Process A3 completed I/O; added to ready queue [Q A3 A1]
time 88647ms: Process A7 completed I/O; added to ready queue [Q A7 A3 A1]
time 91173ms: Process A0 completed a CPU burst; 16 bursts to go [Q A7 A3 A1]
time 91173ms: Process A0 switching out of CPU; blocking on I/O until time 91270ms [Q A7 A3 A1]
time 91179ms: Process A7 started using the CPU for 278ms burst [Q A3 A1]
time 91270ms: Process A0 completed I/O; added to ready queue [Q A0 A3 A1]
time 91457ms: Process A7 completed a CPU burst; 3 bursts to go [Q A0 A3 A1]
time 91457ms: Process A7 switching out of CPU; blocking on I/O until time 93972ms [Q A0 A3 A1]
time 91463ms: Process A0 started using the CPU for 100ms burst [Q A3 A1]
time 91563ms: Process A0 completed a CPU burst; 15 bursts to go [Q A3 A1]
time 91563ms: Process A0 switching out of CPU; blocking on I/O until time 92053ms [Q A3 A1]
time 91569ms: Process A3 started using the CPU for 3756ms burst [Q A1]
time 91998ms: Process A6 completed I/O; added to ready queue [Q A6 A1]
time 92053ms: Process A0 completed I/O; added to ready queue [Q A6 A0 A1]
time 93972ms: Process A7 completed I/O; added to ready queue [Q A7 A6 A0 A1]
time 95325ms: Process A3 completed a CPU burst; 8 bursts to go [Q A7 A6 A0 A1]
time 95325ms: Process A3 switching out of CPU; blocking on I/O until time 95979ms [Q A7 A6 A0 A1]
time 95331ms: Process A7 started using the CPU for 23ms burst [Q A6 A0 A1]
time 95354ms: Process A7 completed a CPU burst; 2 bursts to go [Q A6 A0 A1]
time 95354ms: Process A7 switching out of CPU; blocking on I/O until time 103237ms [Q A6 A0 A1]
time 95360ms: Process A6 started using the CPU for 355ms burst [Q A0 A1]
time 95715ms: Process A6 completed a CPU burst; 9 bursts to go [Q A0 A1]
time 95715ms: Process A6 switching out of CPU; blocking on I/O until time 98686ms [Q A0 A1]
time 95721ms: Process A0 started using the CPU for 3868ms burst [Q A1]
time 95979ms: Process A3 completed I/O; added to ready queue [Q A3 A1]
time 98686ms: Process A6 completed I/O; added to ready queue [Q A6 A3 A1]
time 99589ms: Process A0 completed a CPU burst; 14 bursts to go [Q A6 A3 A1]
time 99589ms: Process A0 switching out of CPU; blocking on I/O until time 99704ms [Q A6 A3 A1]
time 99595ms: Process A6 started using the CPU for 81ms burst [Q A3 A1]
time 99676ms: Process A6 completed a CPU burst; 8 bursts to go [Q A3 A1]
time 99676ms: Process A6 switching out of CPU; blocking on I/O until time 107119ms [Q A3 A1]
time 99682ms: Process A3 started using the CPU for 3864ms burst [Q A1]
time 99704ms: Process A0 completed I/O; added to ready queue [Q A0 A1]
time 103237ms: Process A7 completed I/O; added to ready queue [Q A7 A0 A1]
time 103546ms: Process A3 completed a CPU burst; 7 bursts to go [Q A7 A0 A1]
time 103546ms: Process A3 switching out of CPU; blocking on I/O until time 103972ms [Q A7 A0 A1]
time 103552ms: Process A7 started using the CPU for 188ms burst [Q A0 A1]
time 103740ms: Process A7 completed a CPU burst; 1 burst to go [Q A0 A1]
time 103740ms: Process A7 switching out of CPU; blocking on I/O until time 107639ms [Q A0 A1]
time 103746ms: Process A0 started using the CPU for 1516ms burst [Q A1]
time 103972ms: Process A3 completed I/O; added to ready queue [Q A3 A1]
time 105262ms: Process A0 completed a CPU burst; 13 bursts to go [Q A3 A1]
time 105262ms: Process A0 switching out of CPU; blocking on I/O until time 105576ms [Q A3 A1]
time 105268ms: Process A3 started using the CPU for 1144ms burst [Q A1]
time 105576ms: Process A0 completed I/O; added to ready queue [Q A0 A1]
time 106412ms: Process A3 completed a CPU burst; 6 bursts to go [Q A0 A1]
time 106412ms: Process A3 switching out of CPU; blocking on I/O until time 106565ms [Q A0 A1]
time 106418ms: Process A0 started using the CPU for 1260ms burst [Q A1]
time 106565ms: Process A3 completed I/O; added to ready queue [Q A3 A1]
time 107119ms: Process A6 completed I/O; added to ready queue [Q A6 A3 A1]
time 107639ms: Process A7 completed I/O; added to ready queue [Q A6 A7 A3 A1]
time 107678ms: Process A0 completed a CPU burst; 12 bursts to go [Q A6 A7 A3 A1]
time 107678ms: Process A0 switching out of CPU; blocking on I/O until time 108094ms [Q A6 A7 A3 A1]
time 107684ms: Process A6 started using the CPU for 25ms burst [Q A7 A3 A1]
time 107709ms: Process A6 completed a CPU burst; 7 bursts to go [Q A7 A3 A1]
time 107709ms: Process A6 switching out of CPU; blocking on I/O until time 108656ms [Q A7 A3 A1]
time 107715ms: Process A7 started using the CPU for 214ms burst [Q A3 A1]
time 107929ms: Process A7 terminated [Q A3 A1]
time 107935ms: Process A3 started using the CPU for 492ms burst [Q A1]
time 108094ms: Process A0 completed I/O; added to ready queue [Q A0 A1]
time 108427ms: Process A3 completed a CPU burst; 5 bursts to go [Q A0 A1]
time 108427ms: Process A3 switching out of CPU; blocking on I/O until time 108798ms [Q A0 A1]
time 108433ms: Process A0 started using the CPU for 728ms burst [Q A1]
time 108656ms: Process A6 completed I/O; added to ready queue [Q A6 A1]
time 108798ms: Process A3 completed I/O; added to ready queue [Q A6 A3 A1]
time 109161ms: Process A0 completed a CPU burst; 11 bursts to go [Q A6 A3 A1]
time 109161ms: Process A0 switching out of CPU; blocking on I/O until time 109937ms [Q A6 A3 A1]
time 109167ms: Process A6 started using the CPU for 445ms burst [Q A3 A1]
time 109612ms: Process A6 completed a CPU burst; 6 bursts to go [Q A3 A1]
time 109612ms: Process A6 switching out of CPU; blocking on I/O until time 112823ms [Q A3 A1]
time 109618ms: Process A3 started using the CPU for 2704ms burst [Q A1]
time 109937ms: Process A0 completed I/O; added to ready queue [Q A0 A1]
time 112322ms: Process A3 completed a CPU burst; 4 bursts to go [Q A0 A1]
time 112322ms: Process A3 switching out of CPU; blocking on I/O until time 112501ms [Q A0 A1]
time 112328ms: Process A0 started using the CPU for 2568ms burst [Q A1]
time 112501ms: Process A3 completed I/O; added to ready queue [Q A3 A1]
time 112823ms: Process A6 completed I/O; added to ready queue [Q A6 A3 A1]
time 114896ms: Process A0 completed a CPU burst; 10 bursts to go [Q A6 A3 A1]
time 114896ms: Process A0 switching out of CPU; blocking on I/O until time 115247ms [Q A6 A3 A1]
time 114902ms: Process A6 started using the CPU for 35ms burst [Q A3 A1]
time 114937ms: Process A6 completed a CPU burst; 5 bursts to go [Q A3 A1]
time 114937ms: Process A6 switching out of CPU; blocking on I/O until time 117980ms [Q A3 A1]
time 114943ms: Process A3 started using the CPU for 316ms burst [Q A1]
time 115247ms: Process A0 completed I/O; added to ready queue [Q A0 A1]
time 115259ms: Process A3 completed a CPU burst; 3 bursts to go [Q A0 A1]
time 115259ms: Process A3 switching out of CPU; blocking on I/O until time 115930ms [Q A0 A1]
time 115265ms: Process A0 started using the CPU for 1220ms burst [Q A1]
time 115930ms: Process A3 completed I/O; added to ready queue [Q A3 A1]
time 116485ms: Process A0 completed a CPU burst; 9 bursts to go [Q A3 A1]
time 116485ms: Process A0 switching out of CPU; blocking on I/O until time 117371ms [Q A3 A1]
time 116491ms: Process A3 started using the CPU for 204ms burst [Q A1]
time 116695ms: Process A3 completed a CPU burst; 2 bursts to go [Q A1]
time 116695ms: Process A3 switching out of CPU; blocking on I/O until time 117030ms [Q A1]
time 116701ms: Process A1 started using the CPU for 4060ms burst [Q empty]
time 117030ms: Process A3 completed I/O; added to ready queue [Q A3]
time 117371ms: Process A0 completed I/O; added to ready queue [Q A0 A3]
time 117980ms: Process A6 completed I/O; added to ready queue [Q A6 A0 A3]
time 120761ms: Process A1 completed a CPU burst; 17 bursts to go [Q A6 A0 A3]
time 120761ms: Process A1 switching out of CPU; blocking on I/O until time 120854ms [Q A6 A0 A3]
time 120767ms: Process A6 started using the CPU for 245ms burst [Q A0 A3]
time 120854ms: Process A1 completed I/O; added to ready queue [Q A0 A3 A1]
time 121012ms: Process A6 completed a CPU burst; 4 bursts to go [Q A0 A3 A1]
time 121012ms: Process A6 switching out of CPU; blocking on I/O until time 128255ms [Q A0 A3 A1]
time 121018ms: Process A0 started using the CPU for 2296ms burst [Q A3 A1]
time 123314ms: Process A0 completed a CPU burst; 8 bursts to go [Q A3 A1]
time 123314ms: Process A0 switching out of CPU; blocking on I/O until time 123981ms [Q A3 A1]
time 123320ms: Process A3 started using the CPU for 2328ms burst [Q A1]
time 123981ms: Process A0 completed I/O; added to ready queue [Q A0 A1]
time 125648ms: Process A3 completed a CPU burst; 1 burst to go [Q A0 A1]
time 125648ms: Process A3 switching out of CPU; blocking on I/O until time 126547ms [Q A0 A1]
time 125654ms: Process A0 started using the CPU for 3268ms burst [Q A1]
time 126547ms: Process A3 completed I/O; added to ready queue [Q A3 A1]
time 128255ms: Process A6 completed I/O; added to ready queue [Q A6 A3 A1]
time 128922ms: Process A0 completed a CPU burst; 7 bursts to go [Q A6 A3 A1]
time 128922ms: Process A0 switching out of CPU; blocking on I/O until time 129848ms [Q A6 A3 A1]
time 128928ms: Process A6 started using the CPU for 732ms burst [Q A3 A1]
time 129660ms: Process A6 completed a CPU burst; 3 bursts to go [Q A3 A1]
time 129660ms: Process A6 switching out of CPU; blocking on I/O until time 131727ms [Q A3 A1]
time 129666ms: Process A3 started using the CPU for 2760ms burst [Q A1]
time 129848ms: Process A0 completed I/O; added to ready queue [Q A0 A1]
time 131727ms: Process A6 completed I/O; added to ready queue [Q A6 A0 A1]
time 132426ms: Process A3 terminated [Q A6 A0 A1]
time 132432ms: Process A6 started using the CPU for 850ms burst [Q A0 A1]
time 133282ms: Process A6 completed a CPU burst; 2 bursts to go [Q A0 A1]
time 133282ms: Process A6 switching out of CPU; blocking on I/O until time 140085ms [Q A0 A1]
time 133288ms: Process A0 started using the CPU for 3468ms burst [Q A1]
time 136756ms: Process A0 completed a CPU burst; 6 bursts to go [Q A1]
time 136756ms: Process A0 switching out of CPU; blocking on I/O until time 137047ms [Q A1]
time 136762ms: Process A1 started using the CPU for 3904ms burst [Q empty]
time 137047ms: Process A0 completed I/O; added to ready queue [Q A0]
time 140085ms: Process A6 completed I/O; added to ready queue [Q A6 A0]
time 140666ms: Process A1 completed a CPU burst; 16 bursts to go [Q A6 A0]
time 140666ms: Process A1 switching out of CPU; blocking on I/O until time 141203ms [Q A6 A0]
time 140672ms: Process A6 started using the CPU for 667ms burst [Q A0]
time 141203ms: Process A1 completed I/O; added to ready queue [Q A1 A0]
time 141339ms: Process A6 completed a CPU burst; 1 burst to go [Q A1 A0]
time 141339ms: Process A6 switching out of CPU; blocking on I/O until time 141590ms [Q A1 A0]
time 141345ms: Process A1 started using the CPU for 1488ms burst [Q A0]
time 141590ms: Process A6 completed I/O; added to ready queue [Q A6 A0]
time 142833ms: Process A1 completed a CPU burst; 15 bursts to go [Q A6 A0]
time 142833ms: Process A1 switching out of CPU; blocking on I/O until time 143240ms [Q A6 A0]
time 142839ms: Process A6 started using the CPU for 370ms burst [Q A0]
time 143209ms: Process A6 terminated [Q A0]
time 143215ms: Process A0 started using the CPU for 2392ms burst [Q empty]
time 143240ms: Process A1 completed I/O; added to ready queue [Q A1]
time 145607ms: Process A0 completed a CPU burst; 5 bursts to go [Q A1]
time 145607ms: Process A0 switching out of CPU; blocking on I/O until time 145718ms [Q A1]
time 145613ms: Process A1 started using the CPU for 1080ms burst [Q empty]
time 145718ms: Process A0 completed I/O; added to ready queue [Q A0]
time 146693ms: Process A1 completed a CPU burst; 14 bursts to go [Q A0]
time 146693ms: Process A1 switching out of CPU; blocking on I/O until time 146747ms [Q A0]
time 146699ms: Process A0 started using the CPU for 1976ms burst [Q empty]
time 146747ms: Process A1 completed I/O; added to ready queue [Q A1]
time 148675ms: Process A0 completed a CPU burst; 4 bursts to go [Q A1]
time 148675ms: Process A0 switching out of CPU; blocking on I/O until time 149242ms [Q A1]
time 148681ms: Process A1 started using the CPU for 916ms burst [Q empty]
time 149242ms: Process A0 completed I/O; added to ready queue [Q A0]
time 149597ms: Process A1 completed a CPU burst; 13 bursts to go [Q A0]
time 149597ms: Process A1 switching out of CPU; blocking on I/O until time 149671ms [Q A0]
time 149603ms: Process A0 started using the CPU for 312ms burst [Q empty]
time 149671ms: Process A1 completed I/O; added to ready queue [Q A1]
time 149915ms: Process A0 completed a CPU burst; 3 bursts to go [Q A1]
time 149915ms: Process A0 switching out of CPU; blocking on I/O until time 150463ms [Q A1]
time 149921ms: Process A1 started using the CPU for 3724ms burst [Q empty]
time 150463ms: Process A0 completed I/O; added to ready queue [Q A0]
time 153645ms: Process A1 completed a CPU burst; 12 bursts to go [Q A0]
time 153645ms: Process A1 switching out of CPU; blocking on I/O until time 153759ms [Q A0]
time 153651ms: Process A0 started using the CPU for 1440ms burst [Q empty]
time 153759ms: Process A1 completed I/O; added to ready queue [Q A1]
time 155091ms: Process A0 completed a CPU burst; 2 bursts to go [Q A1]
time 155091ms: Process A0 switching out of CPU; blocking on I/O until time 155230ms [Q A1]
time 155097ms: Process A1 started using the CPU for 1764ms burst [Q empty]
time 155230ms: Process A0 completed I/O; added to ready queue [Q A0]
time 156861ms: Process A1 completed a CPU burst; 11 bursts to go [Q A0]
time 156861ms: Process A1 switching out of CPU; blocking on I/O until time 157146ms [Q A0]
time 156867ms: Process A0 started using the CPU for 3052ms burst [Q empty]
time 157146ms: Process A1 completed I/O; added to ready queue [Q A1]
time 159919ms: Process A0 completed a CPU burst; 1 burst to go [Q A1]
time 159919ms: Process A0 switching out of CPU; blocking on I/O until time 160480ms [Q A1]
time 159925ms: Process A1 started using the CPU for 860ms burst [Q empty]
time 160480ms: Process A0 completed I/O; added to ready queue [Q A0]
time 160785ms: Process A1 completed a CPU burst; 10 bursts to go [Q A0]
time 160785ms: Process A1 switching out of CPU; blocking on I/O until time 160887ms [Q A0]
time 160791ms: Process A0 started using the CPU for 2044ms burst [Q empty]
time 160887ms: Process A1 completed I/O; added to ready queue [Q A1]
time 162835ms: Process A0 terminated [Q A1]
time 162841ms: Process A1 started using the CPU for 2700ms burst [Q empty]
time 165541ms: Process A1 completed a CPU burst; 9 bursts to go [Q empty]
time 165541ms: Process A1 switching out of CPU; blocking on I/O until time 166311ms [Q empty]
time 166311ms: Process A1 completed I/O; added to ready queue [Q A1]
time 166314ms: Process A1 started using the CPU for 100ms burst [Q empty]
time 166414ms: Process A1 completed a CPU burst; 8 bursts to go [Q empty]
time 166414ms: Process A1 switching out of CPU; blocking on I/O until time 167003ms [Q empty]
time 167003ms: Process A1 completed I/O; added to ready queue [Q A1]
time 167006ms: Process A1 started using the CPU for 420ms burst [Q empty]
time 167426ms: Process A1 completed a CPU burst; 7 bursts to go [Q empty]
time 167426ms: Process A1 switching out of CPU; blocking on I/O until time 168138ms [Q empty]
time 168138ms: Process A1 completed I/O; added to ready queue [Q A1]
time 168141ms: Process A1 started using the CPU for 3504ms burst [Q empty]
time 171645ms: Process A1 completed a CPU burst; 6 bursts to go [Q empty]
time 171645ms: Process A1 switching out of CPU; blocking on I/O until time 172319ms [Q empty]
time 172319ms: Process A1 completed I/O; added to ready queue [Q A1]
time 172322ms: Process A1 started using the CPU for 3504ms burst [Q empty]
time 175826ms: Process A1 completed a CPU burst; 5 bursts to go [Q empty]
time 175826ms: Process A1 switching out of CPU; blocking on I/O until time 176163ms [Q empty]
time 176163ms: Process A1 completed I/O; added to ready queue [Q A1]
time 176166ms: Process A1 started using the CPU for 2352ms burst [Q empty]
time 178518ms: Process A1 completed a CPU burst; 4 bursts to go [Q empty]
time 178518ms: Process A1 switching out of CPU; blocking on I/O until time 178772ms [Q empty]
time 178772ms: Process A1 completed I/O; added to ready queue [Q A1]
time 178775ms: Process A1 started using the CPU for 2652ms burst [Q empty]
time 181427ms: Process A1 completed a CPU burst; 3 bursts to go [Q empty]
time 181427ms: Process A1 switching out of CPU; blocking on I/O until time 182198ms [Q empty]
time 182198ms: Process A1 completed I/O; added to ready queue [Q A1]
time 182201ms: Process A1 started using the CPU for 3812ms burst [Q empty]
time 186013ms: Process A1 completed a CPU burst; 2 bursts to go [Q empty]
time 186013ms: Process A1 switching out of CPU; blocking on I/O until time 186543ms [Q empty]
time 186543ms: Process A1 completed I/O; added to ready queue [Q A1]
time 186546ms: Process A1 started using the CPU for 2288ms burst [Q empty]
time 188834ms: Process A1 completed a CPU burst; 1 burst to go [Q empty]
time 188834ms: Process A1 switching out of CPU; blocking on I/O until time 189003ms [Q empty]
time 189003ms: Process A1 completed I/O; added to ready queue [Q A1]
time 189006ms: Process A1 started using the CPU for 388ms burst [Q empty]
time 189394ms: Process A1 terminated [Q empty]
time 189397ms: Simulator ended for SJF [Q empty]

time 0ms: Simulator started for SRT [Q empty]
time 54ms: Process A0 arrived; added to ready queue [Q A0]
time 56ms: Process A1 arrived; added to ready queue [Q A1]
time 57ms: Process A0 started using the CPU for 3764ms burst [Q A1]
time 57ms: Process A1 will preempt A0 [Q A1]
time 63ms: Process A1 started using the CPU for 2828ms burst [Q A0]
time 115ms: Process A5 arrived; preempting A1 [Q A5 A0]
time 121ms: Process A5 started using the CPU for 564ms burst [Q A1 A0]
time 242ms: Process A6 arrived; added to ready queue [Q A6 A1 A0]
time 346ms: Process A4 arrived; added to ready queue [Q A6 A4 A1 A0]
time 357ms: Process A7 arrived; preempting A5 [Q A7 A6 A4 A1 A0]
time 363ms: Process A7 started using the CPU for 297ms burst [Q A5 A6 A4 A1 A0]
time 456ms: Process A2 arrived; added to ready queue [Q A5 A6 A2 A4 A1 A0]
time 660ms: Process A7 completed a CPU burst; 20 bursts to go [Q A5 A6 A2 A4 A1 A0]
time 660ms: Process A7 switching out of CPU; blocking on I/O until time 8527ms [Q A5 A6 A2 A4 A1 A0]
time 666ms: Process A5 started using the CPU for remaining 328ms of 564ms burst [Q A6 A2 A4 A1 A0]
time 758ms: Process A3 arrived; added to ready queue [Q A3 A6 A2 A4 A1 A0]
time 994ms: Process A5 terminated [Q A3 A6 A2 A4 A1 A0]
time 1000ms: Process A3 started using the CPU for 548ms burst [Q A6 A2 A4 A1 A0]
time 1548ms: Process A3 completed a CPU burst; 15 bursts to go [Q A6 A2 A4 A1 A0]
time 1548ms: Process A3 switching out of CPU; blocking on I/O until time 2350ms [Q A6 A2 A4 A1 A0]
time 1554ms: Process A6 started using the CPU for 761ms burst [Q A2 A4 A1 A0]
time 2315ms: Process A6 completed a CPU burst; 26 bursts to go [Q A2 A4 A1 A0]
time 2315ms: Process A6 switching out of CPU; blocking on I/O until time 4582ms [Q A2 A4 A1 A0]
time 2321ms: Process A2 started using the CPU for 1896ms burst [Q A4 A1 A0]
time 2350ms: Process A3 completed I/O; preempting A2 [Q A3 A4 A1 A0]
time 2356ms: Process A3 started using the CPU for 428ms burst [Q A2 A4 A1 A0]
time 2784ms: Process A3 completed a CPU burst; 14 bursts to go [Q A2 A4 A1 A0]
time 2784ms: Process A3 switching out of CPU; blocking on I/O until time 3725ms [Q A2 A4 A1 A0]
time 2790ms: Process A2 started using the CPU for remaining 1867ms of 1896ms burst [Q A4 A1 A0]
time 3725ms: Process A3 completed I/O; added to ready queue [Q A3 A4 A1 A0]
time 4582ms: Process A6 completed I/O; added to ready queue [Q A6 A3 A4 A1 A0]
time 4657ms: Process A2 completed a CPU burst; 8 bursts to go [Q A6 A3 A4 A1 A0]
time 4657ms: Process A2 switching out of CPU; blocking on I/O until time 5278ms [Q A6 A3 A4 A1 A0]
time 4663ms: Process A6 started using the CPU for 903ms burst [Q A3 A4 A1 A0]
time 5278ms: Process A2 completed I/O; added to ready queue [Q A3 A4 A1 A2 A0]
time 5566ms: Process A6 completed a CPU burst; 25 bursts to go [Q A3 A4 A1 A2 A0]
time 5566ms: Process A6 switching out of CPU; blocking on I/O until time 7617ms [Q A3 A4 A1 A2 A0]
time 5572ms: Process A3 started using the CPU for 1432ms burst [Q A4 A1 A2 A0]
time 7004ms: Process A3 completed a CPU burst; 13 bursts to go [Q A4 A1 A2 A0]
time 7004ms: Process A3 switching out of CPU; blocking on I/O until time 7324ms [Q A4 A1 A2 A0]
time 7010ms: Process A4 started using the CPU for 2428ms burst [Q A1 A2 A0]
time 7324ms: Process A3 completed I/O; added to ready queue [Q A1 A2 A0 A3]
time 7617ms: Process A6 completed I/O; preempting A4 [Q A6 A1 A2 A0 A3]
time 7623ms: Process A6 started using the CPU for 303ms burst [Q A4 A1 A2 A0 A3]
time 7926ms: Process A6 completed a CPU burst; 24 bursts to go [Q A4 A1 A2 A0 A3]
time 7926ms: Process A6 switching out of CPU; blocking on I/O until time 15257ms [Q A4 A1 A2 A0 A3]
time 7932ms: Process A4 started using the CPU for remaining 1821ms of 2428ms burst [Q A1 A2 A0 A3]
time 8527ms: Process A7 completed I/O; preempting A4 [Q A7 A1 A2 A0 A3]
time 8533ms: Process A7 started using the CPU for 598ms burst [Q A4 A1 A2 A0 A3]
time 9131ms: Process A7 completed a CPU burst; 19 bursts to go [Q A4 A1 A2 A0 A3]
time 9131ms: Process A7 switching out of CPU; blocking on I/O until time 11590ms [Q A4 A1 A2 A0 A3]
time 9137ms: Process A4 started using the CPU for remaining 1226ms of 2428ms burst [Q A1 A2 A0 A3]
time 10363ms: Process A4 completed a CPU burst; 1 burst to go [Q A1 A2 A0 A3]
time 10363ms: Process A4 switching out of CPU; blocking on I/O until time 10875ms [Q A1 A2 A0 A3]
time 10369ms: Process A1 started using the CPU for remaining 2776ms of 2828ms burst [Q A2 A0 A3]
time 10875ms: Process A4 completed I/O; added to ready queue [Q A4 A2 A0 A3]
time 11590ms: Process A7 completed I/O; preempting A1 [Q A7 A4 A2 A0 A3]
time 11596ms: Process A7 started using the CPU for 721ms burst [Q A1 A4 A2 A0 A3]
time 12317ms: Process A7 completed a CPU burst; 18 bursts to go [Q A1 A4 A2 A0 A3]
time 12317ms: Process A7 switching out of CPU; blocking on I/O until time 15056ms [Q A1 A4 A2 A0 A3]
time 12323ms: Process A1 started using the CPU for remaining 1555ms of 2828ms burst [Q A4 A2 A0 A3]
time 13878ms: Process A1 completed a CPU burst; 30 bursts to go [Q A4 A2 A0 A3]
time 13878ms: Process A1 switching out of CPU; blocking on I/O until time 14203ms [Q A4 A2 A0 A3]
time 13884ms: Process A4 started using the CPU for 2532ms burst [Q A2 A0 A3]
time 14203ms: Process A1 completed I/O; preempting A4 [Q A1 A2 A0 A3]
time 14209ms: Process A1 started using the CPU for 1444ms burst [Q A4 A2 A0 A3]
time 15056ms: Process A7 completed I/O; added to ready queue [Q A7 A4 A2 A0 A3]
time 15257ms: Process A6 completed I/O; preempting A1 [Q A6 A7 A4 A2 A0 A3]
time 15263ms: Process A6 started using the CPU for 194ms burst [Q A1 A7 A4 A2 A0 A3]
time 15457ms: Process A6 completed a CPU burst; 23 bursts to go [Q A1 A7 A4 A2 A0 A3]
time 15457ms: Process A6 switching out of CPU; blocking on I/O until time 22356ms [Q A1 A7 A4 A2 A0 A3]
time 15463ms: Process A1 started using the CPU for remaining 396ms of 1444ms burst [Q A7 A4 A2 A0 A3]
time 15859ms: Process A1 completed a CPU burst; 29 bursts to go [Q A7 A4 A2 A0 A3]
time 15859ms: Process A1 switching out of CPU; blocking on I/O until time 16029ms [Q A7 A4 A2 A0 A3]
time 15865ms: Process A7 started using the CPU for 641ms burst [Q A4 A2 A0 A3]
time 16029ms: Process A1 completed I/O; added to ready queue [Q A4 A1 A2 A0 A3]
time 16506ms: Process A7 completed a CPU burst; 17 bursts to go [Q A4 A1 A2 A0 A3]
time 16506ms: Process A7 switching out of CPU; blocking on I/O until time 18453ms [Q A4 A1 A2 A0 A3]
time 16512ms: Process A4 started using the CPU for remaining 2213ms of 2532ms burst [Q A1 A2 A0 A3]
time 18453ms: Process A7 completed I/O; preempting A4 [Q A7 A1 A2 A0 A3]
time 18459ms: Process A7 started using the CPU for 128ms burst [Q A4 A1 A2 A0 A3]
time 18587ms: Process A7 completed a CPU burst; 16 bursts to go [Q A4 A1 A2 A0 A3]
time 18587ms: Process A7 switching out of CPU; blocking on I/O until time 24758ms [Q A4 A1 A2 A0 A3]
time 18593ms: Process A4 started using the CPU for remaining 272ms of 2532ms burst [Q A1 A2 A0 A3]
time 18865ms: Process A4 terminated [Q A1 A2 A0 A3]
time 18871ms: Process A1 started using the CPU for 2476ms burst [Q A2 A0 A3]
time 21347ms: Process A1 completed a CPU burst; 28 bursts to go [Q A2 A0 A3]
time 21347ms: Process A1 switching out of CPU; blocking on I/O until time 21767ms [Q A2 A0 A3]
time 21353ms: Process A2 started using the CPU for 2940ms burst [Q A0 A3]
time 21767ms: Process A1 completed I/O; preempting A2 [Q A1 A0 A3]
time 21773ms: Process A1 started using the CPU for 2256ms burst [Q A2 A0 A3]
time 22356ms: Process A6 completed I/O; preempting A1 [Q A6 A2 A0 A3]
time 22362ms: Process A6 started using the CPU for 203ms burst [Q A1 A2 A0 A3]
time 22565ms: Process A6 completed a CPU burst; 22 bursts to go [Q A1 A2 A0 A3]
