<<< -- process set (n=16) with 2 CPU-bound processes
<<< -- seed=256; lambda=0.001000; bound=2048

CPU-bound process A0: arrival time 1977ms; 2 CPU bursts:
==> CPU burst 2372ms ==> I/O burst 667ms
==> CPU burst 2652ms

CPU-bound process A1: arrival time 1266ms; 25 CPU bursts:
==> CPU burst 7140ms ==> I/O burst 553ms
==> CPU burst 7828ms ==> I/O burst 136ms
==> CPU burst 5880ms ==> I/O burst 1681ms
==> CPU burst 1912ms ==> I/O burst 230ms
==> CPU burst 200ms ==> I/O burst 430ms
==> CPU burst 7884ms ==> I/O burst 258ms
==> CPU burst 2308ms ==> I/O burst 165ms
==> CPU burst 3492ms ==> I/O burst 1119ms
==> CPU burst 724ms ==> I/O burst 1294ms
==> CPU burst 4068ms ==> I/O burst 610ms
==> CPU burst 3264ms ==> I/O burst 766ms
==> CPU burst 4000ms ==> I/O burst 92ms
==> CPU burst 2332ms ==> I/O burst 1495ms
==> CPU burst 1760ms ==> I/O burst 321ms
==> CPU burst 2612ms ==> I/O burst 738ms
==> CPU burst 140ms ==> I/O burst 544ms
==> CPU burst 1300ms ==> I/O burst 317ms
==> CPU burst 1648ms ==> I/O burst 209ms
==> CPU burst 5856ms ==> I/O burst 716ms
==> CPU burst 4812ms ==> I/O burst 930ms
==> CPU burst 1780ms ==> I/O burst 809ms
==> CPU burst 1984ms ==> I/O burst 516ms
==> CPU burst 3156ms ==> I/O burst 1476ms
==> CPU burst 1040ms ==> I/O burst 2016ms
==> CPU burst 2896ms

I/O-bound process A2: arrival time 1585ms; 5 CPU bursts:
==> CPU burst 527ms ==> I/O burst 3936ms
==> CPU burst 716ms ==> I/O burst 2088ms
==> CPU burst 128ms ==> I/O burst 14080ms
==> CPU burst 226ms ==> I/O burst 3248ms
==> CPU burst 1125ms

I/O-bound process A3: arrival time 386ms; 13 CPU bursts:
==> CPU burst 544ms ==> I/O burst 5496ms
==> CPU burst 1223ms ==> I/O burst 12208ms
==> CPU burst 918ms ==> I/O burst 5680ms
==> CPU burst 165ms ==> I/O burst 3640ms
==> CPU burst 1380ms ==> I/O burst 4384ms
==> CPU burst 556ms ==> I/O burst 14160ms
==> CPU burst 755ms ==> I/O burst 3000ms
==> CPU burst 1219ms ==> I/O burst 1616ms
==> CPU burst 752ms ==> I/O burst 2984ms
==> CPU burst 702ms ==> I/O burst 1256ms
==> CPU burst 54ms ==> I/O burst 800ms
==> CPU burst 40ms ==> I/O burst 752ms
==> CPU burst 887ms

I/O-bound process A4: arrival time 1780ms; 26 CPU bursts:
==> CPU burst 638ms ==> I/O burst 1144ms
==> CPU burst 1550ms ==> I/O burst 8952ms
==> CPU burst 1306ms ==> I/O burst 7328ms
==> CPU burst 1417ms ==> I/O burst 14384ms
==> CPU burst 58ms ==> I/O burst 2432ms
==> CPU burst 233ms ==> I/O burst 4640ms
==> CPU burst 380ms ==> I/O burst 15456ms
==> CPU burst 1081ms ==> I/O burst 14032ms
==> CPU burst 517ms ==> I/O burst 6056ms
==> CPU burst 922ms ==> I/O burst 1112ms
==> CPU burst 721ms ==> I/O burst 1176ms
==> CPU burst 1208ms ==> I/O burst 280ms
==> CPU burst 1559ms ==> I/O burst 1848ms
==> CPU burst 573ms ==> I/O burst 13344ms
==> CPU burst 595ms ==> I/O burst 296ms
==> CPU burst 1138ms ==> I/O burst 7704ms
==> CPU burst 119ms ==> I/O burst 4184ms
==> CPU burst 914ms ==> I/O burst 10392ms
==> CPU burst 14ms ==> I/O burst 10304ms
==> CPU burst 605ms ==> I/O burst 7624ms
==> CPU burst 776ms ==> I/O burst 12528ms
==> CPU burst 107ms ==> I/O burst 2280ms
==> CPU burst 711ms ==> I/O burst 12312ms
==> CPU burst 382ms ==> I/O burst 1568ms
==> CPU burst 1310ms ==> I/O burst 8880ms
==> CPU burst 2006ms

I/O-bound process A5: arrival time 749ms; 32 CPU bursts:
==> CPU burst 638ms ==> I/O burst 4536ms
==> CPU burst 926ms ==> I/O burst 9480ms
==> CPU burst 154ms ==> I/O burst 5624ms
==> CPU burst 735ms ==> I/O burst 6408ms
==> CPU burst 637ms ==> I/O burst 560ms
==> CPU burst 1088ms ==> I/O burst 12488ms
==> CPU burst 2024ms ==> I/O burst 2896ms
==> CPU burst 359ms ==> I/O burst 6136ms
==> CPU burst 1016ms ==> I/O burst 4352ms
==> CPU burst 36ms ==> I/O burst 2840ms
==> CPU burst 133ms ==> I/O burst 2088ms
==> CPU burst 1105ms ==> I/O burst 13472ms
==> CPU burst 1862ms ==> I/O burst 3632ms
==> CPU burst 582ms ==> I/O burst 12760ms
==> CPU burst 512ms ==> I/O burst 4408ms
==> CPU burst 403ms ==> I/O burst 6240ms
==> CPU burst 505ms ==> I/O burst 800ms
==> CPU burst 139ms ==> I/O burst 5048ms
==> CPU burst 914ms ==> I/O burst 3616ms
==> CPU burst 16ms ==> I/O burst 4392ms
==> CPU burst 620ms ==> I/O burst 4752ms
==> CPU burst 757ms ==> I/O burst 3304ms
==> CPU burst 1782ms ==> I/O burst 3848ms
==> CPU burst 190ms ==> I/O burst 1152ms
==> CPU burst 1143ms ==> I/O burst 4424ms
==> CPU burst 1861ms ==> I/O burst 48ms
==> CPU burst 1017ms ==> I/O burst 1720ms
==> CPU burst 2040ms ==> I/O burst 1872ms
==> CPU burst 1184ms ==> I/O burst 8000ms
==> CPU burst 89ms ==> I/O burst 3408ms
==> CPU burst 1365ms ==> I/O burst 7984ms
==> CPU burst 194ms

I/O-bound process A6: arrival time 385ms; 16 CPU bursts:
==> CPU burst 696ms ==> I/O burst 4584ms
==> CPU burst 1015ms ==> I/O burst 9760ms
==> CPU burst 16ms ==> I/O burst 864ms
==> CPU burst 222ms ==> I/O burst 5136ms
==> CPU burst 657ms ==> I/O burst 7112ms
==> CPU burst 421ms ==> I/O burst 9368ms
==> CPU burst 1178ms ==> I/O burst 4600ms
==> CPU burst 540ms ==> I/O burst 2976ms
==> CPU burst 684ms ==> I/O burst 9736ms
==> CPU burst 1616ms ==> I/O burst 4992ms
==> CPU burst 102ms ==> I/O burst 15592ms
==> CPU burst 1321ms ==> I/O burst 5992ms
==> CPU burst 1468ms ==> I/O burst 1072ms
==> CPU burst 333ms ==> I/O burst 1160ms
==> CPU burst 417ms ==> I/O burst 4848ms
==> CPU burst 951ms

I/O-bound process A7: arrival time 1593ms; 7 CPU bursts:
==> CPU burst 56ms ==> I/O burst 5272ms
==> CPU burst 279ms ==> I/O burst 6056ms
==> CPU burst 453ms ==> I/O burst 288ms
==> CPU burst 199ms ==> I/O burst 3064ms
==> CPU burst 84ms ==> I/O burst 1376ms
==> CPU burst 116ms ==> I/O burst 168ms
==> CPU burst 618ms

I/O-bound process A8: arrival time 93ms; 14 CPU bursts:
==> CPU burst 607ms ==> I/O burst 2928ms
==> CPU burst 7ms ==> I/O burst 3392ms
==> CPU burst 506ms ==> I/O burst 13432ms
==> CPU burst 1282ms ==> I/O burst 5488ms
==> CPU burst 495ms ==> I/O burst 8944ms
==> CPU burst 410ms ==> I/O burst 3600ms
==> CPU burst 561ms ==> I/O burst 10560ms
==> CPU burst 38ms ==> I/O burst 5384ms
==> CPU burst 1156ms ==> I/O burst 3704ms
==> CPU burst 158ms ==> I/O burst 2048ms
==> CPU burst 114ms ==> I/O burst 776ms
==> CPU burst 186ms ==> I/O burst 720ms
==> CPU burst 44ms ==> I/O burst 14008ms
==> CPU burst 625ms

I/O-bound process A9: arrival time 322ms; 20 CPU bursts:
==> CPU burst 932ms ==> I/O burst 1192ms
==> CPU burst 1190ms ==> I/O burst 10504ms
==> CPU burst 1299ms ==> I/O burst 200ms
==> CPU burst 351ms ==> I/O burst 1960ms
==> CPU burst 14ms ==> I/O burst 504ms
==> CPU burst 382ms ==> I/O burst 7448ms
==> CPU burst 1135ms ==> I/O burst 12336ms
==> CPU burst 767ms ==> I/O burst 56ms
==> CPU burst 749ms ==> I/O burst 9288ms
==> CPU burst 2023ms ==> I/O burst 1632ms
==> CPU burst 870ms ==> I/O burst 8256ms
==> CPU burst 1290ms ==> I/O burst 13016ms
==> CPU burst 487ms ==> I/O burst 15712ms
==> CPU burst 173ms ==> I/O burst 7616ms
==> CPU burst 780ms ==> I/O burst 3072ms
==> CPU burst 13ms ==> I/O burst 2904ms
==> CPU burst 157ms ==> I/O burst 10624ms
==> CPU burst 952ms ==> I/O burst 240ms
==> CPU burst 840ms ==> I/O burst 2192ms
==> CPU burst 129ms

I/O-bound process B0: arrival time 1197ms; 30 CPU bursts:
==> CPU burst 288ms ==> I/O burst 8288ms
==> CPU burst 93ms ==> I/O burst 14744ms
==> CPU burst 1931ms ==> I/O burst 11448ms
==> CPU burst 924ms ==> I/O burst 14808ms
==> CPU burst 1459ms ==> I/O burst 6512ms
==> CPU burst 1587ms ==> I/O burst 2888ms
==> CPU burst 229ms ==> I/O burst 4208ms
==> CPU burst 1386ms ==> I/O burst 9592ms
==> CPU burst 39ms ==> I/O burst 5760ms
==> CPU burst 848ms ==> I/O burst 1320ms
==> CPU burst 325ms ==> I/O burst 7368ms
==> CPU burst 857ms ==> I/O burst 12416ms
==> CPU burst 1107ms ==> I/O burst 6096ms
==> CPU burst 444ms ==> I/O burst 3208ms
==> CPU burst 401ms ==> I/O burst 3856ms
==> CPU burst 1110ms ==> I/O burst 9320ms
==> CPU burst 809ms ==> I/O burst 1400ms
==> CPU burst 195ms ==> I/O burst 768ms
==> CPU burst 23ms ==> I/O burst 2320ms
==> CPU burst 619ms ==> I/O burst 9408ms
==> CPU burst 316ms ==> I/O burst 672ms
==> CPU burst 1578ms ==> I/O burst 5704ms
==> CPU burst 1178ms ==> I/O burst 2760ms
==> CPU burst 170ms ==> I/O burst 1504ms
==> CPU burst 181ms ==> I/O burst 5000ms
==> CPU burst 884ms ==> I/O burst 4344ms
==> CPU burst 1185ms ==> I/O burst 928ms
==> CPU burst 157ms ==> I/O burst 9408ms
==> CPU burst 191ms ==> I/O burst 928ms
==> CPU burst 941ms

I/O-bound process B1: arrival time 112ms; 28 CPU bursts:
==> CPU burst 1119ms ==> I/O burst 9400ms
==> CPU burst 501ms ==> I/O burst 3496ms
==> CPU burst 1489ms ==> I/O burst 5560ms
==> CPU burst 210ms ==> I/O burst 4168ms
==> CPU burst 8ms ==> I/O burst 12960ms
==> CPU burst 229ms ==> I/O burst 7496ms
==> CPU burst 1357ms ==> I/O burst 1448ms
==> CPU burst 963ms ==> I/O burst 10512ms
==> CPU burst 542ms ==> I/O burst 568ms
==> CPU burst 416ms ==> I/O burst 2840ms
==> CPU burst 211ms ==> I/O burst 5856ms
==> CPU burst 255ms ==> I/O burst 8608ms
==> CPU burst 1565ms ==> I/O burst 5048ms
==> CPU burst 1245ms ==> I/O burst 2472ms
==> CPU burst 1071ms ==> I/O burst 152ms
==> CPU burst 1182ms ==> I/O burst 11248ms
==> CPU burst 20ms ==> I/O burst 6240ms
==> CPU burst 427ms ==> I/O burst 1544ms
==> CPU burst 350ms ==> I/O burst 1192ms
==> CPU burst 319ms ==> I/O burst 1656ms
==> CPU burst 81ms ==> I/O burst 13352ms
==> CPU burst 2ms ==> I/O burst 200ms
==> CPU burst 555ms ==> I/O burst 10352ms
==> CPU burst 443ms ==> I/O burst 12056ms
==> CPU burst 263ms ==> I/O burst 10024ms
==> CPU burst 496ms ==> I/O burst 9328ms
==> CPU burst 71ms ==> I/O burst 10272ms
==> CPU burst 588ms

I/O-bound process B2: arrival time 1572ms; 13 CPU bursts:
==> CPU burst 310ms ==> I/O burst 2448ms
==> CPU burst 1011ms ==> I/O burst 9792ms
==> CPU burst 1671ms ==> I/O burst 16272ms
==> CPU burst 216ms ==> I/O burst 2808ms
==> CPU burst 155ms ==> I/O burst 9312ms
==> CPU burst 139ms ==> I/O burst 4192ms
==> CPU burst 1896ms ==> I/O burst 2352ms
==> CPU burst 322ms ==> I/O burst 2720ms
==> CPU burst 819ms ==> I/O burst 11616ms
==> CPU burst 481ms ==> I/O burst 2128ms
==> CPU burst 451ms ==> I/O burst 2640ms
==> CPU burst 1625ms ==> I/O burst 15648ms
==> CPU burst 724ms

I/O-bound process B3: arrival time 591ms; 5 CPU bursts:
==> CPU burst 944ms ==> I/O burst 14264ms
==> CPU burst 1090ms ==> I/O burst 2040ms
==> CPU burst 363ms ==> I/O burst 64ms
==> CPU burst 1100ms ==> I/O burst 3496ms
==> CPU burst 251ms

I/O-bound process B4: arrival time 561ms; 20 CPU bursts:
==> CPU burst 1575ms ==> I/O burst 424ms
==> CPU burst 1404ms ==> I/O burst 13704ms
==> CPU burst 693ms ==> I/O burst 3088ms
==> CPU burst 279ms ==> I/O burst 2192ms
==> CPU burst 1160ms ==> I/O burst 4264ms
==> CPU burst 593ms ==> I/O burst 1064ms
==> CPU burst 761ms ==> I/O burst 6280ms
==> CPU burst 869ms ==> I/O burst 12824ms
==> CPU burst 233ms ==> I/O burst 4056ms
==> CPU burst 383ms ==> I/O burst 4800ms
==> CPU burst 634ms ==> I/O burst 11256ms
==> CPU burst 3ms ==> I/O burst 6008ms
==> CPU burst 1072ms ==> I/O burst 5952ms
==> CPU burst 795ms ==> I/O burst 2616ms
==> CPU burst 83ms ==> I/O burst 368ms
==> CPU burst 682ms ==> I/O burst 14264ms
==> CPU burst 252ms ==> I/O burst 14144ms
==> CPU burst 85ms ==> I/O burst 5704ms
==> CPU burst 117ms ==> I/O burst 8016ms
==> CPU burst 941ms

I/O-bound process B5: arrival time 877ms; 25 CPU bursts:
==> CPU burst 63ms ==> I/O burst 4104ms
==> CPU burst 204ms ==> I/O burst 13760ms
==> CPU burst 858ms ==> I/O burst 2304ms
==> CPU burst 264ms ==> I/O burst 128ms
==> CPU burst 1666ms ==> I/O burst 5464ms
==> CPU burst 1108ms ==> I/O burst 11824ms
==> CPU burst 110ms ==> I/O burst 6576ms
==> CPU burst 780ms ==> I/O burst 3240ms
==> CPU burst 437ms ==> I/O burst 9384ms
==> CPU burst 303ms ==> I/O burst 15984ms
==> CPU burst 197ms ==> I/O burst 2888ms
==> CPU burst 54ms ==> I/O burst 8096ms
==> CPU burst 296ms ==> I/O burst 6296ms
==> CPU burst 268ms ==> I/O burst 9232ms
==> CPU burst 43ms ==> I/O burst 1000ms
==> CPU burst 1821ms ==> I/O burst 10648ms
==> CPU burst 1628ms ==> I/O burst 4992ms
==> CPU burst 1457ms ==> I/O burst 14568ms
==> CPU burst 53ms ==> I/O burst 56ms
==> CPU burst 650ms ==> I/O burst 12656ms
==> CPU burst 352ms ==> I/O burst 13656ms
==> CPU burst 168ms ==> I/O burst 7312ms
==> CPU burst 654ms ==> I/O burst 6568ms
==> CPU burst 441ms ==> I/O burst 1816ms
==> CPU burst 1195ms

<<< PROJECT SIMULATIONS
<<< -- t_cs=4ms; alpha=0.45; t_slice=32ms
time 0ms: Simulator started for FCFS [Q empty]
time 93ms: Process A8 arrived; added to ready queue [Q A8]
time 95ms: Process A8 started using the CPU for 607ms burst [Q empty]
time 112ms: Process B1 arrived; added to ready queue [Q B1]
time 322ms: Process A9 arrived; added to ready queue [Q B1 A9]
time 385ms: Process A6 arrived; added to ready queue [Q B1 A9 A6]
time 386ms: Process A3 arrived; added to ready queue [Q B1 A9 A6 A3]
time 561ms: Process B4 arrived; added to ready queue [Q B1 A9 A6 A3 B4]
time 591ms: Process B3 arrived; added to ready queue [Q B1 A9 A6 A3 B4 B3]
time 702ms: Process A8 completed a CPU burst; 13 bursts to go [Q B1 A9 A6 A3 B4 B3]
time 702ms: Process A8 switching out of CPU; blocking on I/O until time 3632ms [Q B1 A9 A6 A3 B4 B3]
time 706ms: Process B1 started using the CPU for 1119ms burst [Q A9 A6 A3 B4 B3]
time 749ms: Process A5 arrived; added to ready queue [Q A9 A6 A3 B4 B3 A5]
time 877ms: Process B5 arrived; added to ready queue [Q A9 A6 A3 B4 B3 A5 B5]
time 1197ms: Process B0 arrived; added to ready queue [Q A9 A6 A3 B4 B3 A5 B5 B0]
time 1266ms: Process A1 arrived; added to ready queue [Q A9 A6 A3 B4 B3 A5 B5 B0 A1]
time 1572ms: Process B2 arrived; added to ready queue [Q A9 A6 A3 B4 B3 A5 B5 B0 A1 B2]
time 1585ms: Process A2 arrived; added to ready queue [Q A9 A6 A3 B4 B3 A5 B5 B0 A1 B2 A2]
time 1593ms: Process A7 arrived; added to ready queue [Q A9 A6 A3 B4 B3 A5 B5 B0 A1 B2 A2 A7]
time 1780ms: Process A4 arrived; added to ready queue [Q A9 A6 A3 B4 B3 A5 B5 B0 A1 B2 A2 A7 A4]
time 1825ms: Process B1 completed a CPU burst; 27 bursts to go [Q A9 A6 A3 B4 B3 A5 B5 B0 A1 B2 A2 A7 A4]
time 1825ms: Process B1 switching out of CPU; blocking on I/O until time 11227ms [Q A9 A6 A3 B4 B3 A5 B5 B0 A1 B2 A2 A7 A4]
time 1829ms: Process A9 started using the CPU for 932ms burst [Q A6 A3 B4 B3 A5 B5 B0 A1 B2 A2 A7 A4]
time 1977ms: Process A0 arrived; added to ready queue [Q A6 A3 B4 B3 A5 B5 B0 A1 B2 A2 A7 A4 A0]
time 2761ms: Process A9 completed a CPU burst; 19 bursts to go [Q A6 A3 B4 B3 A5 B5 B0 A1 B2 A2 A7 A4 A0]
time 2761ms: Process A9 switching out of CPU; blocking on I/O until time 3955ms [Q A6 A3 B4 B3 A5 B5 B0 A1 B2 A2 A7 A4 A0]
time 2765ms: Process A6 started using the CPU for 696ms burst [Q A3 B4 B3 A5 B5 B0 A1 B2 A2 A7 A4 A0]
time 3461ms: Process A6 completed a CPU burst; 15 bursts to go [Q A3 B4 B3 A5 B5 B0 A1 B2 A2 A7 A4 A0]
time 3461ms: Process A6 switching out of CPU; blocking on I/O until time 8047ms [Q A3 B4 B3 A5 B5 B0 A1 B2 A2 A7 A4 A0]
time 3465ms: Process A3 started using the CPU for 544ms burst [Q B4 B3 A5 B5 B0 A1 B2 A2 A7 A4 A0]
time 3632ms: Process A8 completed I/O; added to ready queue [Q B4 B3 A5 B5 B0 A1 B2 A2 A7 A4 A0 A8]
time 3955ms: Process A9 completed I/O; added to ready queue [Q B4 B3 A5 B5 B0 A1 B2 A2 A7 A4 A0 A8 A9]
time 4009ms: Process A3 completed a CPU burst; 12 bursts to go [Q B4 B3 A5 B5 B0 A1 B2 A2 A7 A4 A0 A8 A9]
time 4009ms: Process A3 switching out of CPU; blocking on I/O until time 9507ms [Q B4 B3 A5 B5 B0 A1 B2 A2 A7 A4 A0 A8 A9]
time 4013ms: Process B4 started using the CPU for 1575ms burst [Q B3 A5 B5 B0 A1 B2 A2 A7 A4 A0 A8 A9]
time 5588ms: Process B4 completed a CPU burst; 19 bursts to go [Q B3 A5 B5 B0 A1 B2 A2 A7 A4 A0 A8 A9]
time 5588ms: Process B4 switching out of CPU; blocking on I/O until time 6014ms [Q B3 A5 B5 B0 A1 B2 A2 A7 A4 A0 A8 A9]
time 5592ms: Process B3 started using the CPU for 944ms burst [Q A5 B5 B0 A1 B2 A2 A7 A4 A0 A8 A9]
time 6014ms: Process B4 completed I/O; added to ready queue [Q A5 B5 B0 A1 B2 A2 A7 A4 A0 A8 A9 B4]
time 6536ms: Process B3 completed a CPU burst; 4 bursts to go [Q A5 B5 B0 A1 B2 A2 A7 A4 A0 A8 A9 B4]
time 6536ms: Process B3 switching out of CPU; blocking on I/O until time 20802ms [Q A5 B5 B0 A1 B2 A2 A7 A4 A0 A8 A9 B4]
time 6540ms: Process A5 started using the CPU for 638ms burst [Q B5 B0 A1 B2 A2 A7 A4 A0 A8 A9 B4]
time 7178ms: Process A5 completed a CPU burst; 31 bursts to go [Q B5 B0 A1 B2 A2 A7 A4 A0 A8 A9 B4]
time 7178ms: Process A5 switching out of CPU; blocking on I/O until time 11716ms [Q B5 B0 A1 B2 A2 A7 A4 A0 A8 A9 B4]
time 7182ms: Process B5 started using the CPU for 63ms burst [Q B0 A1 B2 A2 A7 A4 A0 A8 A9 B4]
time 7245ms: Process B5 completed a CPU burst; 24 bursts to go [Q B0 A1 B2 A2 A7 A4 A0 A8 A9 B4]
time 7245ms: Process B5 switching out of CPU; blocking on I/O until time 11351ms [Q B0 A1 B2 A2 A7 A4 A0 A8 A9 B4]
time 7249ms: Process B0 started using the CPU for 288ms burst [Q A1 B2 A2 A7 A4 A0 A8 A9 B4]
time 7537ms: Process B0 completed a CPU burst; 29 bursts to go [Q A1 B2 A2 A7 A4 A0 A8 A9 B4]
time 7537ms: Process B0 switching out of CPU; blocking on I/O until time 15827ms [Q A1 B2 A2 A7 A4 A0 A8 A9 B4]
time 7541ms: Process A1 started using the CPU for 7140ms burst [Q B2 A2 A7 A4 A0 A8 A9 B4]
time 8047ms: Process A6 completed I/O; added to ready queue [Q B2 A2 A7 A4 A0 A8 A9 B4 A6]
time 9507ms: Process A3 completed I/O; added to ready queue [Q B2 A2 A7 A4 A0 A8 A9 B4 A6 A3]
time 38260ms: Process A0 terminated [Q A2 B3 A7 A8 B1 A9 A6 A1 A5 B4 A3 B5]
time 70636ms: Process B3 terminated [Q A1 A2 A7 A3 A8 B0]
time 89643ms: Process A2 terminated [Q A5 B4 A3 B2 A1 A7]
time 96337ms: Process A7 terminated [Q A8 A4 A6 B1]
time 154604ms: Process A3 terminated [Q B2 A8 A5 A1]
time 177183ms: Process A8 terminated [Q A5 A6 B0 B1 A1 A4]
time 193633ms: Process B2 terminated [Q A6 B1 B4 A9]
time 203676ms: Process A6 terminated [Q A4 A5 A9]
time 211535ms: Process A1 terminated [Q A9 B5 A5 B0]
time 232234ms: Process A9 terminated [Q empty]
time 245075ms: Process B4 terminated [Q A5 B0]
time 286535ms: Process B0 terminated [Q empty]
time 289549ms: Process A5 terminated [Q empty]
time 292306ms: Process B1 terminated [Q B5]
time 295822ms: Process A4 terminated [Q B5]
time 297021ms: Process B5 terminated [Q empty]
time 297023ms: Simulator ended for FCFS [Q empty]

time 0ms: Simulator started for SJF [Q empty]
time 93ms: Process A8 (tau 1000ms) arrived; added to ready queue [Q A8]
time 95ms: Process A8 (tau 1000ms) started using the CPU for 607ms burst [Q empty]
time 112ms: Process B1 (tau 1000ms) arrived; added to ready queue [Q B1]
time 322ms: Process A9 (tau 1000ms) arrived; added to ready queue [Q A9 B1]
time 385ms: Process A6 (tau 1000ms) arrived; added to ready queue [Q A6 A9 B1]
time 386ms: Process A3 (tau 1000ms) arrived; added to ready queue [Q A3 A6 A9 B1]
time 561ms: Process B4 (tau 1000ms) arrived; added to ready queue [Q A3 A6 A9 B1 B4]
time 591ms: Process B3 (tau 1000ms) arrived; added to ready queue [Q A3 A6 A9 B1 B3 B4]
time 702ms: Process A8 (tau 1000ms) completed a CPU burst; 13 bursts to go [Q A3 A6 A9 B1 B3 B4]
time 702ms: Recalculated tau for process A8: old tau 1000ms ==> new tau 824ms [Q A3 A6 A9 B1 B3 B4]
time 702ms: Process A8 switching out of CPU; blocking on I/O until time 3632ms [Q A3 A6 A9 B1 B3 B4]
time 706ms: Process A3 (tau 1000ms) started using the CPU for 544ms burst [Q A6 A9 B1 B3 B4]
time 749ms: Process A5 (tau 1000ms) arrived; added to ready queue [Q A5 A6 A9 B1 B3 B4]
time 877ms: Process B5 (tau 1000ms) arrived; added to ready queue [Q A5 A6 A9 B1 B3 B4 B5]
time 1197ms: Process B0 (tau 1000ms) arrived; added to ready queue [Q A5 A6 A9 B0 B1 B3 B4 B5]
time 1250ms: Process A3 (tau 1000ms) completed a CPU burst; 12 bursts to go [Q A5 A6 A9 B0 B1 B3 B4 B5]
time 1250ms: Recalculated tau for process A3: old tau 1000ms ==> new tau 795ms [Q A5 A6 A9 B0 B1 B3 B4 B5]
time 1250ms: Process A3 switching out of CPU; blocking on I/O until time 6748ms [Q A5 A6 A9 B0 B1 B3 B4 B5]
time 1254ms: Process A5 (tau 1000ms) started using the CPU for 638ms burst [Q A6 A9 B0 B1 B3 B4 B5]
time 1266ms: Process A1 (tau 1000ms) arrived; added to ready queue [Q A1 A6 A9 B0 B1 B3 B4 B5]
time 1572ms: Process B2 (tau 1000ms) arrived; added to ready queue [Q A1 A6 A9 B0 B1 B2 B3 B4 B5]
time 1585ms: Process A2 (tau 1000ms) arrived; added to ready queue [Q A1 A2 A6 A9 B0 B1 B2 B3 B4 B5]
time 1593ms: Process A7 (tau 1000ms) arrived; added to ready queue [Q A1 A2 A6 A7 A9 B0 B1 B2 B3 B4 B5]
time 1780ms: Process A4 (tau 1000ms) arrived; added to ready queue [Q A1 A2 A4 A6 A7 A9 B0 B1 B2 B3 B4 B5]
time 1892ms: Process A5 (tau 1000ms) completed a CPU burst; 31 bursts to go [Q A1 A2 A4 A6 A7 A9 B0 B1 B2 B3 B4 B5]
time 1892ms: Recalculated tau for process A5: old tau 1000ms ==> new tau 838ms [Q A1 A2 A4 A6 A7 A9 B0 B1 B2 B3 B4 B5]
time 1892ms: Process A5 switching out of CPU; blocking on I/O until time 6430ms [Q A1 A2 A4 A6 A7 A9 B0 B1 B2 B3 B4 B5]
time 1896ms: Process A1 (tau 1000ms) started using the CPU for 7140ms burst [Q A2 A4 A6 A7 A9 B0 B1 B2 B3 B4 B5]
time 1977ms: Process A0 (tau 1000ms) arrived; added to ready queue [Q A0 A2 A4 A6 A7 A9 B0 B1 B2 B3 B4 B5]
time 3632ms: Process A8 (tau 824ms) completed I/O; added to ready queue [Q A8 A0 A2 A4 A6 A7 A9 B0 B1 B2 B3 B4 B5]
time 6430ms: Process A5 (tau 838ms) completed I/O; added to ready queue [Q A8 A5 A0 A2 A4 A6 A7 A9 B0 B1 B2 B3 B4 B5]
time 6748ms: Process A3 (tau 795ms) completed I/O; added to ready queue [Q A3 A8 A5 A0 A2 A4 A6 A7 A9 B0 B1 B2 B3 B4 B5]
time 9036ms: Process A1 (tau 1000ms) completed a CPU burst; 24 bursts to go [Q A3 A8 A5 A0 A2 A4 A6 A7 A9 B0 B1 B2 B3 B4 B5]
time 9036ms: Recalculated tau for process A1: old tau 1000ms ==> new tau 3763ms [Q A3 A8 A5 A0 A2 A4 A6 A7 A9 B0 B1 B2 B3 B4 B5]
time 9036ms: Process A1 switching out of CPU; blocking on I/O until time 9591ms [Q A3 A8 A5 A0 A2 A4 A6 A7 A9 B0 B1 B2 B3 B4 B5]
time 9040ms: Process A3 (tau 795ms) started using the CPU for 1223ms burst [Q A8 A5 A0 A2 A4 A6 A7 A9 B0 B1 B2 B3 B4 B5]
time 9591ms: Process A1 (tau 3763ms) completed I/O; added to ready queue [Q A8 A5 A0 A2 A4 A6 A7 A9 B0 B1 B2 B3 B4 B5 A1]
time 37393ms: Process A7 terminated [Q B5 A5 A9 A8 B4 A0 A1]
time 41543ms: Process A2 terminated [Q A9 A5 B2 A8 A3 B3 A4 B4 A0 A1]
time 62877ms: Process B3 terminated [Q B0 B2 A5 A0 A1]
time 74042ms: Process A0 terminated [Q A8 A4 A3 A5 B4 A1]
time 83735ms: Process A3 terminated [Q B2 B1 B0 B4 B5 A9 A1]
time 105729ms: Process A8 terminated [Q A6 B5 B1 B0 A1]
time 137282ms: Process A6 terminated [Q A5 A4 B1 A1]
time 155747ms: Process B2 terminated [Q B1 A1]
time 184442ms: Process A9 terminated [Q A1]
time 240642ms: Process B4 terminated [Q B0 A5]
time 249948ms: Process A1 terminated [Q A4 B0]
time 252814ms: Process A5 terminated [Q empty]
time 254852ms: Process B1 terminated [Q empty]
time 262152ms: Process A4 terminated [Q empty]
time 269859ms: Process B5 terminated [Q B0]
time 281496ms: Process B0 terminated [Q empty]
time 281498ms: Simulator ended for SJF [Q empty]

time 0ms: Simulator started for SRT [Q empty]
time 93ms: Process A8 (tau 1000ms) arrived; added to ready queue [Q A8]
time 95ms: Process A8 (tau 1000ms) started using the CPU for 607ms burst [Q empty]
time 112ms: Process B1 (tau 1000ms) arrived; added to ready queue [Q B1]
time 322ms: Process A9 (tau 1000ms) arrived; added to ready queue [Q A9 B1]
time 385ms: Process A6 (tau 1000ms) arrived; added to ready queue [Q A6 A9 B1]
time 386ms: Process A3 (tau 1000ms) arrived; added to ready queue [Q A3 A6 A9 B1]
time 561ms: Process B4 (tau 1000ms) arrived; added to ready queue [Q A3 A6 A9 B1 B4]
time 591ms: Process B3 (tau 1000ms) arrived; added to ready queue [Q A3 A6 A9 B1 B3 B4]
time 702ms: Process A8 (tau 1000ms) completed a CPU burst; 13 bursts to go [Q A3 A6 A9 B1 B3 B4]
time 702ms: Recalculated tau for process A8: old tau 1000ms ==> new tau 824ms [Q A3 A6 A9 B1 B3 B4]
time 702ms: Process A8 switching out of CPU; blocking on I/O until time 3632ms [Q A3 A6 A9 B1 B3 B4]
time 706ms: Process A3 (tau 1000ms) started using the CPU for 544ms burst [Q A6 A9 B1 B3 B4]
time 749ms: Process A5 (tau 1000ms) arrived; added to ready queue [Q A5 A6 A9 B1 B3 B4]
time 877ms: Process B5 (tau 1000ms) arrived; added to ready queue [Q A5 A6 A9 B1 B3 B4 B5]
time 1197ms: Process B0 (tau 1000ms) arrived; added to ready queue [Q A5 A6 A9 B0 B1 B3 B4 B5]
time 1250ms: Process A3 (tau 1000ms) completed a CPU burst; 12 bursts to go [Q A5 A6 A9 B0 B1 B3 B4 B5]
time 1250ms: Recalculated tau for process A3: old tau 1000ms ==> new tau 795ms [Q A5 A6 A9 B0 B1 B3 B4 B5]
time 1250ms: Process A3 switching out of CPU; blocking on I/O until time 6748ms [Q A5 A6 A9 B0 B1 B3 B4 B5]
time 1254ms: Process A5 (tau 1000ms) started using the CPU for 638ms burst [Q A6 A9 B0 B1 B3 B4 B5]
time 1266ms: Process A1 (tau 1000ms) arrived; added to ready queue [Q A1 A6 A9 B0 B1 B3 B4 B5]
time 1572ms: Process B2 (tau 1000ms) arrived; added to ready queue [Q A1 A6 A9 B0 B1 B2 B3 B4 B5]
time 1585ms: Process A2 (tau 1000ms) arrived; added to ready queue [Q A1 A2 A6 A9 B0 B1 B2 B3 B4 B5]
time 1593ms: Process A7 (tau 1000ms) arrived; added to ready queue [Q A1 A2 A6 A7 A9 B0 B1 B2 B3 B4 B5]
time 1780ms: Process A4 (tau 1000ms) arrived; added to ready queue [Q A1 A2 A4 A6 A7 A9 B0 B1 B2 B3 B4 B5]
time 1892ms: Process A5 (tau 1000ms) completed a CPU burst; 31 bursts to go [Q A1 A2 A4 A6 A7 A9 B0 B1 B2 B3 B4 B5]
time 1892ms: Recalculated tau for process A5: old tau 1000ms ==> new tau 838ms [Q A1 A2 A4 A6 A7 A9 B0 B1 B2 B3 B4 B5]
time 1892ms: Process A5 switching out of CPU; blocking on I/O until time 6430ms [Q A1 A2 A4 A6 A7 A9 B0 B1 B2 B3 B4 B5]
time 1896ms: Process A1 (tau 1000ms) started using the CPU for 7140ms burst [Q A2 A4 A6 A7 A9 B0 B1 B2 B3 B4 B5]
time 1977ms: Process A0 (tau 1000ms) arrived; added to ready queue [Q A0 A2 A4 A6 A7 A9 B0 B1 B2 B3 B4 B5]
time 3632ms: Process A8 (tau 824ms) completed I/O; added to ready queue [Q A8 A0 A2 A4 A6 A7 A9 B0 B1 B2 B3 B4 B5]
time 6430ms: Process A5 (tau 838ms) completed I/O; added to ready queue [Q A8 A5 A0 A2 A4 A6 A7 A9 B0 B1 B2 B3 B4 B5]
time 6748ms: Process A3 (tau 795ms) completed I/O; added to ready queue [Q A3 A8 A5 A0 A2 A4 A6 A7 A9 B0 B1 B2 B3 B4 B5]
time 9036ms: Process A1 (tau 1000ms) completed a CPU burst; 24 bursts to go [Q A3 A8 A5 A0 A2 A4 A6 A7 A9 B0 B1 B2 B3 B4 B5]
time 9036ms: Recalculated tau for process A1: old tau 1000ms ==> new tau 3763ms [Q A3 A8 A5 A0 A2 A4 A6 A7 A9 B0 B1 B2 B3 B4 B5]
time 9036ms: Process A1 switching out of CPU; blocking on I/O until time 9591ms [Q A3 A8 A5 A0 A2 A4 A6 A7 A9 B0 B1 B2 B3 B4 B5]
time 9040ms: Process A3 (tau 795ms) started using the CPU for 1223ms burst [Q A8 A5 A0 A2 A4 A6 A7 A9 B0 B1 B2 B3 B4 B5]
time 9591ms: Process A1 (tau 3763ms) completed I/O; added to ready queue [Q A8 A5 A0 A2 A4 A6 A7 A9 B0 B1 B2 B3 B4 B5 A1]
time 10263ms: Simulator ended for SRT [Q A8 A5 A0 A2 A4 A6 A7 A9 B0 B1 B2 B3 B4 B5 A1]

time 0ms: Simulator started for RR [Q empty]
time 93ms: Process A8 arrived; added to ready queue [Q A8]
time 95ms: Process A8 started using the CPU for 607ms burst [Q empty]
time 112ms: Process B1 arrived; added to ready queue [Q B1]
time 127ms: Time slice expired; preempting process A8 with 575ms remaining [Q B1]
time 131ms: Process B1 started using the CPU for 1119ms burst [Q A8]
time 163ms: Time slice expired; preempting process B1 with 1087ms remaining [Q A8]
time 167ms: Process A8 started using the CPU for remaining 575ms of 607ms burst [Q B1]
time 199ms: Time slice expired; preempting process A8 with 543ms remaining [Q B1]
time 203ms: Process B1 started using the CPU for remaining 1087ms of 1119ms burst [Q A8]
time 235ms: Time slice expired; preempting process B1 with 1055ms remaining [Q A8]
time 239ms: Process A8 started using the CPU for remaining 543ms of 607ms burst [Q B1]
time 271ms: Time slice expired; preempting process A8 with 511ms remaining [Q B1]
time 275ms: Process B1 started using the CPU for remaining 1055ms of 1119ms burst [Q A8]
time 307ms: Time slice expired; preempting process B1 with 1023ms remaining [Q A8]
time 311ms: Process A8 started using the CPU for remaining 511ms of 607ms burst [Q B1]
time 322ms: Process A9 arrived; added to ready queue [Q B1 A9]
time 343ms: Time slice expired; preempting process A8 with 479ms remaining [Q B1 A9]
time 347ms: Process B1 started using the CPU for remaining 1023ms of 1119ms burst [Q A8 A9]
time 379ms: Time slice expired; preempting process B1 with 991ms remaining [Q A8 A9]
time 383ms: Process A8 started using the CPU for remaining 479ms of 607ms burst [Q B1 A9]
time 385ms: Process A6 arrived; added to ready queue [Q B1 A9 A6]
time 386ms: Process A3 arrived; added to ready queue [Q B1 A9 A6 A3]
time 415ms: Time slice expired; preempting process A8 with 447ms remaining [Q B1 A9 A6 A3]
time 419ms: Process B1 started using the CPU for remaining 991ms of 1119ms burst [Q A8 A9 A6 A3]
time 451ms: Time slice expired; preempting process B1 with 959ms remaining [Q A8 A9 A6 A3]
time 455ms: Process A8 started using the CPU for remaining 447ms of 607ms burst [Q B1 A9 A6 A3]
time 487ms: Time slice expired; preempting process A8 with 415ms remaining [Q B1 A9 A6 A3]
time 491ms: Process B1 started using the CPU for remaining 959ms of 1119ms burst [Q A8 A9 A6 A3]
time 523ms: Time slice expired; preempting process B1 with 927ms remaining [Q A8 A9 A6 A3]
time 527ms: Process A8 started using the CPU for remaining 415ms of 607ms burst [Q B1 A9 A6 A3]
time 559ms: Time slice expired; preempting process A8 with 383ms remaining [Q B1 A9 A6 A3]
time 561ms: Process B4 arrived; added to ready queue [Q A8 A9 A6 A3 B4]
time 563ms: Process B1 started using the CPU for remaining 927ms of 1119ms burst [Q A8 A9 A6 A3 B4]
time 591ms: Process B3 arrived; added to ready queue [Q A8 A9 A6 A3 B4 B3]
time 595ms: Time slice expired; preempting process B1 with 895ms remaining [Q A8 A9 A6 A3 B4 B3]
time 599ms: Process A8 started using the CPU for remaining 383ms of 607ms burst [Q B1 A9 A6 A3 B4 B3]
time 631ms: Time slice expired; preempting process A8 with 351ms remaining [Q B1 A9 A6 A3 B4 B3]
time 635ms: Process B1 started using the CPU for remaining 895ms of 1119ms burst [Q A8 A9 A6 A3 B4 B3]
time 667ms: Time slice expired; preempting process B1 with 863ms remaining [Q A8 A9 A6 A3 B4 B3]
time 671ms: Process A8 started using the CPU for remaining 351ms of 607ms burst [Q B1 A9 A6 A3 B4 B3]
time 703ms: Time slice expired; preempting process A8 with 319ms remaining [Q B1 A9 A6 A3 B4 B3]
time 707ms: Process B1 started using the CPU for remaining 863ms of 1119ms burst [Q A8 A9 A6 A3 B4 B3]
time 739ms: Time slice expired; preempting process B1 with 831ms remaining [Q A8 A9 A6 A3 B4 B3]
time 743ms: Process A8 started using the CPU for remaining 319ms of 607ms burst [Q B1 A9 A6 A3 B4 B3]
time 749ms: Process A5 arrived; added to ready queue [Q B1 A9 A6 A3 B4 B3 A5]
time 775ms: Time slice expired; preempting process A8 with 287ms remaining [Q B1 A9 A6 A3 B4 B3 A5]
time 779ms: Process B1 started using the CPU for remaining 831ms of 1119ms burst [Q A8 A9 A6 A3 B4 B3 A5]
time 811ms: Time slice expired; preempting process B1 with 799ms remaining [Q A8 A9 A6 A3 B4 B3 A5]
time 815ms: Process A8 started using the CPU for remaining 287ms of 607ms burst [Q B1 A9 A6 A3 B4 B3 A5]
time 847ms: Time slice expired; preempting process A8 with 255ms remaining [Q B1 A9 A6 A3 B4 B3 A5]
time 851ms: Process B1 started using the CPU for remaining 799ms of 1119ms burst [Q A8 A9 A6 A3 B4 B3 A5]
time 877ms: Process B5 arrived; added to ready queue [Q A8 A9 A6 A3 B4 B3 A5 B5]
time 883ms: Time slice expired; preempting process B1 with 767ms remaining [Q A8 A9 A6 A3 B4 B3 A5 B5]
time 887ms: Process A8 started using the CPU for remaining 255ms of 607ms burst [Q B1 A9 A6 A3 B4 B3 A5 B5]
time 919ms: Time slice expired; preempting process A8 with 223ms remaining [Q B1 A9 A6 A3 B4 B3 A5 B5]
time 923ms: Process B1 started using the CPU for remaining 767ms of 1119ms burst [Q A8 A9 A6 A3 B4 B3 A5 B5]
time 955ms: Time slice expired; preempting process B1 with 735ms remaining [Q A8 A9 A6 A3 B4 B3 A5 B5]
time 959ms: Process A8 started using the CPU for remaining 223ms of 607ms burst [Q B1 A9 A6 A3 B4 B3 A5 B5]
time 991ms: Time slice expired; preempting process A8 with 191ms remaining [Q B1 A9 A6 A3 B4 B3 A5 B5]
time 995ms: Process B1 started using the CPU for remaining 735ms of 1119ms burst [Q A8 A9 A6 A3 B4 B3 A5 B5]
time 1027ms: Time slice expired; preempting process B1 with 703ms remaining [Q A8 A9 A6 A3 B4 B3 A5 B5]
time 1031ms: Process A8 started using the CPU for remaining 191ms of 607ms burst [Q B1 A9 A6 A3 B4 B3 A5 B5]
time 1063ms: Time slice expired; preempting process A8 with 159ms remaining [Q B1 A9 A6 A3 B4 B3 A5 B5]
time 1067ms: Process B1 started using the CPU for remaining 703ms of 1119ms burst [Q A8 A9 A6 A3 B4 B3 A5 B5]
time 1099ms: Time slice expired; preempting process B1 with 671ms remaining [Q A8 A9 A6 A3 B4 B3 A5 B5]
time 1103ms: Process A8 started using the CPU for remaining 159ms of 607ms burst [Q B1 A9 A6 A3 B4 B3 A5 B5]
time 1135ms: Time slice expired; preempting process A8 with 127ms remaining [Q B1 A9 A6 A3 B4 B3 A5 B5]
time 1139ms: Process B1 started using the CPU for remaining 671ms of 1119ms burst [Q A8 A9 A6 A3 B4 B3 A5 B5]
time 1171ms: Time slice expired; preempting process B1 with 639ms remaining [Q A8 A9 A6 A3 B4 B3 A5 B5]
time 1175ms: Process A8 started using the CPU for remaining 127ms of 607ms burst [Q B1 A9 A6 A3 B4 B3 A5 B5]
time 1197ms: Process B0 arrived; added to ready queue [Q B1 A9 A6 A3 B4 B3 A5 B5 B0]
time 1207ms: Time slice expired; preempting process A8 with 95ms remaining [Q B1 A9 A6 A3 B4 B3 A5 B5 B0]
time 1211ms: Process B1 started using the CPU for remaining 639ms of 1119ms burst [Q A8 A9 A6 A3 B4 B3 A5 B5 B0]
time 1243ms: Time slice expired; preempting process B1 with 607ms remaining [Q A8 A9 A6 A3 B4 B3 A5 B5 B0]
time 1247ms: Process A8 started using the CPU for remaining 95ms of 607ms burst [Q B1 A9 A6 A3 B4 B3 A5 B5 B0]
time 1266ms: Process A1 arrived; added to ready queue [Q B1 A9 A6 A3 B4 B3 A5 B5 B0 A1]
time 1279ms: Time slice expired; preempting process A8 with 63ms remaining [Q B1 A9 A6 A3 B4 B3 A5 B5 B0 A1]
time 1283ms: Process B1 started using the CPU for remaining 607ms of 1119ms burst [Q A8 A9 A6 A3 B4 B3 A5 B5 B0 A1]
time 1315ms: Time slice expired; preempting process B1 with 575ms remaining [Q A8 A9 A6 A3 B4 B3 A5 B5 B0 A1]
time 1319ms: Process A8 started using the CPU for remaining 63ms of 607ms burst [Q B1 A9 A6 A3 B4 B3 A5 B5 B0 A1]
time 1351ms: Time slice expired; preempting process A8 with 31ms remaining [Q B1 A9 A6 A3 B4 B3 A5 B5 B0 A1]
time 1355ms: Process B1 started using the CPU for remaining 575ms of 1119ms burst [Q A8 A9 A6 A3 B4 B3 A5 B5 B0 A1]
time 1387ms: Time slice expired; preempting process B1 with 543ms remaining [Q A8 A9 A6 A3 B4 B3 A5 B5 B0 A1]
time 1391ms: Process A8 started using the CPU for remaining 31ms of 607ms burst [Q B1 A9 A6 A3 B4 B3 A5 B5 B0 A1]
time 1422ms: Process A8 completed a CPU burst; 13 bursts to go [Q B1 A9 A6 A3 B4 B3 A5 B5 B0 A1]
time 1422ms: Process A8 switching out of CPU; blocking on I/O until time 4352ms [Q B1 A9 A6 A3 B4 B3 A5 B5 B0 A1]
time 1426ms: Process B1 started using the CPU for remaining 543ms of 1119ms burst [Q A9 A6 A3 B4 B3 A5 B5 B0 A1]
time 1458ms: Time slice expired; preempting process B1 with 511ms remaining [Q A9 A6 A3 B4 B3 A5 B5 B0 A1]
time 1462ms: Process A9 started using the CPU for 932ms burst [Q B1 A6 A3 B4 B3 A5 B5 B0 A1]
time 1494ms: Time slice expired; preempting process A9 with 900ms remaining [Q B1 A6 A3 B4 B3 A5 B5 B0 A1]
time 1498ms: Process B1 started using the CPU for remaining 511ms of 1119ms burst [Q A9 A6 A3 B4 B3 A5 B5 B0 A1]
time 1530ms: Time slice expired; preempting process B1 with 479ms remaining [Q A9 A6 A3 B4 B3 A5 B5 B0 A1]
time 1534ms: Process A9 started using the CPU for remaining 900ms of 932ms burst [Q B1 A6 A3 B4 B3 A5 B5 B0 A1]
time 1566ms: Time slice expired; preempting process A9 with 868ms remaining [Q B1 A6 A3 B4 B3 A5 B5 B0 A1]
time 1570ms: Process B1 started using the CPU for remaining 479ms of 1119ms burst [Q A9 A6 A3 B4 B3 A5 B5 B0 A1]
time 1572ms: Process B2 arrived; added to ready queue [Q A9 A6 A3 B4 B3 A5 B5 B0 A1 B2]
time 1585ms: Process A2 arrived; added to ready queue [Q A9 A6 A3 B4 B3 A5 B5 B0 A1 B2 A2]
time 1593ms: Process A7 arrived; added to ready queue [Q A9 A6 A3 B4 B3 A5 B5 B0 A1 B2 A2 A7]
time 1602ms: Time slice expired; preempting process B1 with 447ms remaining [Q A9 A6 A3 B4 B3 A5 B5 B0 A1 B2 A2 A7]
time 1606ms: Process A9 started using the CPU for remaining 868ms of 932ms burst [Q B1 A6 A3 B4 B3 A5 B5 B0 A1 B2 A2 A7]
time 1638ms: Time slice expired; preempting process A9 with 836ms remaining [Q B1 A6 A3 B4 B3 A5 B5 B0 A1 B2 A2 A7]
time 1642ms: Process B1 started using the CPU for remaining 447ms of 1119ms burst [Q A9 A6 A3 B4 B3 A5 B5 B0 A1 B2 A2 A7]
time 1674ms: Time slice expired; preempting process B1 with 415ms remaining [Q A9 A6 A3 B4 B3 A5 B5 B0 A1 B2 A2 A7]
time 1678ms: Process A9 started using the CPU for remaining 836ms of 932ms burst [Q B1 A6 A3 B4 B3 A5 B5 B0 A1 B2 A2 A7]
time 1710ms: Time slice expired; preempting process A9 with 804ms remaining [Q B1 A6 A3 B4 B3 A5 B5 B0 A1 B2 A2 A7]
time 1714ms: Process B1 started using the CPU for remaining 415ms of 1119ms burst [Q A9 A6 A3 B4 B3 A5 B5 B0 A1 B2 A2 A7]
time 1746ms: Time slice expired; preempting process B1 with 383ms remaining [Q A9 A6 A3 B4 B3 A5 B5 B0 A1 B2 A2 A7]
time 1750ms: Process A9 started using the CPU for remaining 804ms of 932ms burst [Q B1 A6 A3 B4 B3 A5 B5 B0 A1 B2 A2 A7]
time 1780ms: Process A4 arrived; added to ready queue [Q B1 A6 A3 B4 B3 A5 B5 B0 A1 B2 A2 A7 A4]
time 1782ms: Time slice expired; preempting process A9 with 772ms remaining [Q B1 A6 A3 B4 B3 A5 B5 B0 A1 B2 A2 A7 A4]
time 1786ms: Process B1 started using the CPU for remaining 383ms of 1119ms burst [Q A9 A6 A3 B4 B3 A5 B5 B0 A1 B2 A2 A7 A4]
time 1818ms: Time slice expired; preempting process B1 with 351ms remaining [Q A9 A6 A3 B4 B3 A5 B5 B0 A1 B2 A2 A7 A4]
time 1822ms: Process A9 started using the CPU for remaining 772ms of 932ms burst [Q B1 A6 A3 B4 B3 A5 B5 B0 A1 B2 A2 A7 A4]
time 1854ms: Time slice expired; preempting process A9 with 740ms remaining [Q B1 A6 A3 B4 B3 A5 B5 B0 A1 B2 A2 A7 A4]
time 1858ms: Process B1 started using the CPU for remaining 351ms of 1119ms burst [Q A9 A6 A3 B4 B3 A5 B5 B0 A1 B2 A2 A7 A4]
time 1890ms: Time slice expired; preempting process B1 with 319ms remaining [Q A9 A6 A3 B4 B3 A5 B5 B0 A1 B2 A2 A7 A4]
time 1894ms: Process A9 started using the CPU for remaining 740ms of 932ms burst [Q B1 A6 A3 B4 B3 A5 B5 B0 A1 B2 A2 A7 A4]
time 1926ms: Time slice expired; preempting process A9 with 708ms remaining [Q B1 A6 A3 B4 B3 A5 B5 B0 A1 B2 A2 A7 A4]
time 1930ms: Process B1 started using the CPU for remaining 319ms of 1119ms burst [Q A9 A6 A3 B4 B3 A5 B5 B0 A1 B2 A2 A7 A4]
time 1962ms: Time slice expired; preempting process B1 with 287ms remaining [Q A9 A6 A3 B4 B3 A5 B5 B0 A1 B2 A2 A7 A4]
time 1966ms: Process A9 started using the CPU for remaining 708ms of 932ms burst [Q B1 A6 A3 B4 B3 A5 B5 B0 A1 B2 A2 A7 A4]
time 1977ms: Process A0 arrived; added to ready queue [Q B1 A6 A3 B4 B3 A5 B5 B0 A1 B2 A2 A7 A4 A0]
time 1998ms: Time slice expired; preempting process A9 with 676ms remaining [Q B1 A6 A3 B4 B3 A5 B5 B0 A1 B2 A2 A7 A4 A0]
time 2002ms: Process B1 started using the CPU for remaining 287ms of 1119ms burst [Q A9 A6 A3 B4 B3 A5 B5 B0 A1 B2 A2 A7 A4 A0]
time 2034ms: Time slice expired; preempting process B1 with 255ms remaining [Q A9 A6 A3 B4 B3 A5 B5 B0 A1 B2 A2 A7 A4 A0]
time 2038ms: Process A9 started using the CPU for remaining 676ms of 932ms burst [Q B1 A6 A3 B4 B3 A5 B5 B0 A1 B2 A2 A7 A4 A0]
time 2070ms: Time slice expired; preempting process A9 with 644ms remaining [Q B1 A6 A3 B4 B3 A5 B5 B0 A1 B2 A2 A7 A4 A0]
time 2074ms: Process B1 started using the CPU for remaining 255ms of 1119ms burst [Q A9 A6 A3 B4 B3 A5 B5 B0 A1 B2 A2 A7 A4 A0]
time 2106ms: Time slice expired; preempting process B1 with 223ms remaining [Q A9 A6 A3 B4 B3 A5 B5 B0 A1 B2 A2 A7 A4 A0]
time 2110ms: Process A9 started using the CPU for remaining 644ms of 932ms burst [Q B1 A6 A3 B4 B3 A5 B5 B0 A1 B2 A2 A7 A4 A0]
time 2142ms: Time slice expired; preempting process A9 with 612ms remaining [Q B1 A6 A3 B4 B3 A5 B5 B0 A1 B2 A2 A7 A4 A0]
time 2146ms: Process B1 started using the CPU for remaining 223ms of 1119ms burst [Q A9 A6 A3 B4 B3 A5 B5 B0 A1 B2 A2 A7 A4 A0]
time 2178ms: Time slice expired; preempting process B1 with 191ms remaining [Q A9 A6 A3 B4 B3 A5 B5 B0 A1 B2 A2 A7 A4 A0]
time 2182ms: Process A9 started using the CPU for remaining 612ms of 932ms burst [Q B1 A6 A3 B4 B3 A5 B5 B0 A1 B2 A2 A7 A4 A0]
time 2214ms: Time slice expired; preempting process A9 with 580ms remaining [Q B1 A6 A3 B4 B3 A5 B5 B0 A1 B2 A2 A7 A4 A0]
time 2218ms: Process B1 started using the CPU for remaining 191ms of 1119ms burst [Q A9 A6 A3 B4 B3 A5 B5 B0 A1 B2 A2 A7 A4 A0]
time 2250ms: Time slice expired; preempting process B1 with 159ms remaining [Q A9 A6 A3 B4 B3 A5 B5 B0 A1 B2 A2 A7 A4 A0]
time 2254ms: Process A9 started using the CPU for remaining 580ms of 932ms burst [Q B1 A6 A3 B4 B3 A5 B5 B0 A1 B2 A2 A7 A4 A0]
time 2286ms: Time slice expired; preempting process A9 with 548ms remaining [Q B1 A6 A3 B4 B3 A5 B5 B0 A1 B2 A2 A7 A4 A0]
time 2290ms: Process B1 started using the CPU for remaining 159ms of 1119ms burst [Q A9 A6 A3 B4 B3 A5 B5 B0 A1 B2 A2 A7 A4 A0]
time 2322ms: Time slice expired; preempting process B1 with 127ms remaining [Q A9 A6 A3 B4 B3 A5 B5 B0 A1 B2 A2 A7 A4 A0]
time 2326ms: Process A9 started using the CPU for remaining 548ms of 932ms burst [Q B1 A6 A3 B4 B3 A5 B5 B0 A1 B2 A2 A7 A4 A0]
time 2358ms: Time slice expired; preempting process A9 with 516ms remaining [Q B1 A6 A3 B4 B3 A5 B5 B0 A1 B2 A2 A7 A4 A0]
time 2362ms: Process B1 started using the CPU for remaining 127ms of 1119ms burst [Q A9 A6 A3 B4 B3 A5 B5 B0 A1 B2 A2 A7 A4 A0]
time 2394ms: Time slice expired; preempting process B1 with 95ms remaining [Q A9 A6 A3 B4 B3 A5 B5 B0 A1 B2 A2 A7 A4 A0]
time 2398ms: Process A9 started using the CPU for remaining 516ms of 932ms burst [Q B1 A6 A3 B4 B3 A5 B5 B0 A1 B2 A2 A7 A4 A0]
time 2430ms: Time slice expired; preempting process A9 with 484ms remaining [Q B1 A6 A3 B4 B3 A5 B5 B0 A1 B2 A2 A7 A4 A0]
time 2434ms: Process B1 started using the CPU for remaining 95ms of 1119ms burst [Q A9 A6 A3 B4 B3 A5 B5 B0 A1 B2 A2 A7 A4 A0]
time 2466ms: Time slice expired; preempting process B1 with 63ms remaining [Q A9 A6 A3 B4 B3 A5 B5 B0 A1 B2 A2 A7 A4 A0]
time 2470ms: Process A9 started using the CPU for remaining 484ms of 932ms burst [Q B1 A6 A3 B4 B3 A5 B5 B0 A1 B2 A2 A7 A4 A0]
time 2502ms: Time slice expired; preempting process A9 with 452ms remaining [Q B1 A6 A3 B4 B3 A5 B5 B0 A1 B2 A2 A7 A4 A0]
time 2506ms: Process B1 started using the CPU for remaining 63ms of 1119ms burst [Q A9 A6 A3 B4 B3 A5 B5 B0 A1 B2 A2 A7 A4 A0]
time 2538ms: Time slice expired; preempting process B1 with 31ms remaining [Q A9 A6 A3 B4 B3 A5 B5 B0 A1 B2 A2 A7 A4 A0]
time 2542ms: Process A9 started using the CPU for remaining 452ms of 932ms burst [Q B1 A6 A3 B4 B3 A5 B5 B0 A1 B2 A2 A7 A4 A0]
time 2574ms: Time slice expired; preempting process A9 with 420ms remaining [Q B1 A6 A3 B4 B3 A5 B5 B0 A1 B2 A2 A7 A4 A0]
time 2578ms: Process B1 started using the CPU for remaining 31ms of 1119ms burst [Q A9 A6 A3 B4 B3 A5 B5 B0 A1 B2 A2 A7 A4 A0]
time 2609ms: Process B1 completed a CPU burst; 27 bursts to go [Q A9 A6 A3 B4 B3 A5 B5 B0 A1 B2 A2 A7 A4 A0]
time 2609ms: Process B1 switching out of CPU; blocking on I/O until time 12011ms [Q A9 A6 A3 B4 B3 A5 B5 B0 A1 B2 A2 A7 A4 A0]
time 2613ms: Process A9 started using the CPU for remaining 420ms of 932ms burst [Q A6 A3 B4 B3 A5 B5 B0 A1 B2 A2 A7 A4 A0]
time 2645ms: Time slice expired; preempting process A9 with 388ms remaining [Q A6 A3 B4 B3 A5 B5 B0 A1 B2 A2 A7 A4 A0]
time 2649ms: Process A6 started using the CPU for 696ms burst [Q A9 A3 B4 B3 A5 B5 B0 A1 B2 A2 A7 A4 A0]
time 2681ms: Time slice expired; preempting process A6 with 664ms remaining [Q A9 A3 B4 B3 A5 B5 B0 A1 B2 A2 A7 A4 A0]
time 2685ms: Process A9 started using the CPU for remaining 388ms of 932ms burst [Q A6 A3 B4 B3 A5 B5 B0 A1 B2 A2 A7 A4 A0]
time 2717ms: Time slice expired; preempting process A9 with 356ms remaining [Q A6 A3 B4 B3 A5 B5 B0 A1 B2 A2 A7 A4 A0]
time 2721ms: Process A6 started using the CPU for remaining 664ms of 696ms burst [Q A9 A3 B4 B3 A5 B5 B0 A1 B2 A2 A7 A4 A0]
time 2753ms: Time slice expired; preempting process A6 with 632ms remaining [Q A9 A3 B4 B3 A5 B5 B0 A1 B2 A2 A7 A4 A0]
time 2757ms: Process A9 started using the CPU for remaining 356ms of 932ms burst [Q A6 A3 B4 B3 A5 B5 B0 A1 B2 A2 A7 A4 A0]
time 2789ms: Time slice expired; preempting process A9 with 324ms remaining [Q A6 A3 B4 B3 A5 B5 B0 A1 B2 A2 A7 A4 A0]
time 2793ms: Process A6 started using the CPU for remaining 632ms of 696ms burst [Q A9 A3 B4 B3 A5 B5 B0 A1 B2 A2 A7 A4 A0]
time 2825ms: Time slice expired; preempting process A6 with 600ms remaining [Q A9 A3 B4 B3 A5 B5 B0 A1 B2 A2 A7 A4 A0]
time 2829ms: Process A9 started using the CPU for remaining 324ms of 932ms burst [Q A6 A3 B4 B3 A5 B5 B0 A1 B2 A2 A7 A4 A0]
time 2861ms: Time slice expired; preempting process A9 with 292ms remaining [Q A6 A3 B4 B3 A5 B5 B0 A1 B2 A2 A7 A4 A0]
time 2865ms: Process A6 started using the CPU for remaining 600ms of 696ms burst [Q A9 A3 B4 B3 A5 B5 B0 A1 B2 A2 A7 A4 A0]
time 2897ms: Time slice expired; preempting process A6 with 568ms remaining [Q A9 A3 B4 B3 A5 B5 B0 A1 B2 A2 A7 A4 A0]
time 2901ms: Process A9 started using the CPU for remaining 292ms of 932ms burst [Q A6 A3 B4 B3 A5 B5 B0 A1 B2 A2 A7 A4 A0]
time 2933ms: Time slice expired; preempting process A9 with 260ms remaining [Q A6 A3 B4 B3 A5 B5 B0 A1 B2 A2 A7 A4 A0]
time 2937ms: Process A6 started using the CPU for remaining 568ms of 696ms burst [Q A9 A3 B4 B3 A5 B5 B0 A1 B2 A2 A7 A4 A0]
time 2969ms: Time slice expired; preempting process A6 with 536ms remaining [Q A9 A3 B4 B3 A5 B5 B0 A1 B2 A2 A7 A4 A0]
time 2973ms: Process A9 started using the CPU for remaining 260ms of 932ms burst [Q A6 A3 B4 B3 A5 B5 B0 A1 B2 A2 A7 A4 A0]
time 3005ms: Time slice expired; preempting process A9 with 228ms remaining [Q A6 A3 B4 B3 A5 B5 B0 A1 B2 A2 A7 A4 A0]
time 3009ms: Process A6 started using the CPU for remaining 536ms of 696ms burst [Q A9 A3 B4 B3 A5 B5 B0 A1 B2 A2 A7 A4 A0]
time 3041ms: Time slice expired; preempting process A6 with 504ms remaining [Q A9 A3 B4 B3 A5 B5 B0 A1 B2 A2 A7 A4 A0]
time 3045ms: Process A9 started using the CPU for remaining 228ms of 932ms burst [Q A6 A3 B4 B3 A5 B5 B0 A1 B2 A2 A7 A4 A0]
time 3077ms: Time slice expired; preempting process A9 with 196ms remaining [Q A6 A3 B4 B3 A5 B5 B0 A1 B2 A2 A7 A4 A0]
time 3081ms: Process A6 started using the CPU for remaining 504ms of 696ms burst [Q A9 A3 B4 B3 A5 B5 B0 A1 B2 A2 A7 A4 A0]
time 3113ms: Time slice expired; preempting process A6 with 472ms remaining [Q A9 A3 B4 B3 A5 B5 B0 A1 B2 A2 A7 A4 A0]
time 3117ms: Process A9 started using the CPU for remaining 196ms of 932ms burst [Q A6 A3 B4 B3 A5 B5 B0 A1 B2 A2 A7 A4 A0]
time 3149ms: Time slice expired; preempting process A9 with 164ms remaining [Q A6 A3 B4 B3 A5 B5 B0 A1 B2 A2 A7 A4 A0]
time 3153ms: Process A6 started using the CPU for remaining 472ms of 696ms burst [Q A9 A3 B4 B3 A5 B5 B0 A1 B2 A2 A7 A4 A0]
time 3185ms: Time slice expired; preempting process A6 with 440ms remaining [Q A9 A3 B4 B3 A5 B5 B0 A1 B2 A2 A7 A4 A0]
time 3189ms: Process A9 started using the CPU for remaining 164ms of 932ms burst [Q A6 A3 B4 B3 A5 B5 B0 A1 B2 A2 A7 A4 A0]
time 3221ms: Time slice expired; preempting process A9 with 132ms remaining [Q A6 A3 B4 B3 A5 B5 B0 A1 B2 A2 A7 A4 A0]
time 3225ms: Process A6 started using the CPU for remaining 440ms of 696ms burst [Q A9 A3 B4 B3 A5 B5 B0 A1 B2 A2 A7 A4 A0]
time 3257ms: Time slice expired; preempting process A6 with 408ms remaining [Q A9 A3 B4 B3 A5 B5 B0 A1 B2 A2 A7 A4 A0]
time 3261ms: Process A9 started using the CPU for remaining 132ms of 932ms burst [Q A6 A3 B4 B3 A5 B5 B0 A1 B2 A2 A7 A4 A0]
time 3293ms: Time slice expired; preempting process A9 with 100ms remaining [Q A6 A3 B4 B3 A5 B5 B0 A1 B2 A2 A7 A4 A0]
time 3297ms: Process A6 started using the CPU for remaining 408ms of 696ms burst [Q A9 A3 B4 B3 A5 B5 B0 A1 B2 A2 A7 A4 A0]
time 3329ms: Time slice expired; preempting process A6 with 376ms remaining [Q A9 A3 B4 B3 A5 B5 B0 A1 B2 A2 A7 A4 A0]
time 3333ms: Process A9 started using the CPU for remaining 100ms of 932ms burst [Q A6 A3 B4 B3 A5 B5 B0 A1 B2 A2 A7 A4 A0]
time 3365ms: Time slice expired; preempting process A9 with 68ms remaining [Q A6 A3 B4 B3 A5 B5 B0 A1 B2 A2 A7 A4 A0]
time 3369ms: Process A6 started using the CPU for remaining 376ms of 696ms burst [Q A9 A3 B4 B3 A5 B5 B0 A1 B2 A2 A7 A4 A0]
time 3401ms: Time slice expired; preempting process A6 with 344ms remaining [Q A9 A3 B4 B3 A5 B5 B0 A1 B2 A2 A7 A4 A0]
time 3405ms: Process A9 started using the CPU for remaining 68ms of 932ms burst [Q A6 A3 B4 B3 A5 B5 B0 A1 B2 A2 A7 A4 A0]
time 3437ms: Time slice expired; preempting process A9 with 36ms remaining [Q A6 A3 B4 B3 A5 B5 B0 A1 B2 A2 A7 A4 A0]
time 3441ms: Process A6 started using the CPU for remaining 344ms of 696ms burst [Q A9 A3 B4 B3 A5 B5 B0 A1 B2 A2 A7 A4 A0]
time 3473ms: Time slice expired; preempting process A6 with 312ms remaining [Q A9 A3 B4 B3 A5 B5 B0 A1 B2 A2 A7 A4 A0]
time 3477ms: Process A9 started using the CPU for remaining 36ms of 932ms burst [Q A6 A3 B4 B3 A5 B5 B0 A1 B2 A2 A7 A4 A0]
time 3509ms: Time slice expired; preempting process A9 with 4ms remaining [Q A6 A3 B4 B3 A5 B5 B0 A1 B2 A2 A7 A4 A0]
time 3513ms: Process A6 started using the CPU for remaining 312ms of 696ms burst [Q A9 A3 B4 B3 A5 B5 B0 A1 B2 A2 A7 A4 A0]
time 3545ms: Time slice expired; preempting process A6 with 280ms remaining [Q A9 A3 B4 B3 A5 B5 B0 A1 B2 A2 A7 A4 A0]
time 3549ms: Process A9 started using the CPU for remaining 4ms of 932ms burst [Q A6 A3 B4 B3 A5 B5 B0 A1 B2 A2 A7 A4 A0]
time 3553ms: Process A9 completed a CPU burst; 19 bursts to go [Q A6 A3 B4 B3 A5 B5 B0 A1 B2 A2 A7 A4 A0]
time 3553ms: Process A9 switching out of CPU; blocking on I/O until time 4747ms [Q A6 A3 B4 B3 A5 B5 B0 A1 B2 A2 A7 A4 A0]
time 3557ms: Process A6 started using the CPU for remaining 280ms of 696ms burst [Q A3 B4 B3 A5 B5 B0 A1 B2 A2 A7 A4 A0]
time 3589ms: Time slice expired; preempting process A6 with 248ms remaining [Q A3 B4 B3 A5 B5 B0 A1 B2 A2 A7 A4 A0]
time 3593ms: Process A3 started using the CPU for 544ms burst [Q A6 B4 B3 A5 B5 B0 A1 B2 A2 A7 A4 A0]
time 3625ms: Time slice expired; preempting process A3 with 512ms remaining [Q A6 B4 B3 A5 B5 B0 A1 B2 A2 A7 A4 A0]
time 3629ms: Process A6 started using the CPU for remaining 248ms of 696ms burst [Q A3 B4 B3 A5 B5 B0 A1 B2 A2 A7 A4 A0]
time 3661ms: Time slice expired; preempting process A6 with 216ms remaining [Q A3 B4 B3 A5 B5 B0 A1 B2 A2 A7 A4 A0]
time 3665ms: Process A3 started using the CPU for remaining 512ms of 544ms burst [Q A6 B4 B3 A5 B5 B0 A1 B2 A2 A7 A4 A0]
time 3697ms: Time slice expired; preempting process A3 with 480ms remaining [Q A6 B4 B3 A5 B5 B0 A1 B2 A2 A7 A4 A0]
time 3701ms: Process A6 started using the CPU for remaining 216ms of 696ms burst [Q A3 B4 B3 A5 B5 B0 A1 B2 A2 A7 A4 A0]
time 3733ms: Time slice expired; preempting process A6 with 184ms remaining [Q A3 B4 B3 A5 B5 B0 A1 B2 A2 A7 A4 A0]
time 3737ms: Process A3 started using the CPU for remaining 480ms of 544ms burst [Q A6 B4 B3 A5 B5 B0 A1 B2 A2 A7 A4 A0]
time 3769ms: Time slice expired; preempting process A3 with 448ms remaining [Q A6 B4 B3 A5 B5 B0 A1 B2 A2 A7 A4 A0]
time 3773ms: Process A6 started using the CPU for remaining 184ms of 696ms burst [Q A3 B4 B3 A5 B5 B0 A1 B2 A2 A7 A4 A0]
time 3805ms: Time slice expired; preempting process A6 with 152ms remaining [Q A3 B4 B3 A5 B5 B0 A1 B2 A2 A7 A4 A0]
time 3809ms: Process A3 started using the CPU for remaining 448ms of 544ms burst [Q A6 B4 B3 A5 B5 B0 A1 B2 A2 A7 A4 A0]
time 3841ms: Time slice expired; preempting process A3 with 416ms remaining [Q A6 B4 B3 A5 B5 B0 A1 B2 A2 A7 A4 A0]
time 3845ms: Process A6 started using the CPU for remaining 152ms of 696ms burst [Q A3 B4 B3 A5 B5 B0 A1 B2 A2 A7 A4 A0]
time 3877ms: Time slice expired; preempting process A6 with 120ms remaining [Q A3 B4 B3 A5 B5 B0 A1 B2 A2 A7 A4 A0]
time 3881ms: Process A3 started using the CPU for remaining 416ms of 544ms burst [Q A6 B4 B3 A5 B5 B0 A1 B2 A2 A7 A4 A0]
time 3913ms: Time slice expired; preempting process A3 with 384ms remaining [Q A6 B4 B3 A5 B5 B0 A1 B2 A2 A7 A4 A0]
time 3917ms: Process A6 started using the CPU for remaining 120ms of 696ms burst [Q A3 B4 B3 A5 B5 B0 A1 B2 A2 A7 A4 A0]
time 3949ms: Time slice expired; preempting process A6 with 88ms remaining [Q A3 B4 B3 A5 B5 B0 A1 B2 A2 A7 A4 A0]
time 3953ms: Process A3 started using the CPU for remaining 384ms of 544ms burst [Q A6 B4 B3 A5 B5 B0 A1 B2 A2 A7 A4 A0]
time 3985ms: Time slice expired; preempting process A3 with 352ms remaining [Q A6 B4 B3 A5 B5 B0 A1 B2 A2 A7 A4 A0]
time 3989ms: Process A6 started using the CPU for remaining 88ms of 696ms burst [Q A3 B4 B3 A5 B5 B0 A1 B2 A2 A7 A4 A0]
time 4021ms: Time slice expired; preempting process A6 with 56ms remaining [Q A3 B4 B3 A5 B5 B0 A1 B2 A2 A7 A4 A0]
time 4025ms: Process A3 started using the CPU for remaining 352ms of 544ms burst [Q A6 B4 B3 A5 B5 B0 A1 B2 A2 A7 A4 A0]
time 4057ms: Time slice expired; preempting process A3 with 320ms remaining [Q A6 B4 B3 A5 B5 B0 A1 B2 A2 A7 A4 A0]
time 4061ms: Process A6 started using the CPU for remaining 56ms of 696ms burst [Q A3 B4 B3 A5 B5 B0 A1 B2 A2 A7 A4 A0]
time 4093ms: Time slice expired; preempting process A6 with 24ms remaining [Q A3 B4 B3 A5 B5 B0 A1 B2 A2 A7 A4 A0]
time 4097ms: Process A3 started using the CPU for remaining 320ms of 544ms burst [Q A6 B4 B3 A5 B5 B0 A1 B2 A2 A7 A4 A0]
time 4129ms: Time slice expired; preempting process A3 with 288ms remaining [Q A6 B4 B3 A5 B5 B0 A1 B2 A2 A7 A4 A0]
time 4133ms: Process A6 started using the CPU for remaining 24ms of 696ms burst [Q A3 B4 B3 A5 B5 B0 A1 B2 A2 A7 A4 A0]
time 4157ms: Process A6 completed a CPU burst; 15 bursts to go [Q A3 B4 B3 A5 B5 B0 A1 B2 A2 A7 A4 A0]
time 4157ms: Process A6 switching out of CPU; blocking on I/O until time 8743ms [Q A3 B4 B3 A5 B5 B0 A1 B2 A2 A7 A4 A0]
time 4161ms: Process A3 started using the CPU for remaining 288ms of 544ms burst [Q B4 B3 A5 B5 B0 A1 B2 A2 A7 A4 A0]
time 4193ms: Time slice expired; preempting process A3 with 256ms remaining [Q B4 B3 A5 B5 B0 A1 B2 A2 A7 A4 A0]
time 4197ms: Process B4 started using the CPU for 1575ms burst [Q A3 B3 A5 B5 B0 A1 B2 A2 A7 A4 A0]
time 4229ms: Time slice expired; preempting process B4 with 1543ms remaining [Q A3 B3 A5 B5 B0 A1 B2 A2 A7 A4 A0]
time 4233ms: Process A3 started using the CPU for remaining 256ms of 544ms burst [Q B4 B3 A5 B5 B0 A1 B2 A2 A7 A4 A0]
time 4265ms: Time slice expired; preempting process A3 with 224ms remaining [Q B4 B3 A5 B5 B0 A1 B2 A2 A7 A4 A0]
time 4269ms: Process B4 started using the CPU for remaining 1543ms of 1575ms burst [Q A3 B3 A5 B5 B0 A1 B2 A2 A7 A4 A0]
time 4301ms: Time slice expired; preempting process B4 with 1511ms remaining [Q A3 B3 A5 B5 B0 A1 B2 A2 A7 A4 A0]
time 4305ms: Process A3 started using the CPU for remaining 224ms of 544ms burst [Q B4 B3 A5 B5 B0 A1 B2 A2 A7 A4 A0]
time 4337ms: Time slice expired; preempting process A3 with 192ms remaining [Q B4 B3 A5 B5 B0 A1 B2 A2 A7 A4 A0]
time 4341ms: Process B4 started using the CPU for remaining 1511ms of 1575ms burst [Q A3 B3 A5 B5 B0 A1 B2 A2 A7 A4 A0]
time 4352ms: Process A8 completed I/O; added to ready queue [Q A3 B3 A5 B5 B0 A1 B2 A2 A7 A4 A0 A8]
time 4373ms: Time slice expired; preempting process B4 with 1479ms remaining [Q A3 B3 A5 B5 B0 A1 B2 A2 A7 A4 A0 A8]
time 4377ms: Process A3 started using the CPU for remaining 192ms of 544ms burst [Q B4 B3 A5 B5 B0 A1 B2 A2 A7 A4 A0 A8]
time 4409ms: Time slice expired; preempting process A3 with 160ms remaining [Q B4 B3 A5 B5 B0 A1 B2 A2 A7 A4 A0 A8]
time 4413ms: Process B4 started using the CPU for remaining 1479ms of 1575ms burst [Q A3 B3 A5 B5 B0 A1 B2 A2 A7 A4 A0 A8]
time 4445ms: Time slice expired; preempting process B4 with 1447ms remaining [Q A3 B3 A5 B5 B0 A1 B2 A2 A7 A4 A0 A8]
time 4449ms: Process A3 started using the CPU for remaining 160ms of 544ms burst [Q B4 B3 A5 B5 B0 A1 B2 A2 A7 A4 A0 A8]
time 4481ms: Time slice expired; preempting process A3 with 128ms remaining [Q B4 B3 A5 B5 B0 A1 B2 A2 A7 A4 A0 A8]
time 4485ms: Process B4 started using the CPU for remaining 1447ms of 1575ms burst [Q A3 B3 A5 B5 B0 A1 B2 A2 A7 A4 A0 A8]
time 4517ms: Time slice expired; preempting process B4 with 1415ms remaining [Q A3 B3 A5 B5 B0 A1 B2 A2 A7 A4 A0 A8]
time 4521ms: Process A3 started using the CPU for remaining 128ms of 544ms burst [Q B4 B3 A5 B5 B0 A1 B2 A2 A7 A4 A0 A8]
time 4553ms: Time slice expired; preempting process A3 with 96ms remaining [Q B4 B3 A5 B5 B0 A1 B2 A2 A7 A4 A0 A8]
time 4557ms: Process B4 started using the CPU for remaining 1415ms of 1575ms burst [Q A3 B3 A5 B5 B0 A1 B2 A2 A7 A4 A0 A8]
time 4589ms: Time slice expired; preempting process B4 with 1383ms remaining [Q A3 B3 A5 B5 B0 A1 B2 A2 A7 A4 A0 A8]
time 4593ms: Process A3 started using the CPU for remaining 96ms of 544ms burst [Q B4 B3 A5 B5 B0 A1 B2 A2 A7 A4 A0 A8]
time 4625ms: Time slice expired; preempting process A3 with 64ms remaining [Q B4 B3 A5 B5 B0 A1 B2 A2 A7 A4 A0 A8]
time 4629ms: Process B4 started using the CPU for remaining 1383ms of 1575ms burst [Q A3 B3 A5 B5 B0 A1 B2 A2 A7 A4 A0 A8]
time 4661ms: Time slice expired; preempting process B4 with 1351ms remaining [Q A3 B3 A5 B5 B0 A1 B2 A2 A7 A4 A0 A8]
time 4665ms: Process A3 started using the CPU for remaining 64ms of 544ms burst [Q B4 B3 A5 B5 B0 A1 B2 A2 A7 A4 A0 A8]
time 4697ms: Time slice expired; preempting process A3 with 32ms remaining [Q B4 B3 A5 B5 B0 A1 B2 A2 A7 A4 A0 A8]
time 4701ms: Process B4 started using the CPU for remaining 1351ms of 1575ms burst [Q A3 B3 A5 B5 B0 A1 B2 A2 A7 A4 A0 A8]
time 4733ms: Time slice expired; preempting process B4 with 1319ms remaining [Q A3 B3 A5 B5 B0 A1 B2 A2 A7 A4 A0 A8]
time 4737ms: Process A3 started using the CPU for remaining 32ms of 544ms burst [Q B4 B3 A5 B5 B0 A1 B2 A2 A7 A4 A0 A8]
time 4747ms: Process A9 completed I/O; added to ready queue [Q B4 B3 A5 B5 B0 A1 B2 A2 A7 A4 A0 A8 A9]
time 4769ms: Process A3 completed a CPU burst; 12 bursts to go [Q B4 B3 A5 B5 B0 A1 B2 A2 A7 A4 A0 A8 A9]
time 4769ms: Process A3 switching out of CPU; blocking on I/O until time 10267ms [Q B4 B3 A5 B5 B0 A1 B2 A2 A7 A4 A0 A8 A9]
time 4773ms: Process B4 started using the CPU for remaining 1319ms of 1575ms burst [Q B3 A5 B5 B0 A1 B2 A2 A7 A4 A0 A8 A9]
time 4805ms: Time slice expired; preempting process B4 with 1287ms remaining [Q B3 A5 B5 B0 A1 B2 A2 A7 A4 A0 A8 A9]
time 4809ms: Process B3 started using the CPU for 944ms burst [Q B4 A5 B5 B0 A1 B2 A2 A7 A4 A0 A8 A9]
time 4841ms: Time slice expired; preempting process B3 with 912ms remaining [Q B4 A5 B5 B0 A1 B2 A2 A7 A4 A0 A8 A9]
time 4845ms: Process B4 started using the CPU for remaining 1287ms of 1575ms burst [Q B3 A5 B5 B0 A1 B2 A2 A7 A4 A0 A8 A9]
time 4877ms: Time slice expired; preempting process B4 with 1255ms remaining [Q B3 A5 B5 B0 A1 B2 A2 A7 A4 A0 A8 A9]
time 4881ms: Process B3 started using the CPU for remaining 912ms of 944ms burst [Q B4 A5 B5 B0 A1 B2 A2 A7 A4 A0 A8 A9]
time 4913ms: Time slice expired; preempting process B3 with 880ms remaining [Q B4 A5 B5 B0 A1 B2 A2 A7 A4 A0 A8 A9]
time 4917ms: Process B4 started using the CPU for remaining 1255ms of 1575ms burst [Q B3 A5 B5 B0 A1 B2 A2 A7 A4 A0 A8 A9]
time 4949ms: Time slice expired; preempting process B4 with 1223ms remaining [Q B3 A5 B5 B0 A1 B2 A2 A7 A4 A0 A8 A9]
time 4953ms: Process B3 started using the CPU for remaining 880ms of 944ms burst [Q B4 A5 B5 B0 A1 B2 A2 A7 A4 A0 A8 A9]
time 4985ms: Time slice expired; preempting process B3 with 848ms remaining [Q B4 A5 B5 B0 A1 B2 A2 A7 A4 A0 A8 A9]
time 4989ms: Process B4 started using the CPU for remaining 1223ms of 1575ms burst [Q B3 A5 B5 B0 A1 B2 A2 A7 A4 A0 A8 A9]
time 5021ms: Time slice expired; preempting process B4 with 1191ms remaining [Q B3 A5 B5 B0 A1 B2 A2 A7 A4 A0 A8 A9]
time 5025ms: Process B3 started using the CPU for remaining 848ms of 944ms burst [Q B4 A5 B5 B0 A1 B2 A2 A7 A4 A0 A8 A9]
time 5057ms: Time slice expired; preempting process B3 with 816ms remaining [Q B4 A5 B5 B0 A1 B2 A2 A7 A4 A0 A8 A9]
time 5061ms: Process B4 started using the CPU for remaining 1191ms of 1575ms burst [Q B3 A5 B5 B0 A1 B2 A2 A7 A4 A0 A8 A9]
time 5093ms: Time slice expired; preempting process B4 with 1159ms remaining [Q B3 A5 B5 B0 A1 B2 A2 A7 A4 A0 A8 A9]
time 5097ms: Process B3 started using the CPU for remaining 816ms of 944ms burst [Q B4 A5 B5 B0 A1 B2 A2 A7 A4 A0 A8 A9]
time 5129ms: Time slice expired; preempting process B3 with 784ms remaining [Q B4 A5 B5 B0 A1 B2 A2 A7 A4 A0 A8 A9]
time 5133ms: Process B4 started using the CPU for remaining 1159ms of 1575ms burst [Q B3 A5 B5 B0 A1 B2 A2 A7 A4 A0 A8 A9]
time 5165ms: Time slice expired; preempting process B4 with 1127ms remaining [Q B3 A5 B5 B0 A1 B2 A2 A7 A4 A0 A8 A9]
time 5169ms: Process B3 started using the CPU for remaining 784ms of 944ms burst [Q B4 A5 B5 B0 A1 B2 A2 A7 A4 A0 A8 A9]
time 5201ms: Time slice expired; preempting process B3 with 752ms remaining [Q B4 A5 B5 B0 A1 B2 A2 A7 A4 A0 A8 A9]
time 5205ms: Process B4 started using the CPU for remaining 1127ms of 1575ms burst [Q B3 A5 B5 B0 A1 B2 A2 A7 A4 A0 A8 A9]
time 5237ms: Time slice expired; preempting process B4 with 1095ms remaining [Q B3 A5 B5 B0 A1 B2 A2 A7 A4 A0 A8 A9]
time 5241ms: Process B3 started using the CPU for remaining 752ms of 944ms burst [Q B4 A5 B5 B0 A1 B2 A2 A7 A4 A0 A8 A9]
time 5273ms: Time slice expired; preempting process B3 with 720ms remaining [Q B4 A5 B5 B0 A1 B2 A2 A7 A4 A0 A8 A9]
time 5277ms: Process B4 started using the CPU for remaining 1095ms of 1575ms burst [Q B3 A5 B5 B0 A1 B2 A2 A7 A4 A0 A8 A9]
time 5309ms: Time slice expired; preempting process B4 with 1063ms remaining [Q B3 A5 B5 B0 A1 B2 A2 A7 A4 A0 A8 A9]
time 5313ms: Process B3 started using the CPU for remaining 720ms of 944ms burst [Q B4 A5 B5 B0 A1 B2 A2 A7 A4 A0 A8 A9]
time 5345ms: Time slice expired; preempting process B3 with 688ms remaining [Q B4 A5 B5 B0 A1 B2 A2 A7 A4 A0 A8 A9]
time 5349ms: Process B4 started using the CPU for remaining 1063ms of 1575ms burst [Q B3 A5 B5 B0 A1 B2 A2 A7 A4 A0 A8 A9]
time 5381ms: Time slice expired; preempting process B4 with 1031ms remaining [Q B3 A5 B5 B0 A1 B2 A2 A7 A4 A0 A8 A9]
time 5385ms: Process B3 started using the CPU for remaining 688ms of 944ms burst [Q B4 A5 B5 B0 A1 B2 A2 A7 A4 A0 A8 A9]
time 5417ms: Time slice expired; preempting process B3 with 656ms remaining [Q B4 A5 B5 B0 A1 B2 A2 A7 A4 A0 A8 A9]
time 5421ms: Process B4 started using the CPU for remaining 1031ms of 1575ms burst [Q B3 A5 B5 B0 A1 B2 A2 A7 A4 A0 A8 A9]
time 5453ms: Time slice expired; preempting process B4 with 999ms remaining [Q B3 A5 B5 B0 A1 B2 A2 A7 A4 A0 A8 A9]
time 5457ms: Process B3 started using the CPU for remaining 656ms of 944ms burst [Q B4 A5 B5 B0 A1 B2 A2 A7 A4 A0 A8 A9]
time 5489ms: Time slice expired; preempting process B3 with 624ms remaining [Q B4 A5 B5 B0 A1 B2 A2 A7 A4 A0 A8 A9]
time 5493ms: Process B4 started using the CPU for remaining 999ms of 1575ms burst [Q B3 A5 B5 B0 A1 B2 A2 A7 A4 A0 A8 A9]
time 5525ms: Time slice expired; preempting process B4 with 967ms remaining [Q B3 A5 B5 B0 A1 B2 A2 A7 A4 A0 A8 A9]
time 5529ms: Process B3 started using the CPU for remaining 624ms of 944ms burst [Q B4 A5 B5 B0 A1 B2 A2 A7 A4 A0 A8 A9]
time 5561ms: Time slice expired; preempting process B3 with 592ms remaining [Q B4 A5 B5 B0 A1 B2 A2 A7 A4 A0 A8 A9]
time 5565ms: Process B4 started using the CPU for remaining 967ms of 1575ms burst [Q B3 A5 B5 B0 A1 B2 A2 A7 A4 A0 A8 A9]
time 5597ms: Time slice expired; preempting process B4 with 935ms remaining [Q B3 A5 B5 B0 A1 B2 A2 A7 A4 A0 A8 A9]
time 5601ms: Process B3 started using the CPU for remaining 592ms of 944ms burst [Q B4 A5 B5 B0 A1 B2 A2 A7 A4 A0 A8 A9]
time 5633ms: Time slice expired; preempting process B3 with 560ms remaining [Q B4 A5 B5 B0 A1 B2 A2 A7 A4 A0 A8 A9]
time 5637ms: Process B4 started using the CPU for remaining 935ms of 1575ms burst [Q B3 A5 B5 B0 A1 B2 A2 A7 A4 A0 A8 A9]
time 5669ms: Time slice expired; preempting process B4 with 903ms remaining [Q B3 A5 B5 B0 A1 B2 A2 A7 A4 A0 A8 A9]
time 5673ms: Process B3 started using the CPU for remaining 560ms of 944ms burst [Q B4 A5 B5 B0 A1 B2 A2 A7 A4 A0 A8 A9]
time 5705ms: Time slice expired; preempting process B3 with 528ms remaining [Q B4 A5 B5 B0 A1 B2 A2 A7 A4 A0 A8 A9]
time 5709ms: Process B4 started using the CPU for remaining 903ms of 1575ms burst [Q B3 A5 B5 B0 A1 B2 A2 A7 A4 A0 A8 A9]
time 5741ms: Time slice expired; preempting process B4 with 871ms remaining [Q B3 A5 B5 B0 A1 B2 A2 A7 A4 A0 A8 A9]
time 5745ms: Process B3 started using the CPU for remaining 528ms of 944ms burst [Q B4 A5 B5 B0 A1 B2 A2 A7 A4 A0 A8 A9]
time 5777ms: Time slice expired; preempting process B3 with 496ms remaining [Q B4 A5 B5 B0 A1 B2 A2 A7 A4 A0 A8 A9]
time 5781ms: Process B4 started using the CPU for remaining 871ms of 1575ms burst [Q B3 A5 B5 B0 A1 B2 A2 A7 A4 A0 A8 A9]
time 5813ms: Time slice expired; preempting process B4 with 839ms remaining [Q B3 A5 B5 B0 A1 B2 A2 A7 A4 A0 A8 A9]
time 5817ms: Process B3 started using the CPU for remaining 496ms of 944ms burst [Q B4 A5 B5 B0 A1 B2 A2 A7 A4 A0 A8 A9]
time 5849ms: Time slice expired; preempting process B3 with 464ms remaining [Q B4 A5 B5 B0 A1 B2 A2 A7 A4 A0 A8 A9]
time 5853ms: Process B4 started using the CPU for remaining 839ms of 1575ms burst [Q B3 A5 B5 B0 A1 B2 A2 A7 A4 A0 A8 A9]
time 5885ms: Time slice expired; preempting process B4 with 807ms remaining [Q B3 A5 B5 B0 A1 B2 A2 A7 A4 A0 A8 A9]
time 5889ms: Process B3 started using the CPU for remaining 464ms of 944ms burst [Q B4 A5 B5 B0 A1 B2 A2 A7 A4 A0 A8 A9]
time 5921ms: Time slice expired; preempting process B3 with 432ms remaining [Q B4 A5 B5 B0 A1 B2 A2 A7 A4 A0 A8 A9]
time 5925ms: Process B4 started using the CPU for remaining 807ms of 1575ms burst [Q B3 A5 B5 B0 A1 B2 A2 A7 A4 A0 A8 A9]
time 5957ms: Time slice expired; preempting process B4 with 775ms remaining [Q B3 A5 B5 B0 A1 B2 A2 A7 A4 A0 A8 A9]
time 5961ms: Process B3 started using the CPU for remaining 432ms of 944ms burst [Q B4 A5 B5 B0 A1 B2 A2 A7 A4 A0 A8 A9]
time 5993ms: Time slice expired; preempting process B3 with 400ms remaining [Q B4 A5 B5 B0 A1 B2 A2 A7 A4 A0 A8 A9]
time 5997ms: Process B4 started using the CPU for remaining 775ms of 1575ms burst [Q B3 A5 B5 B0 A1 B2 A2 A7 A4 A0 A8 A9]
time 6029ms: Time slice expired; preempting process B4 with 743ms remaining [Q B3 A5 B5 B0 A1 B2 A2 A7 A4 A0 A8 A9]
time 6033ms: Process B3 started using the CPU for remaining 400ms of 944ms burst [Q B4 A5 B5 B0 A1 B2 A2 A7 A4 A0 A8 A9]
time 6065ms: Time slice expired; preempting process B3 with 368ms remaining [Q B4 A5 B5 B0 A1 B2 A2 A7 A4 A0 A8 A9]
time 6069ms: Process B4 started using the CPU for remaining 743ms of 1575ms burst [Q B3 A5 B5 B0 A1 B2 A2 A7 A4 A0 A8 A9]
time 6101ms: Time slice expired; preempting process B4 with 711ms remaining [Q B3 A5 B5 B0 A1 B2 A2 A7 A4 A0 A8 A9]
time 6105ms: Process B3 started using the CPU for remaining 368ms of 944ms burst [Q B4 A5 B5 B0 A1 B2 A2 A7 A4 A0 A8 A9]
time 6137ms: Time slice expired; preempting process B3 with 336ms remaining [Q B4 A5 B5 B0 A1 B2 A2 A7 A4 A0 A8 A9]
time 6141ms: Process B4 started using the CPU for remaining 711ms of 1575ms burst [Q B3 A5 B5 B0 A1 B2 A2 A7 A4 A0 A8 A9]
time 6173ms: Time slice expired; preempting process B4 with 679ms remaining [Q B3 A5 B5 B0 A1 B2 A2 A7 A4 A0 A8 A9]
time 6177ms: Process B3 started using the CPU for remaining 336ms of 944ms burst [Q B4 A5 B5 B0 A1 B2 A2 A7 A4 A0 A8 A9]
time 6209ms: Time slice expired; preempting process B3 with 304ms remaining [Q B4 A5 B5 B0 A1 B2 A2 A7 A4 A0 A8 A9]
time 6213ms: Process B4 started using the CPU for remaining 679ms of 1575ms burst [Q B3 A5 B5 B0 A1 B2 A2 A7 A4 A0 A8 A9]
time 6245ms: Time slice expired; preempting process B4 with 647ms remaining [Q B3 A5 B5 B0 A1 B2 A2 A7 A4 A0 A8 A9]
time 6249ms: Process B3 started using the CPU for remaining 304ms of 944ms burst [Q B4 A5 B5 B0 A1 B2 A2 A7 A4 A0 A8 A9]
time 6281ms: Time slice expired; preempting process B3 with 272ms remaining [Q B4 A5 B5 B0 A1 B2 A2 A7 A4 A0 A8 A9]
time 6285ms: Process B4 started using the CPU for remaining 647ms of 1575ms burst [Q B3 A5 B5 B0 A1 B2 A2 A7 A4 A0 A8 A9]
time 6317ms: Time slice expired; preempting process B4 with 615ms remaining [Q B3 A5 B5 B0 A1 B2 A2 A7 A4 A0 A8 A9]
time 6321ms: Process B3 started using the CPU for remaining 272ms of 944ms burst [Q B4 A5 B5 B0 A1 B2 A2 A7 A4 A0 A8 A9]
time 6353ms: Time slice expired; preempting process B3 with 240ms remaining [Q B4 A5 B5 B0 A1 B2 A2 A7 A4 A0 A8 A9]
time 6357ms: Process B4 started using the CPU for remaining 615ms of 1575ms burst [Q B3 A5 B5 B0 A1 B2 A2 A7 A4 A0 A8 A9]
time 6389ms: Time slice expired; preempting process B4 with 583ms remaining [Q B3 A5 B5 B0 A1 B2 A2 A7 A4 A0 A8 A9]
time 6393ms: Process B3 started using the CPU for remaining 240ms of 944ms burst [Q B4 A5 B5 B0 A1 B2 A2 A7 A4 A0 A8 A9]
time 6425ms: Time slice expired; preempting process B3 with 208ms remaining [Q B4 A5 B5 B0 A1 B2 A2 A7 A4 A0 A8 A9]
time 6429ms: Process B4 started using the CPU for remaining 583ms of 1575ms burst [Q B3 A5 B5 B0 A1 B2 A2 A7 A4 A0 A8 A9]
time 6461ms: Time slice expired; preempting process B4 with 551ms remaining [Q B3 A5 B5 B0 A1 B2 A2 A7 A4 A0 A8 A9]
time 6465ms: Process B3 started using the CPU for remaining 208ms of 944ms burst [Q B4 A5 B5 B0 A1 B2 A2 A7 A4 A0 A8 A9]
time 6497ms: Time slice expired; preempting process B3 with 176ms remaining [Q B4 A5 B5 B0 A1 B2 A2 A7 A4 A0 A8 A9]
time 6501ms: Process B4 started using the CPU for remaining 551ms of 1575ms burst [Q B3 A5 B5 B0 A1 B2 A2 A7 A4 A0 A8 A9]
time 6533ms: Time slice expired; preempting process B4 with 519ms remaining [Q B3 A5 B5 B0 A1 B2 A2 A7 A4 A0 A8 A9]
time 6537ms: Process B3 started using the CPU for remaining 176ms of 944ms burst [Q B4 A5 B5 B0 A1 B2 A2 A7 A4 A0 A8 A9]
time 6569ms: Time slice expired; preempting process B3 with 144ms remaining [Q B4 A5 B5 B0 A1 B2 A2 A7 A4 A0 A8 A9]
time 6573ms: Process B4 started using the CPU for remaining 519ms of 1575ms burst [Q B3 A5 B5 B0 A1 B2 A2 A7 A4 A0 A8 A9]
time 6605ms: Time slice expired; preempting process B4 with 487ms remaining [Q B3 A5 B5 B0 A1 B2 A2 A7 A4 A0 A8 A9]
time 6609ms: Process B3 started using the CPU for remaining 144ms of 944ms burst [Q B4 A5 B5 B0 A1 B2 A2 A7 A4 A0 A8 A9]
time 6641ms: Time slice expired; preempting process B3 with 112ms remaining [Q B4 A5 B5 B0 A1 B2 A2 A7 A4 A0 A8 A9]
time 6645ms: Process B4 started using the CPU for remaining 487ms of 1575ms burst [Q B3 A5 B5 B0 A1 B2 A2 A7 A4 A0 A8 A9]
time 6677ms: Time slice expired; preempting process B4 with 455ms remaining [Q B3 A5 B5 B0 A1 B2 A2 A7 A4 A0 A8 A9]
time 6681ms: Process B3 started using the CPU for remaining 112ms of 944ms burst [Q B4 A5 B5 B0 A1 B2 A2 A7 A4 A0 A8 A9]
time 6713ms: Time slice expired; preempting process B3 with 80ms remaining [Q B4 A5 B5 B0 A1 B2 A2 A7 A4 A0 A8 A9]
time 6717ms: Process B4 started using the CPU for remaining 455ms of 1575ms burst [Q B3 A5 B5 B0 A1 B2 A2 A7 A4 A0 A8 A9]
time 6749ms: Time slice expired; preempting process B4 with 423ms remaining [Q B3 A5 B5 B0 A1 B2 A2 A7 A4 A0 A8 A9]
time 6753ms: Process B3 started using the CPU for remaining 80ms of 944ms burst [Q B4 A5 B5 B0 A1 B2 A2 A7 A4 A0 A8 A9]
time 6785ms: Time slice expired; preempting process B3 with 48ms remaining [Q B4 A5 B5 B0 A1 B2 A2 A7 A4 A0 A8 A9]
time 6789ms: Process B4 started using the CPU for remaining 423ms of 1575ms burst [Q B3 A5 B5 B0 A1 B2 A2 A7 A4 A0 A8 A9]
time 6821ms: Time slice expired; preempting process B4 with 391ms remaining [Q B3 A5 B5 B0 A1 B2 A2 A7 A4 A0 A8 A9]
time 6825ms: Process B3 started using the CPU for remaining 48ms of 944ms burst [Q B4 A5 B5 B0 A1 B2 A2 A7 A4 A0 A8 A9]
time 6857ms: Time slice expired; preempting process B3 with 16ms remaining [Q B4 A5 B5 B0 A1 B2 A2 A7 A4 A0 A8 A9]
time 6861ms: Process B4 started using the CPU for remaining 391ms of 1575ms burst [Q B3 A5 B5 B0 A1 B2 A2 A7 A4 A0 A8 A9]
time 6893ms: Time slice expired; preempting process B4 with 359ms remaining [Q B3 A5 B5 B0 A1 B2 A2 A7 A4 A0 A8 A9]
time 6897ms: Process B3 started using the CPU for remaining 16ms of 944ms burst [Q B4 A5 B5 B0 A1 B2 A2 A7 A4 A0 A8 A9]
time 6913ms: Process B3 completed a CPU burst; 4 bursts to go [Q B4 A5 B5 B0 A1 B2 A2 A7 A4 A0 A8 A9]
time 6913ms: Process B3 switching out of CPU; blocking on I/O until time 21179ms [Q B4 A5 B5 B0 A1 B2 A2 A7 A4 A0 A8 A9]
time 6917ms: Process B4 started using the CPU for remaining 359ms of 1575ms burst [Q A5 B5 B0 A1 B2 A2 A7 A4 A0 A8 A9]
time 6949ms: Time slice expired; preempting process B4 with 327ms remaining [Q A5 B5 B0 A1 B2 A2 A7 A4 A0 A8 A9]
time 6953ms: Process A5 started using the CPU for 638ms burst [Q B4 B5 B0 A1 B2 A2 A7 A4 A0 A8 A9]
time 6985ms: Time slice expired; preempting process A5 with 606ms remaining [Q B4 B5 B0 A1 B2 A2 A7 A4 A0 A8 A9]
time 6989ms: Process B4 started using the CPU for remaining 327ms of 1575ms burst [Q A5 B5 B0 A1 B2 A2 A7 A4 A0 A8 A9]
time 7021ms: Time slice expired; preempting process B4 with 295ms remaining [Q A5 B5 B0 A1 B2 A2 A7 A4 A0 A8 A9]
time 7025ms: Process A5 started using the CPU for remaining 606ms of 638ms burst [Q B4 B5 B0 A1 B2 A2 A7 A4 A0 A8 A9]
time 7057ms: Time slice expired; preempting process A5 with 574ms remaining [Q B4 B5 B0 A1 B2 A2 A7 A4 A0 A8 A9]
time 7061ms: Process B4 started using the CPU for remaining 295ms of 1575ms burst [Q A5 B5 B0 A1 B2 A2 A7 A4 A0 A8 A9]
time 7093ms: Time slice expired; preempting process B4 with 263ms remaining [Q A5 B5 B0 A1 B2 A2 A7 A4 A0 A8 A9]
time 7097ms: Process A5 started using the CPU for remaining 574ms of 638ms burst [Q B4 B5 B0 A1 B2 A2 A7 A4 A0 A8 A9]
time 7129ms: Time slice expired; preempting process A5 with 542ms remaining [Q B4 B5 B0 A1 B2 A2 A7 A4 A0 A8 A9]
time 7133ms: Process B4 started using the CPU for remaining 263ms of 1575ms burst [Q A5 B5 B0 A1 B2 A2 A7 A4 A0 A8 A9]
time 7165ms: Time slice expired; preempting process B4 with 231ms remaining [Q A5 B5 B0 A1 B2 A2 A7 A4 A0 A8 A9]
time 7169ms: Process A5 started using the CPU for remaining 542ms of 638ms burst [Q B4 B5 B0 A1 B2 A2 A7 A4 A0 A8 A9]
time 7201ms: Time slice expired; preempting process A5 with 510ms remaining [Q B4 B5 B0 A1 B2 A2 A7 A4 A0 A8 A9]
time 7205ms: Process B4 started using the CPU for remaining 231ms of 1575ms burst [Q A5 B5 B0 A1 B2 A2 A7 A4 A0 A8 A9]
time 7237ms: Time slice expired; preempting process B4 with 199ms remaining [Q A5 B5 B0 A1 B2 A2 A7 A4 A0 A8 A9]
time 7241ms: Process A5 started using the CPU for remaining 510ms of 638ms burst [Q B4 B5 B0 A1 B2 A2 A7 A4 A0 A8 A9]
time 7273ms: Time slice expired; preempting process A5 with 478ms remaining [Q B4 B5 B0 A1 B2 A2 A7 A4 A0 A8 A9]
time 7277ms: Process B4 started using the CPU for remaining 199ms of 1575ms burst [Q A5 B5 B0 A1 B2 A2 A7 A4 A0 A8 A9]
time 7309ms: Time slice expired; preempting process B4 with 167ms remaining [Q A5 B5 B0 A1 B2 A2 A7 A4 A0 A8 A9]
time 7313ms: Process A5 started using the CPU for remaining 478ms of 638ms burst [Q B4 B5 B0 A1 B2 A2 A7 A4 A0 A8 A9]
time 7345ms: Time slice expired; preempting process A5 with 446ms remaining [Q B4 B5 B0 A1 B2 A2 A7 A4 A0 A8 A9]
time 7349ms: Process B4 started using the CPU for remaining 167ms of 1575ms burst [Q A5 B5 B0 A1 B2 A2 A7 A4 A0 A8 A9]
time 7381ms: Time slice expired; preempting process B4 with 135ms remaining [Q A5 B5 B0 A1 B2 A2 A7 A4 A0 A8 A9]
time 7385ms: Process A5 started using the CPU for remaining 446ms of 638ms burst [Q B4 B5 B0 A1 B2 A2 A7 A4 A0 A8 A9]
time 7417ms: Time slice expired; preempting process A5 with 414ms remaining [Q B4 B5 B0 A1 B2 A2 A7 A4 A0 A8 A9]
time 7421ms: Process B4 started using the CPU for remaining 135ms of 1575ms burst [Q A5 B5 B0 A1 B2 A2 A7 A4 A0 A8 A9]
time 7453ms: Time slice expired; preempting process B4 with 103ms remaining [Q A5 B5 B0 A1 B2 A2 A7 A4 A0 A8 A9]
time 7457ms: Process A5 started using the CPU for remaining 414ms of 638ms burst [Q B4 B5 B0 A1 B2 A2 A7 A4 A0 A8 A9]
time 7489ms: Time slice expired; preempting process A5 with 382ms remaining [Q B4 B5 B0 A1 B2 A2 A7 A4 A0 A8 A9]
time 7493ms: Process B4 started using the CPU for remaining 103ms of 1575ms burst [Q A5 B5 B0 A1 B2 A2 A7 A4 A0 A8 A9]
time 7525ms: Time slice expired; preempting process B4 with 71ms remaining [Q A5 B5 B0 A1 B2 A2 A7 A4 A0 A8 A9]
time 7529ms: Process A5 started using the CPU for remaining 382ms of 638ms burst [Q B4 B5 B0 A1 B2 A2 A7 A4 A0 A8 A9]
time 7561ms: Time slice expired; preempting process A5 with 350ms remaining [Q B4 B5 B0 A1 B2 A2 A7 A4 A0 A8 A9]
time 7565ms: Process B4 started using the CPU for remaining 71ms of 1575ms burst [Q A5 B5 B0 A1 B2 A2 A7 A4 A0 A8 A9]
time 7597ms: Time slice expired; preempting process B4 with 39ms remaining [Q A5 B5 B0 A1 B2 A2 A7 A4 A0 A8 A9]
time 7601ms: Process A5 started using the CPU for remaining 350ms of 638ms burst [Q B4 B5 B0 A1 B2 A2 A7 A4 A0 A8 A9]
time 7633ms: Time slice expired; preempting process A5 with 318ms remaining [Q B4 B5 B0 A1 B2 A2 A7 A4 A0 A8 A9]
time 7637ms: Process B4 started using the CPU for remaining 39ms of 1575ms burst [Q A5 B5 B0 A1 B2 A2 A7 A4 A0 A8 A9]
time 7669ms: Time slice expired; preempting process B4 with 7ms remaining [Q A5 B5 B0 A1 B2 A2 A7 A4 A0 A8 A9]
time 7673ms: Process A5 started using the CPU for remaining 318ms of 638ms burst [Q B4 B5 B0 A1 B2 A2 A7 A4 A0 A8 A9]
time 7705ms: Time slice expired; preempting process A5 with 286ms remaining [Q B4 B5 B0 A1 B2 A2 A7 A4 A0 A8 A9]
time 7709ms: Process B4 started using the CPU for remaining 7ms of 1575ms burst [Q A5 B5 B0 A1 B2 A2 A7 A4 A0 A8 A9]
time 7716ms: Process B4 completed a CPU burst; 19 bursts to go [Q A5 B5 B0 A1 B2 A2 A7 A4 A0 A8 A9]
time 7716ms: Process B4 switching out of CPU; blocking on I/O until time 8142ms [Q A5 B5 B0 A1 B2 A2 A7 A4 A0 A8 A9]
time 7720ms: Process A5 started using the CPU for remaining 286ms of 638ms burst [Q B5 B0 A1 B2 A2 A7 A4 A0 A8 A9]
time 7752ms: Time slice expired; preempting process A5 with 254ms remaining [Q B5 B0 A1 B2 A2 A7 A4 A0 A8 A9]
time 7756ms: Process B5 started using the CPU for 63ms burst [Q A5 B0 A1 B2 A2 A7 A4 A0 A8 A9]
time 7788ms: Time slice expired; preempting process B5 with 31ms remaining [Q A5 B0 A1 B2 A2 A7 A4 A0 A8 A9]
time 7792ms: Process A5 started using the CPU for remaining 254ms of 638ms burst [Q B5 B0 A1 B2 A2 A7 A4 A0 A8 A9]
time 7824ms: Time slice expired; preempting process A5 with 222ms remaining [Q B5 B0 A1 B2 A2 A7 A4 A0 A8 A9]
time 7828ms: Process B5 started using the CPU for remaining 31ms of 63ms burst [Q A5 B0 A1 B2 A2 A7 A4 A0 A8 A9]
time 7859ms: Process B5 completed a CPU burst; 24 bursts to go [Q A5 B0 A1 B2 A2 A7 A4 A0 A8 A9]
time 7859ms: Process B5 switching out of CPU; blocking on I/O until time 11965ms [Q A5 B0 A1 B2 A2 A7 A4 A0 A8 A9]
time 7863ms: Process A5 started using the CPU for remaining 222ms of 638ms burst [Q B0 A1 B2 A2 A7 A4 A0 A8 A9]
time 7895ms: Time slice expired; preempting process A5 with 190ms remaining [Q B0 A1 B2 A2 A7 A4 A0 A8 A9]
time 7899ms: Process B0 started using the CPU for 288ms burst [Q A5 A1 B2 A2 A7 A4 A0 A8 A9]
time 7931ms: Time slice expired; preempting process B0 with 256ms remaining [Q A5 A1 B2 A2 A7 A4 A0 A8 A9]
time 7935ms: Process A5 started using the CPU for remaining 190ms of 638ms burst [Q B0 A1 B2 A2 A7 A4 A0 A8 A9]
time 7967ms: Time slice expired; preempting process A5 with 158ms remaining [Q B0 A1 B2 A2 A7 A4 A0 A8 A9]
time 7971ms: Process B0 started using the CPU for remaining 256ms of 288ms burst [Q A5 A1 B2 A2 A7 A4 A0 A8 A9]
time 8003ms: Time slice expired; preempting process B0 with 224ms remaining [Q A5 A1 B2 A2 A7 A4 A0 A8 A9]
time 8007ms: Process A5 started using the CPU for remaining 158ms of 638ms burst [Q B0 A1 B2 A2 A7 A4 A0 A8 A9]
time 8039ms: Time slice expired; preempting process A5 with 126ms remaining [Q B0 A1 B2 A2 A7 A4 A0 A8 A9]
time 8043ms: Process B0 started using the CPU for remaining 224ms of 288ms burst [Q A5 A1 B2 A2 A7 A4 A0 A8 A9]
time 8075ms: Time slice expired; preempting process B0 with 192ms remaining [Q A5 A1 B2 A2 A7 A4 A0 A8 A9]
time 8079ms: Process A5 started using the CPU for remaining 126ms of 638ms burst [Q B0 A1 B2 A2 A7 A4 A0 A8 A9]
time 8111ms: Time slice expired; preempting process A5 with 94ms remaining [Q B0 A1 B2 A2 A7 A4 A0 A8 A9]
time 8115ms: Process B0 started using the CPU for remaining 192ms of 288ms burst [Q A5 A1 B2 A2 A7 A4 A0 A8 A9]
time 8142ms: Process B4 completed I/O; added to ready queue [Q A5 A1 B2 A2 A7 A4 A0 A8 A9 B4]
time 8147ms: Time slice expired; preempting process B0 with 160ms remaining [Q A5 A1 B2 A2 A7 A4 A0 A8 A9 B4]
time 8151ms: Process A5 started using the CPU for remaining 94ms of 638ms burst [Q B0 A1 B2 A2 A7 A4 A0 A8 A9 B4]
time 8183ms: Time slice expired; preempting process A5 with 62ms remaining [Q B0 A1 B2 A2 A7 A4 A0 A8 A9 B4]
time 8187ms: Process B0 started using the CPU for remaining 160ms of 288ms burst [Q A5 A1 B2 A2 A7 A4 A0 A8 A9 B4]
time 8219ms: Time slice expired; preempting process B0 with 128ms remaining [Q A5 A1 B2 A2 A7 A4 A0 A8 A9 B4]
time 8223ms: Process A5 started using the CPU for remaining 62ms of 638ms burst [Q B0 A1 B2 A2 A7 A4 A0 A8 A9 B4]
time 8255ms: Time slice expired; preempting process A5 with 30ms remaining [Q B0 A1 B2 A2 A7 A4 A0 A8 A9 B4]
time 8259ms: Process B0 started using the CPU for remaining 128ms of 288ms burst [Q A5 A1 B2 A2 A7 A4 A0 A8 A9 B4]
time 8291ms: Time slice expired; preempting process B0 with 96ms remaining [Q A5 A1 B2 A2 A7 A4 A0 A8 A9 B4]
time 8295ms: Process A5 started using the CPU for remaining 30ms of 638ms burst [Q B0 A1 B2 A2 A7 A4 A0 A8 A9 B4]
time 8325ms: Process A5 completed a CPU burst; 31 bursts to go [Q B0 A1 B2 A2 A7 A4 A0 A8 A9 B4]
time 8325ms: Process A5 switching out of CPU; blocking on I/O until time 12863ms [Q B0 A1 B2 A2 A7 A4 A0 A8 A9 B4]
time 8329ms: Process B0 started using the CPU for remaining 96ms of 288ms burst [Q A1 B2 A2 A7 A4 A0 A8 A9 B4]
time 8361ms: Time slice expired; preempting process B0 with 64ms remaining [Q A1 B2 A2 A7 A4 A0 A8 A9 B4]
time 8365ms: Process A1 started using the CPU for 7140ms burst [Q B0 B2 A2 A7 A4 A0 A8 A9 B4]
time 8397ms: Time slice expired; preempting process A1 with 7108ms remaining [Q B0 B2 A2 A7 A4 A0 A8 A9 B4]
time 8401ms: Process B0 started using the CPU for remaining 64ms of 288ms burst [Q A1 B2 A2 A7 A4 A0 A8 A9 B4]
time 8433ms: Time slice expired; preempting process B0 with 32ms remaining [Q A1 B2 A2 A7 A4 A0 A8 A9 B4]
time 8437ms: Process A1 started using the CPU for remaining 7108ms of 7140ms burst [Q B0 B2 A2 A7 A4 A0 A8 A9 B4]
time 8469ms: Time slice expired; preempting process A1 with 7076ms remaining [Q B0 B2 A2 A7 A4 A0 A8 A9 B4]
time 8473ms: Process B0 started using the CPU for remaining 32ms of 288ms burst [Q A1 B2 A2 A7 A4 A0 A8 A9 B4]
time 8505ms: Process B0 completed a CPU burst; 29 bursts to go [Q A1 B2 A2 A7 A4 A0 A8 A9 B4]
time 8505ms: Process B0 switching out of CPU; blocking on I/O until time 16795ms [Q A1 B2 A2 A7 A4 A0 A8 A9 B4]
time 8509ms: Process A1 started using the CPU for remaining 7076ms of 7140ms burst [Q B2 A2 A7 A4 A0 A8 A9 B4]
time 8541ms: Time slice expired; preempting process A1 with 7044ms remaining [Q B2 A2 A7 A4 A0 A8 A9 B4]
time 8545ms: Process B2 started using the CPU for 310ms burst [Q A1 A2 A7 A4 A0 A8 A9 B4]
time 8577ms: Time slice expired; preempting process B2 with 278ms remaining [Q A1 A2 A7 A4 A0 A8 A9 B4]
time 8581ms: Process A1 started using the CPU for remaining 7044ms of 7140ms burst [Q B2 A2 A7 A4 A0 A8 A9 B4]
time 8613ms: Time slice expired; preempting process A1 with 7012ms remaining [Q B2 A2 A7 A4 A0 A8 A9 B4]
time 8617ms: Process B2 started using the CPU for remaining 278ms of 310ms burst [Q A1 A2 A7 A4 A0 A8 A9 B4]
time 8649ms: Time slice expired; preempting process B2 with 246ms remaining [Q A1 A2 A7 A4 A0 A8 A9 B4]
time 8653ms: Process A1 started using the CPU for remaining 7012ms of 7140ms burst [Q B2 A2 A7 A4 A0 A8 A9 B4]
time 8685ms: Time slice expired; preempting process A1 with 6980ms remaining [Q B2 A2 A7 A4 A0 A8 A9 B4]
time 8689ms: Process B2 started using the CPU for remaining 246ms of 310ms burst [Q A1 A2 A7 A4 A0 A8 A9 B4]
time 8721ms: Time slice expired; preempting process B2 with 214ms remaining [Q A1 A2 A7 A4 A0 A8 A9 B4]
time 8725ms: Process A1 started using the CPU for remaining 6980ms of 7140ms burst [Q B2 A2 A7 A4 A0 A8 A9 B4]
time 8743ms: Process A6 completed I/O; added to ready queue [Q B2 A2 A7 A4 A0 A8 A9 B4 A6]
time 8757ms: Time slice expired; preempting process A1 with 6948ms remaining [Q B2 A2 A7 A4 A0 A8 A9 B4 A6]
time 8761ms: Process B2 started using the CPU for remaining 214ms of 310ms burst [Q A1 A2 A7 A4 A0 A8 A9 B4 A6]
time 8793ms: Time slice expired; preempting process B2 with 182ms remaining [Q A1 A2 A7 A4 A0 A8 A9 B4 A6]
time 8797ms: Process A1 started using the CPU for remaining 6948ms of 7140ms burst [Q B2 A2 A7 A4 A0 A8 A9 B4 A6]
time 8829ms: Time slice expired; preempting process A1 with 6916ms remaining [Q B2 A2 A7 A4 A0 A8 A9 B4 A6]
time 8833ms: Process B2 started using the CPU for remaining 182ms of 310ms burst [Q A1 A2 A7 A4 A0 A8 A9 B4 A6]
time 8865ms: Time slice expired; preempting process B2 with 150ms remaining [Q A1 A2 A7 A4 A0 A8 A9 B4 A6]
time 8869ms: Process A1 started using the CPU for remaining 6916ms of 7140ms burst [Q B2 A2 A7 A4 A0 A8 A9 B4 A6]
time 8901ms: Time slice expired; preempting process A1 with 6884ms remaining [Q B2 A2 A7 A4 A0 A8 A9 B4 A6]
time 8905ms: Process B2 started using the CPU for remaining 150ms of 310ms burst [Q A1 A2 A7 A4 A0 A8 A9 B4 A6]
time 8937ms: Time slice expired; preempting process B2 with 118ms remaining [Q A1 A2 A7 A4 A0 A8 A9 B4 A6]
time 8941ms: Process A1 started using the CPU for remaining 6884ms of 7140ms burst [Q B2 A2 A7 A4 A0 A8 A9 B4 A6]
time 8973ms: Time slice expired; preempting process A1 with 6852ms remaining [Q B2 A2 A7 A4 A0 A8 A9 B4 A6]
time 8977ms: Process B2 started using the CPU for remaining 118ms of 310ms burst [Q A1 A2 A7 A4 A0 A8 A9 B4 A6]
time 9009ms: Time slice expired; preempting process B2 with 86ms remaining [Q A1 A2 A7 A4 A0 A8 A9 B4 A6]
time 9013ms: Process A1 started using the CPU for remaining 6852ms of 7140ms burst [Q B2 A2 A7 A4 A0 A8 A9 B4 A6]
time 9045ms: Time slice expired; preempting process A1 with 6820ms remaining [Q B2 A2 A7 A4 A0 A8 A9 B4 A6]
time 9049ms: Process B2 started using the CPU for remaining 86ms of 310ms burst [Q A1 A2 A7 A4 A0 A8 A9 B4 A6]
time 9081ms: Time slice expired; preempting process B2 with 54ms remaining [Q A1 A2 A7 A4 A0 A8 A9 B4 A6]
time 9085ms: Process A1 started using the CPU for remaining 6820ms of 7140ms burst [Q B2 A2 A7 A4 A0 A8 A9 B4 A6]
time 9117ms: Time slice expired; preempting process A1 with 6788ms remaining [Q B2 A2 A7 A4 A0 A8 A9 B4 A6]
time 9121ms: Process B2 started using the CPU for remaining 54ms of 310ms burst [Q A1 A2 A7 A4 A0 A8 A9 B4 A6]
time 9153ms: Time slice expired; preempting process B2 with 22ms remaining [Q A1 A2 A7 A4 A0 A8 A9 B4 A6]
time 9157ms: Process A1 started using the CPU for remaining 6788ms of 7140ms burst [Q B2 A2 A7 A4 A0 A8 A9 B4 A6]
time 9189ms: Time slice expired; preempting process A1 with 6756ms remaining [Q B2 A2 A7 A4 A0 A8 A9 B4 A6]
time 9193ms: Process B2 started using the CPU for remaining 22ms of 310ms burst [Q A1 A2 A7 A4 A0 A8 A9 B4 A6]
time 9215ms: Process B2 completed a CPU burst; 12 bursts to go [Q A1 A2 A7 A4 A0 A8 A9 B4 A6]
time 9215ms: Process B2 switching out of CPU; blocking on I/O until time 11665ms [Q A1 A2 A7 A4 A0 A8 A9 B4 A6]
time 9219ms: Process A1 started using the CPU for remaining 6756ms of 7140ms burst [Q A2 A7 A4 A0 A8 A9 B4 A6]
time 9251ms: Time slice expired; preempting process A1 with 6724ms remaining [Q A2 A7 A4 A0 A8 A9 B4 A6]
time 9255ms: Process A2 started using the CPU for 527ms burst [Q A1 A7 A4 A0 A8 A9 B4 A6]
time 9287ms: Time slice expired; preempting process A2 with 495ms remaining [Q A1 A7 A4 A0 A8 A9 B4 A6]
time 9291ms: Process A1 started using the CPU for remaining 6724ms of 7140ms burst [Q A2 A7 A4 A0 A8 A9 B4 A6]
time 9323ms: Time slice expired; preempting process A1 with 6692ms remaining [Q A2 A7 A4 A0 A8 A9 B4 A6]
time 9327ms: Process A2 started using the CPU for remaining 495ms of 527ms burst [Q A1 A7 A4 A0 A8 A9 B4 A6]
time 9359ms: Time slice expired; preempting process A2 with 463ms remaining [Q A1 A7 A4 A0 A8 A9 B4 A6]
time 9363ms: Process A1 started using the CPU for remaining 6692ms of 7140ms burst [Q A2 A7 A4 A0 A8 A9 B4 A6]
time 9395ms: Time slice expired; preempting process A1 with 6660ms remaining [Q A2 A7 A4 A0 A8 A9 B4 A6]
time 9399ms: Process A2 started using the CPU for remaining 463ms of 527ms burst [Q A1 A7 A4 A0 A8 A9 B4 A6]
time 9431ms: Time slice expired; preempting process A2 with 431ms remaining [Q A1 A7 A4 A0 A8 A9 B4 A6]
time 9435ms: Process A1 started using the CPU for remaining 6660ms of 7140ms burst [Q A2 A7 A4 A0 A8 A9 B4 A6]
time 9467ms: Time slice expired; preempting process A1 with 6628ms remaining [Q A2 A7 A4 A0 A8 A9 B4 A6]
time 9471ms: Process A2 started using the CPU for remaining 431ms of 527ms burst [Q A1 A7 A4 A0 A8 A9 B4 A6]
time 9503ms: Time slice expired; preempting process A2 with 399ms remaining [Q A1 A7 A4 A0 A8 A9 B4 A6]
time 9507ms: Process A1 started using the CPU for remaining 6628ms of 7140ms burst [Q A2 A7 A4 A0 A8 A9 B4 A6]
time 9539ms: Time slice expired; preempting process A1 with 6596ms remaining [Q A2 A7 A4 A0 A8 A9 B4 A6]
time 9543ms: Process A2 started using the CPU for remaining 399ms of 527ms burst [Q A1 A7 A4 A0 A8 A9 B4 A6]
time 9575ms: Time slice expired; preempting process A2 with 367ms remaining [Q A1 A7 A4 A0 A8 A9 B4 A6]
time 9579ms: Process A1 started using the CPU for remaining 6596ms of 7140ms burst [Q A2 A7 A4 A0 A8 A9 B4 A6]
time 9611ms: Time slice expired; preempting process A1 with 6564ms remaining [Q A2 A7 A4 A0 A8 A9 B4 A6]
time 9615ms: Process A2 started using the CPU for remaining 367ms of 527ms burst [Q A1 A7 A4 A0 A8 A9 B4 A6]
time 9647ms: Time slice expired; preempting process A2 with 335ms remaining [Q A1 A7 A4 A0 A8 A9 B4 A6]
time 9651ms: Process A1 started using the CPU for remaining 6564ms of 7140ms burst [Q A2 A7 A4 A0 A8 A9 B4 A6]
time 9683ms: Time slice expired; preempting process A1 with 6532ms remaining [Q A2 A7 A4 A0 A8 A9 B4 A6]
time 9687ms: Process A2 started using the CPU for remaining 335ms of 527ms burst [Q A1 A7 A4 A0 A8 A9 B4 A6]
time 9719ms: Time slice expired; preempting process A2 with 303ms remaining [Q A1 A7 A4 A0 A8 A9 B4 A6]
time 9723ms: Process A1 started using the CPU for remaining 6532ms of 7140ms burst [Q A2 A7 A4 A0 A8 A9 B4 A6]
time 9755ms: Time slice expired; preempting process A1 with 6500ms remaining [Q A2 A7 A4 A0 A8 A9 B4 A6]
time 9759ms: Process A2 started using the CPU for remaining 303ms of 527ms burst [Q A1 A7 A4 A0 A8 A9 B4 A6]
time 9791ms: Time slice expired; preempting process A2 with 271ms remaining [Q A1 A7 A4 A0 A8 A9 B4 A6]
time 9795ms: Process A1 started using the CPU for remaining 6500ms of 7140ms burst [Q A2 A7 A4 A0 A8 A9 B4 A6]
time 9827ms: Time slice expired; preempting process A1 with 6468ms remaining [Q A2 A7 A4 A0 A8 A9 B4 A6]
time 9831ms: Process A2 started using the CPU for remaining 271ms of 527ms burst [Q A1 A7 A4 A0 A8 A9 B4 A6]
time 9863ms: Time slice expired; preempting process A2 with 239ms remaining [Q A1 A7 A4 A0 A8 A9 B4 A6]
time 9867ms: Process A1 started using the CPU for remaining 6468ms of 7140ms burst [Q A2 A7 A4 A0 A8 A9 B4 A6]
time 9899ms: Time slice expired; preempting process A1 with 6436ms remaining [Q A2 A7 A4 A0 A8 A9 B4 A6]
time 9903ms: Process A2 started using the CPU for remaining 239ms of 527ms burst [Q A1 A7 A4 A0 A8 A9 B4 A6]
time 9935ms: Time slice expired; preempting process A2 with 207ms remaining [Q A1 A7 A4 A0 A8 A9 B4 A6]
time 9939ms: Process A1 started using the CPU for remaining 6436ms of 7140ms burst [Q A2 A7 A4 A0 A8 A9 B4 A6]
time 9971ms: Time slice expired; preempting process A1 with 6404ms remaining [Q A2 A7 A4 A0 A8 A9 B4 A6]
time 9975ms: Process A2 started using the CPU for remaining 207ms of 527ms burst [Q A1 A7 A4 A0 A8 A9 B4 A6]
time 38103ms: Process A0 terminated [Q A1 A9 B1 A2 A6 B4 B2 B3]
time 77571ms: Process B3 terminated [Q B5 A2 A3 A5 B0 B4 A6 A7 A1]
time 80106ms: Process A2 terminated [Q A3 A5 B0 B4 A6 A7 A1 A9 B2]
time 90717ms: Process A7 terminated [Q B4 A8 A3 B1 A1 A4]
time 154265ms: Process A3 terminated [Q A1 A5 B0 A9]
time 168083ms: Process A8 terminated [Q A4 B4 A1]
time 183583ms: Process B2 terminated [Q B4 A1 B1 A4 A5]
time 204576ms: Process A6 terminated [Q A1 A5]
time 245777ms: Process B4 terminated [Q A1 A9]
time 246106ms: Process A9 terminated [Q A1 A5]
time 262505ms: Process A1 terminated [Q empty]
time 294872ms: Process B0 terminated [Q empty]
time 300910ms: Process B5 terminated [Q empty]
time 305330ms: Process A5 terminated [Q A4 B1]
time 306678ms: Process B1 terminated [Q A4]
time 317602ms: Process A4 terminated [Q empty]
time 317604ms: Simulator ended for RR [Q empty]

